Workbook

Sheet Samples
A1: TriStar ID | B1: Original ID | C1: Sample Date | D1: Age | E1: Ethnicity | F1: Gender | G1: Origin | H1: Type | I1: Sub-Type | J1: T | K1: N | L1: M | M1: Grade | N1: Stage | O1: KRAS Mutation | P1: EGFR Mutation
A2: 08A13674 A4 | B2: 08A13674 A4 | C2: 42632 | D2: 73 | F2: M | G2: NHSB | H2: Prostate Pri. | I2: ADC | J2: 3 | K2: - | L2: - | M2: 5+4=9 | N2: - | O2: - | P2: -
A3: 08A7021 A1 | B3: 08A7021 A1 | D3: - | F3: M | G3: NHSB | H3: Prostate Pri. | I3: - | J3: - | K3: - | L3: - | M3: - | N3: - | O3: - | P3: -
A4: 08A7457 A2 | B4: 08A7457 A2 | C4: 42632 | D4: 72 | F4: M | G4: NHSB | H4: Prostate Pri. | I4: ADC | J4: - | K4: - | L4: - | M4: 4+5=9 | N4: IV | O4: - | P4: -
A5: 09A10605 A8 | B5: 09A10605 A8 | D5: 71 | F5: F | G5: NHSB | H5: Ovarian Pri. | I5: Serous | J5: - | K5: - | L5: - | M5: - | N5: IIIC | O5: - | P5: -
A6: 09A15013 B10 | B6: 09A15013 B10 | D6: 63 | F6: F | G6: NHSB | H6: Ovarian Pri. | I6: Papillary Serous | J6: - | K6: - | L6: - | M6: - | N6: IIIC | O6: - | P6: -
A7: 09A16004 A3 | B7: 09A16004 A3 | D7: - | F7: M | G7: NHSB | H7: Prostate Pri. | I7: - | J7: - | K7: - | L7: - | M7: - | N7: - | O7: - | P7: -
A8: 09A16464 A3 | B8: 09A16464 A3 | C8: 42632 | D8: 73 | F8: M | G8: NHSB | H8: Prostate Pri. | I8: ADC | J8: mri 3b | K8: 1 | L8: 1b | M8: 4+5=9 | N8: IV | O8: - | P8: -
A9: 09A17429 A4 | B9: 09A17429 A4 | D9: 54 | F9: F | G9: NHSB | H9: Ovarian Pri. | I9: Papillary Serous | J9: - | K9: - | L9: - | M9: - | N9: IIIC | O9: - | P9: -
A10: 09A4009 A4 | B10: 09A4009 A4 | D10: 64 | F10: F | G10: NHSB | H10: Ovarian Pri. | I10: Papillary Serous | J10: - | K10: - | L10: - | M10: - | N10: IIIC | O10: - | P10: -
A11: 09A709 A7 | B11: 09A709 A7 | C11: 42632 | D11: 57 | F11: M | G11: NHSB | H11: Prostate Pri. | I11: ADC with focal extracapsular, perineural and vascular invasion and high grade PIN | J11: 3b | K11: x | L11: x | M11: 4+5=9 | N11: - | O11: - | P11: -
A12: 09A7173 A14 | B12: 09A7173 A14 | D12: 61 | F12: F | G12: NHSB | H12: Ovarian Pri. | I12: Carcinoma (Endometrioid) | J12: - | K12: - | L12: - | M12: - | N12: IIIB | O12: - | P12: -
A13: 100G001 | B13: 100G001 | D13: 63 | F13: F | G13: HGUGM | H13: Gastric Pri. | I13: ADC Mucosecretory | J13: 3 | K13: 2 | L13: x | M13: - | N13: IIIA | O13: - | P13: -
A14: 100G002 | B14: 100G002 | D14: 68 | F14: F | G14: HGUGM | H14: Gastric Pri. | I14: ADC | J14: 2 | K14: 1 | L14: - | M14: 3 | N14: IIA | O14: - | P14: -
A15: 100G003 | B15: 100G003 | D15: 78 | F15: F | G15: HGUGM | H15: Gastric Pri. | I15: ADC | J15: 3 | K15: 3 | L15: - | M15: 3 | N15: IIIB | O15: - | P15: -
A16: 100G004 | B16: 100G004 | D16: 68 | F16: F | G16: HGUGM | H16: Gastric Pri. and Nodal Met. | I16: ADC | J16: 3 | K16: 1 | L16: x | M16: 2 | N16: IIB | O16: - | P16: -
A17: 100G005 | B17: 100G005 | D17: 83 | F17: F | G17: HGUGM | H17: Gastric Pri. | I17: ADC | J17: - | K17: - | L17: - | M17: 2 | N17: - | O17: - | P17: -
A18: 100G006 | B18: 100G006 | D18: 58 | F18: F | G18: HGUGM | H18: Gastric Pri. | I18: ADC | J18: - | K18: - | L18: - | M18: 1 | N18: - | O18: - | P18: -
A19: 100G007 | B19: 100G007 | D19: 53 | F19: F | G19: HGUGM | H19: Gastric Pri. | I19: ADC Intestinal Type | J19: 4 | K19: 1 | L19: - | M19: - | N19: IIIB | O19: - | P19: -
A20: 100G008 | B20: 100G008 | D20: 83 | F20: F | G20: HGUGM | H20: Gastric Pri. and Nodal Met. | I20: ADC Enteroid Type | J20: 2a | K20: 1 | L20: - | M20: 2 | N20: II | O20: - | P20: -
A21: 100G009 | B21: 100G009 | D21: 68 | F21: F | G21: HGUGM | H21: Gastric Pri. and Nodal Met. | I21: ADC | J21: 3 | K21: 1 | L21: x | M21: 3 | N21: IIB | O21: - | P21: -
A22: 100G010 | B22: 100G010 | D22: 73 | F22: F | G22: HGUGM | H22: Gastric Pri. | I22: ADC | J22: 2b | K22: 0 | L22: x | M22: 3 | N22: IB | O22: - | P22: -
A23: 100G011 | B23: 100G011 | D23: 43 | F23: F | G23: HGUGM | H23: Gastric Pri. | I23: ADC | J23: 3 | K23: 1 | L23: x | M23: 3 | N23: IIB | O23: - | P23: -
A24: 100G012 | B24: 100G012 | D24: 48 | F24: F | G24: HGUGM | H24: Gastric Pri. | I24: ADC | J24: 3 | K24: 2 | L24: x | M24: 3 | N24: IIIA | O24: - | P24: -
A25: 100G013 | B25: 100G013 | D25: 63 | F25: F | G25: HGUGM | H25: Gastric Pri. | I25: ADC | J25: 3 | K25: 0 | L25: 0 | M25: 2 | N25: IIA | O25: - | P25: -
A26: 100G014 | B26: 100G014 | D26: 63 | F26: F | G26: HGUGM | H26: Gastric Pri. and Nodal Met. | I26: ADC | J26: 3 | K26: 0 | L26: 0 | M26: 2 | N26: IIA | O26: - | P26: -
A27: 100G015 | B27: 100G015 | D27: 73 | F27: F | G27: HGUGM | H27: Gastric Pri. | I27: ADC | J27: 4 | K27: 0 | L27: x | M27: 2 | N27: IIB | O27: - | P27: -
A28: 100G016 | B28: 100G016 | D28: 83 | F28: F | G28: HGUGM | H28: Gastric Pri. | I28: ADC | J28: - | K28: - | L28: - | M28: 1 | N28: - | O28: - | P28: -
A29: 100G017 | B29: 100G017 | D29: 88 | F29: F | G29: HGUGM | H29: Gastric Pri. and Nodal Met. | I29: ADC | J29: 3 | K29: 3 | L29: 0 | M29: 2 | N29: IIIB | O29: - | P29: -
A30: 100G018 | B30: 100G018 | D30: 78 | F30: F | G30: HGUGM | H30: Gastric Pri. | I30: ADC Intestinal Type | J30: 2 | K30: 1 | L30: x | M30: 1 | N30: IIA | O30: - | P30: -
A31: 100G019 | B31: 100G019 | D31: 88 | F31: F | G31: HGUGM | H31: Gastric Pri. and Nodal Met. | I31: ADC | J31: - | K31: - | L31: - | M31: 3 | N31: - | O31: - | P31: -
A32: 100G020 | B32: 100G020 | D32: 68 | F32: F | G32: HGUGM | H32: Gastric Pri. | I32: ADC | J32: - | K32: - | L32: - | M32: 1 | N32: - | O32: - | P32: -
A33: 100G021 | B33: 100G021 | D33: 78 | F33: F | G33: HGUGM | H33: Gastric Pri. | I33: ADC Mucosecretory | J33: 2 | K33: 1 | L33: 0 | M33: - | N33: IIA | O33: - | P33: -
A34: 100G022 | B34: 100G022 | D34: 78 | F34: F | G34: HGUGM | H34: Gastric Pri. | I34: ADC Papillary | J34: 3 | K34: 1 | L34: 0 | M34: 2 | N34: IIB | O34: - | P34: -
A35: 100G023 | B35: 100G023 | D35: 43 | F35: F | G35: HGUGM | H35: Gastric Pri. and Nodal Met. | I35: ADC Mucinous | J35: - | K35: - | L35: - | M35: - | N35: - | O35: - | P35: -
A36: 100G024 | B36: 100G024 | D36: 83 | F36: F | G36: HGUGM | H36: Gastric Pri. | I36: ADC | J36: 4 | K36: 0 | L36: 0 | M36: - | N36: IIIB | O36: - | P36: -
A37: 100G025 | B37: 100G025 | D37: 73 | F37: F | G37: HGUGM | H37: Gastric Pri. | I37: ADC | J37: 2 | K37: 0 | L37: x | M37: 3 | N37: IB | O37: - | P37: -
A38: 100G026 | B38: 100G026 | D38: 73 | F38: F | G38: HGUGM | H38: Gastric Pri. | I38: ADC | J38: 3b | K38: 0 | L38: 0 | M38: 2 | N38: IIA | O38: - | P38: -
A39: 100G027 | B39: 100G027 | D39: 48 | F39: F | G39: HGUGM | H39: Gastric Pri. | I39: ADC | J39: 2b | K39: 0 | L39: x | M39: 2 | N39: IB | O39: - | P39: -
A40: 100G028 | B40: 100G028 | D40: 73 | F40: F | G40: HGUGM | H40: Gastric Pri. | I40: ADC | J40: - | K40: - | L40: - | M40: 2 | N40: - | O40: - | P40: -
...

Sheet Small Cell Carcinoma
A1: TriStar ID | B1: Primary lab number | C1: Slide number(s) | D1: Tumour site | E1: Immunohistochemistry | F1: LYMPH NODE SLIDE/BLOCK NUMBER | G1: Tumour Subtype | H1: Tumour Grade | I1: Manifest
A2: TS-16 - 0862 | B2: 09A001047 | C2: 09A001047 D4 | D2: Left lower lobe | E2: Needlecore biopsy: Positive for CD56 | F2: - | G2: - | H2: - | I2: 7768 7230 4075 NHSBAC manifest NHSB247 SCLC blocks
A3: TS-16 - 0863 | B3: 13D020014 | C3: 13D020014 C3 | D3: Right lower lobe | E3: Positive for TTF1, CD56 and synaptophysin | F3: - | G3: - | H3: - | I3: 7768 7230 4075 NHSBAC manifest NHSB247 SCLC blocks
A4: TS-16 - 0864 | B4: 13D026142 | C4: 13D026142 G5 | D4: Left upper lobe | E4: Positive for TTF1, CD56 and chromogranin | F4: - | G4: - | H4: - | I4: 7768 7230 4075 NHSBAC manifest NHSB247 SCLC blocks
A5: TS-17 - 1716 | B5: 568 | C5: 00/568 6, 00/568 10 | D5: Left side of tongue | F5: BOTH PRIMARY TUMOUR | G5: - | H5: Poorly differentiated, some areas heavy keratinisation | I5: 7704 1184 8537 NHSBAC CTA transfer manifest NHSB 373
A6: TS-17 - 1717 | B6: 4376 | C6: 00/4376 D2,00/4376 D13 BB1 | D6: Oropharynx left tonsil and lymph nodes | F6: BOTH PRIMARY TUMOUR | G6: - | H6: Moderately differentiated, keratinising | I6: 7704 1184 8537 NHSBAC CTA transfer manifest NHSB 373
A7: TS-17 - 1718 | B7: 6781 | C7: 00/6781 C15, 00/6781 C24 | D7: Laryngectomy, right piriform fossa | F7: BOTH PRIMARY TUMOUR | G7: - | H7: Poorly differentiated | I7: 7704 1184 8537 NHSBAC CTA transfer manifest NHSB 373
A8: TS-17 - 1719 | B8: 7419 | C8: 00/7419 B24, 00/7419 B31 | D8: Tongue and lymph nodes | F8: BOTH PRIMARY TUMOUR | G8: - | H8: Moderately differentiated, non-keratinising | I8: 7704 1184 8537 NHSBAC CTA transfer manifest NHSB 373
A9: TS-17 - 1720 | B9: 8732 | C9: 00/8732 B1, 00/8732 B4 | D9: Tonsillar fossa and lymph nodes, right neck dissection | F9: BOTH PRIMARY TUMOUR | G9: - | H9: Moderately differentiated, keratinising | I9: 7704 1184 8537 NHSBAC CTA transfer manifest NHSB 373
A10: TS-17 - 1721 | B10: 8900 | C10: 00/8900 12, 00/8900 15 | D10: Right lateral border of tongue | F10: BOTH PRIMARY TUMOUR | G10: - | H10: Moderately differentiated, keratinising | I10: 7704 1184 8537 NHSBAC CTA transfer manifest NHSB 373
A11: TS-17 - 1722 | B11: 10103 | C11: 00/10103 B8, 00/10103 B29 | D11: Right lateral border of tongue | F11: BOTH PRIMARY TUMOUR | G11: - | H11: Moderately to poorly differentiated keratinising | I11: 7704 1184 8537 NHSBAC CTA transfer manifest NHSB 373
A12: TS-17 - 1723 | B12: 11538 | C12: 00/11538 C19, 00/11538 C29 | D12: Oropharynx base of tongue and lymph node from left side of neck | F12: BOTH PRIMARY TUMOUR | G12: Basaloid | H12: Moderately to poorly differentiated, non-keratinising | I12: 7704 1184 8537 NHSBAC CTA transfer manifest NHSB 373
A13: TS-17 - 1724 | B13: 15225 | C13: 00/15225 B8, 00/15225 B26 | D13: Posterior pharyngeal wall | F13: 00/15225 B8 | G13: - | H13: Moderately to poorly differentiated, abundant keratin formation | I13: 7704 1184 8537 NHSBAC CTA transfer manifest NHSB 373
A14: TS-17 - 1725 | B14: 17136 | C14: 00/17136 C34, 00/17136 C58 | D14: Left floor of mouth | F14: BOTH PRIMARY TUMOUR | G14: - | H14: Moderately to poorly differentiated, non-keratinising | I14: 7704 1184 8537 NHSBAC CTA transfer manifest NHSB 373
A15: TS-17 - 1726 | B15: 21115 | C15: 00/21115 B10, 00/21115 B13 | D15: Oral cavity tongue left lateral border and lymph nodes in skin tissue mandible | F15: 00/21115 B10, 00/21115 B13 | G15: - | H15: Not stated | I15: 7704 1184 8537 NHSBAC CTA transfer manifest NHSB 373
A16: TS-17 - 1727 | B16: 1011920 | C16: 01/11920 4, 01/11920 8 | D16: Right lateral border of tongue | F16: BOTH PRIMARY TUMOUR | G16: - | H16: Moderately to poorly differentiated | I16: 7704 1184 8537 NHSBAC CTA transfer manifest NHSB 373
... A47: TS-17 - 1758 | B47: 95003025 | C47: 95/3025 C16, 95/3025 C16BB1 | D47: Mandible and tongue | F47: BOTH PRIMARY TUMOUR | G47: - | H47: Poorly differentiated | I47: 7704 1184 8537 NHSBAC CTA transfer manifest NHSB 373
A48: TS-17 - 1759 | B48: 95005815 | C48: 95/5815 B3, 95/5815 B2 BB1 | D48: Left radical neck dissection, two thirds glossectomy specimen tumour in tip opening | F48: BOTH PRIMARY TUMOUR | G48: - | H48: Well differentiated | I48: 7704 1184 8537 NHSBAC CTA transfer manifest NHSB 373
A49: TS-17 - 1760 | B49: 95007761 | C49: 95/7761 A4, 95/7761 A4 BB1 | D49: Neck of mandible soft palette and tongue and lymph nodes | F49: BOTH PRIMARY TUMOUR | G49: - | H49: Moderately differentiated, keratinising | I49: 7704 1184 8537 NHSBAC CTA transfer manifest NHSB 373
A50: TS-17 - 1761 | B50: 95017903 | C50: 95/17903 A2, 95/17903 A1 BB1 | D50: Lateral border of tongue | F50: BOTH PRIMARY TUMOUR | G50: - | H50: Poor to Well differentiated, keratinising | I50: 7704 1184 8537 NHSBAC CTA transfer manifest NHSB 373
A51: TS-17 - 1762 | B51: 96001032 | C51: 96/1032 B6, 96/1032 B6 BB1 | D51: Tongue | F51: BOTH PRIMARY TUMOUR | G51: - | H51: Well differentiated, keratinising | I51: 7704 1184 8537 NHSBAC CTA transfer manifest NHSB 373
A52: TS-17 - 1763 | B52: 96008297 | C52: 96/8297 B3, 96/8297 D1BB1 | D52: Submandilar gland and lymph nodes and right side of tongue | F52: 96/8297 B3 | G52: - | H52: Poorly differentiated | I52: 7704 1184 8537 NHSBAC CTA transfer manifest NHSB 373
A53: TS-17 - 1764 | B53: 97017482 | C53: 97/17482 B6BB1, 97/17482 B14 | D53: Tongue (anterior), floor of mouth and lymph nodes | F53: BOTH PRIMARY TUMOUR | G53: - | H53: Poorly differentiated | I53: 7704 1184 8537 NHSBAC CTA transfer manifest NHSB 373
A54: TS-17 - 1765 | B54: 98007510 | C54: 98/7510 A32,98/7510 A28 BB1 | D54: Right floor of mouth and lymph nodes | F54: A28 BB1 | G54: - | H54: Poorly differentiated | I54: 7704 1184 8537 NHSBAC CTA transfer manifest NHSB 373
A55: TS-17 - 1766 | B55: 16D034446 | C55: 16D34446 D15, 16D34446 D16 | D55: Right tongue base and lymph nodes from right selective neck dissection | F55: 16D34446 D15, 16D34446 D16 | G55: Basaloid | I55: 7704 1184 8537 NHSBAC CTA transfer manifest NHSB 373
A56: TS-17 - 1767 | B56: 16D037712 | C56: 16D37712 B38, 16D37712 B39 | D56: Right tongue base | F56: BOTH PRIMARY TUMOUR | G56: - | H56: Poorly differentiated | I56: 7704 1184 8537 NHSBAC CTA transfer manifest NHSB 373
A57: TS-17 - 1768 | B57: 16D041641 | C57: 16D41641 C2, 16D41641 C3 | D57: Right tonsil | F57: Both Bloks are SCC invading the tonsils | G57: Basaloid | H57: Poorly differentiated, non-keratinising | I57: 7704 1184 8537 NHSBAC CTA transfer manifest NHSB 373
A58: TS-17 - 1769 | B58: 16D046370 | C58: 16D46370 C2, 16D46370 C3 | D58: Left tongue and lymp nodes from left neck dissection | F58: BOTH PRIMARY TUMOUR | G58: - | H58: Moderately differentiated, keratinising | I58: 7704 1184 8537 NHSBAC CTA transfer manifest NHSB 373
A59: TS-17 - 1770 | B59: 16D047661 | C59: 16D47661 C3, 16D47661 C6 | D59: Left lateral tongue and lymph nodes | F59: BOTH PRIMARY TUMOUR | G59: - | H59: Poorly differentiated | I59: 7704 1184 8537 NHSBAC CTA transfer manifest NHSB 373
A60: TS-17 - 1771 | B60: 16D059569 | C60: 16D59569 B47, 16D59569 B55 | D60: supraglottic involving vallecular and right oropharyngeal wall with lymph nodes | F60: BOTH PRIMARY TUMOUR | G60: Basaloid and conventional mixed | H60: Poorly differentiated | I60: 7704 1184 8537 NHSBAC CTA transfer manifest NHSB 373
A61: TS-17 - 1772 | B61: 17D000270 | C61: 17D270 B6, 17D270 B8 | D61: Left lateral tongue, lymph nodes from left radical neck dissection level II | F61: BOTH PRIMARY TUMOUR | G61: - | H61: Poorly differentiated | I61: 7704 1184 8537 NHSBAC CTA transfer manifest NHSB 373
A62: TS-17 - 1773 | B62: 17D001208 | C62: 17D1208 D4, 17D1208 D5 | D62: Right tonsil | F62: Both Bloks are SCC invading the tonsils | G62: Basaloid | H62: Not stated | I62: 7704 1184 8537 NHSBAC CTA transfer manifest NHSB 373
A63: TS-17 - 1774 | B63: 17D007302 | C63: 17D7302 A5, 17D7302 A6 | D63: Right lateral tongue and lymph nodes from right selective neck dissection | F63: BOTH PRIMARY TUMOUR | G63: - | H63: Moderate to poorly differentiated | I63: 7704 1184 8537 NHSBAC CTA transfer manifest NHSB 373
A64: TS-17 - 1775 | B64: 17D020053 | C64: 17D20053 A5, 17D20053 A6 | D64: Right tongue | F64: BOTH PRIMARY TUMOUR | G64: - | H64: Poorly differentiated | I64: 7704 1184 8537 NHSBAC CTA transfer manifest NHSB 373
A65: TS-17 - 1776 | B65: 7012704 | C65: 07/12704 D16, 07/12704 D17 | D65: Left and right supraglottis | F65: BOTH PRIMARY TUMOUR | G65: - | H65: Poorly differentiated | I65: 7704 1184 8537 NHSBAC CTA transfer manifest NHSB 373
A66: TS-17 - 1777 | B66: 7017976 | C66: 07/17976 53, 07/17976 54 | D66: Anterior supraglottis from total laryngectomy and lymph nodes | F66: BOTH PRIMARY TUMOUR | G66: - | H66: Poorly differentiated | I66: 7704 1184 8537 NHSBAC CTA transfer manifest NHSB 373
A67: TS-17 - 1778 | B67: 7021188 | C67: 07/21188 B26, 07/21188 B27 | D67: Right piriform fossa and pharyngeal wall from laryngo-pharyngectomy and lymph nodes | F67: BOTH PRIMARY TUMOUR | G67: - | H67: Poorly differentiated | I67: 7704 1184 8537 NHSBAC CTA transfer manifest NHSB 373
A68: TS-17 - 1779 | B68: 3016778 | C68: 03/16778 D36, 03/16778 D38 | D68: Right tongue, floor of mouth, and lymph node | F68: BOTH PRIMARY TUMOUR | G68: - | H68: Moderately differentiated, focally keratinising | I68: 7704 1184 8537 NHSBAC CTA transfer manifest NHSB 373
A69: TS-17 - 1780 | B69: 3017352 | C69: 03/17352 A7, 03/17352 A8 | D69: Right lateral/ventral tongue | F69: BOTH PRIMARY TUMOUR | G69: - | H69: Moderately differentiated, heavily keratinising | I69: 7704 1184 8537 NHSBAC CTA transfer manifest NHSB 373
A70: TS-17 - 1781 | B70: 98008186 | C70: 98/8186 D2, 98/8186 D3 | D70: Oropharynx right tonsil and lymph nodes | F70: BOTH PRIMARY TUMOUR | G70: - | H70: Moderately differentiated | I70: 7704 1184 8537 NHSBAC CTA transfer manifest NHSB 373
...

Sheet ADC
A1: TriStar ID | B1: Primary lab number | C1: Block/Slide Number | D1: Date Obtained | E1: Procedure Type | F1: Date hormone treatment first given | G1: Date mets first diagnosed | H1: mCRPC or mHSPC | I1: % of Tumour | J1: % of Normal | K1: Ratio of Nucleated | L1: Prior cancer other than prostate | M1: Prior platinum based therapy or PARP | N1: Gleason score | O1: Tumour/ normal surface area | P1: Tumour sub-type or grade / differentiation | Q1: Comments | R1: slides QC | S1: PSA Levels (month-year - Prostate specific AG-EQU ug/L) [acceptable range 0.00 - 5.00] | T1: Manifest
A2: 6670/07 C | B2: 7106670 | C2: 6670/07 C | E2: Prostate TURP (Chips) | F2: - | G2: - | H2: - | I2: - | J2: - | K2: - | L2: - | M2: - | Q2: - | R2: - | S2: Jan-07 - 57.40; Jul-07 - 45.30; Aug-07 - 14.20; Jan-08 - 6.50; May-08 - 3.10; Dec-08 - 1.40; Jun-09 - 1.30; Dec-09 - 1.40; Jun-10 - 2.80; Jul-10 - 1.80; Jan-11 - 2.90; Jul-11 - 5.30; Oct-11 - 6.20; Jan-12 - 7.90; Feb-12 - 10.50; May-12 - 14.60; Aug-12 - 17.10; Nov-12 - 32.40; Jun-13 - 17.90; Sep-13 - 10.20; Dec-13 - 10.40; Apr-14 - 11.80; Jul-14 - 12.10; Oct-14 - 11.70; Apr-15 - 14.10; Jul-15 - 19.90; Oct-15 - 9.40. | T2: 7775-1317-3171 (1418) transfer manifest NHSBAC CTA
A3: 2938/04 B | B3: 4102938 | C3: 2938/04 B | E3: Prostate TURP (Chips) | F3: - | G3: - | H3: - | I3: - | J3: - | K3: - | L3: - | M3: - | Q3: - | R3: - | S3: Nov-03 - 64.60; Dec-03 - 67.50; May-04 - 79.10; Aug-04 - 12.50; Jan-05 - 7.50; Aug-05 - 4.10; Feb-06 - 10.30; Oct-06 - 19.90; Apr-07 - 28.00; Oct-07 - 42.80; Jan-08 - 73.70; May-08 - 60.10; Aug-08 - 25.60; Jan-09 - 78.20; Mar-10 - 459.00. | T3: 7775-1317-3171 (1418) transfer manifest NHSBAC CTA
A4: 9421/04 H | B4: 4109421 | C4: 9421/04 H | E4: Prostate TURP (Chips) | F4: - | G4: - | H4: - | I4: - | J4: - | K4: - | L4: - | M4: - | Q4: - | R4: - | S4: Apr-04 - 29.60; Dec-04 - 34.90; Apr-05 - 109.00; Jul-05 - 1.80; Aug-05 - 2.50; Jan-06 - 0.40; May-06 - 0.70; Sep-06 - 4.00; Nov-06 - 12.10; Dec-06 - 12.00; Feb-07 - 8.10; Apr-07 - 6.40; Jul-07 - 11.90; Aug-07 - 24.40 and 30.10. | T4: 7775-1317-3171 (1418) transfer manifest NHSBAC CTA
A5: 5020/06 B | B5: 6105020 | C5: 5020/06 B | E5: Prostate TURP (Chips) | F5: - | G5: - | H5: - | I5: - | J5: - | K5: - | L5: - | M5: - | Q5: - | R5: - | S5: Apr-00 - 12.7; Sep-05 - 5.00; Jun-06 - 3.00; Jan-07 - 5.90; Sep-07 - 6.40; Apr-08 - 8.50; Sep-08 - 5.80; Mar-09 - 5.60; Apr-09 - 6.20; Sep-09 - 9.20; Mar-10 - 14.90; Aug-10 - 35.10; Sep-10 - 8.80; Nov-10 - 1.10; Mar-11 - 0.58; May-11 - 0.49; May-11 - 0.53; Sep-11 - 0.86; Oct-11 - 0.94; Jan-12 - 1.40; Apr-12 - 3.60; May-12 - 4.50; Jul-12 - 29.20; Aug-12 - 96.00. | T5: 7775-1317-3171 (1418) transfer manifest NHSBAC CTA
A6: 10343/06 A | B6: 6110343 | C6: 10343/06 A | E6: Prostate TURP (Chips) | F6: - | G6: - | H6: - | I6: - | J6: - | K6: - | L6: - | M6: - | Q6: - | R6: - | S6: Dec-03 - 21.0; Apr-04 - 30.8; Mar-06 - 54.50; May-07 - 0.80; Sep-07 - 1.40; Apr-08 - 3.00; Jul-08 - 4.30; Oct-08 - 4.00; Jan-09 - 5.20; May-09 - 5.50; Jul-09 - 6.00; Nov-09 - 5.50; Feb-10 - 6.50; May-10 - 6.90; Jun-10 - 6.60; Aug-10 - 6.10; Dec-10 - 6.70; May-11 - 55.00; Jul-11 - 289.00. | T6: 7775-1317-3171 (1418) transfer manifest NHSBAC CTA
A7: 11461/06 H | B7: 6111461 | C7: 11461/06 H | E7: Prostate TURP (Chips) | F7: - | G7: - | H7: - | I7: - | J7: - | K7: - | L7: - | M7: - | Q7: - | R7: - | S7: Aug-04 - 40.50 and 47.50; Dec-04 - 3.00; Mar-05 - 0.60; Jul-05 - 4.10; Sep-05 - 7.40; Mar-06 - 27.30; Apr-06 - 27.10; Aug-06 - 316.00; Sep-06 - 149.00. | T7: 7775-1317-3171 (1418) transfer manifest NHSBAC CTA
A8: 12D6505 A1 | B8: 12D006505 | C8: 12D6505 A1 | E8: Prostate TURP (Chips) | F8: - | G8: - | H8: - | I8: - | J8: - | K8: - | L8: - | M8: - | Q8: - | R8: - | S8: Nov-11 - 8.29; Apr-12 - 0.14; Nov-14 - 10.00; Dec-14 - 3.10; Jan-15 - 1.80; Feb-15 - 1.00; Mar-15 - 0.73; May-15 - 0.64; Jul-15 - 0.89; Sep-15 - 2.30; Oct-15 - 1.20; Nov-15 - 1.40; Dec-15 - 3.70; Jan-16 - 9.30; Mar-16 - 11.90; Apr-16 - 17.40; May-16 - 26.90. | T8: 7775-1317-3171 (1418) transfer manifest NHSBAC CTA
A9: 15671/04 3B | B9: 4115671 | C9: 15671/04 3B | E9: Radical prostatectomy | F9: - | G9: - | H9: - | I9: - | J9: - | K9: - | L9: - | M9: - | Q9: - | R9: - | S9: Jul-04 - 17.0; Apr-05 - 0.60; Jun-05 - <0.10; Jul-05 - 0.10; Oct-05 - 0.20; Jan-06 - 0.50; May-06 - 2.80 and 4.40; Jun-06 - 4.70; Jul-06 - 0.30; Dec-06 - <0.10; Apr-07 - 0.10; Jun-07 - 1.20; Sep-07 - 2.30; Jan-08 - 7.60; Feb-08 - 14.90; Mar-08 - 14.80; Apr-08 - 13.40; May-08 - 26.80; Jun-08 - 62.60 and 88.60; Jul-08 - 115.00 and 160.00; Aug-08 - 192.00 and 228.00; Sep-08 - 205.00; Oct-08 - 252.00; Nov-08 - 335.00 and 389.00; Nov-08 - 368.00; Jan-09 - 249.00; Apr-09 - 504.00; Jun-09 - 804.00; Jul-09 - 1390.00; Aug-09 - 1282.00 and 1427.00; Sep-09 - 1682.00 and 2228.00; Oct-09 - 2138.00; Nov-09 - 1215.00; Dec-09 - 886.00; Jan-10 - 1476.00. | T9: 7775-1317-3171 (1418) transfer manifest NHSBAC CTA
A10: 10A19304 A2 BB1 | B10: 10A019304 | C10: 10A19304 A2 BB1 | E10: Prostate TURP (Chips) | F10: - | G10: - | H10: - | I10: - | J10: - | K10: - | L10: - | M10: - | Q10: - | R10: - | S10: Jan-02 - 29.60; Apr-02 - 23.00; Aug-02 - 1.70; Sep-02 - 1.50; Mar-03 - 1.10; Jul-03 - 0.80; Jun-04 - 2.50; Jul-04 - 3.60; Apr-06 - 1.30; Aug-06 - 1.10; Nov-06 - 1.90; Jan-07 - 7.70; May-07 - 16.00; Aug-07 - 3.00; Mar-08 - 3.20; May-08 - 17.40; Aug-08 - 7.40; Jan-09 - 5.50; May-09 - 26.50; Aug-09 - 7.10; Mar-10 - 5.20; Jun-10 - 11.50; Jan-11 - 5.00; Apr-11 - 19.80; Nov-11 - 7.10; May-12 - 6.10; Aug-12 - 25.00; Nov-12 - 10.50; May-13 - 8.10; Oct-13 - 18.30; Nov-13 - 12.10; Feb-14 - 23.00; May-14 - 8.60; Aug-14 - 26.10; Oct-14 - 10.20; May-15 - 12.20; Sep-15 - 29.80; Dec-15 - 14.50; Mar-16 - 12.80; Apr-16 - 15.90; Jul-16 - 16.00. | T10: 7775-1317-3171 (1418) transfer manifest NHSBAC CTA
A11: 5485/07 A BB1 | B11: 7105485 | C11: 5485/07 A BB1 | E11: Prostate TURP (Chips) | F11: - | G11: - | H11: - | I11: - | J11: - | K11: - | L11: - | M11: - | Q11: - | R11: - | S11: Jun-99 - 29.8; Aug-00 - 2.5; Dec-00 - 12.1; Mar-01 - <1.0; Oct-01 - <1.0; Oct-02 - <1.0 Feb-03 - 0.20; Nov-05 - 1.30; Aug-06 - 1.50; Jan-07 - 8.10; Jul-07 - 19.40; Sep-07 - 17.90; Nov-07 - 23.80; Dec-07 - 30.60; Mar-08 - 96.40 and 112.00; Apr-08 - 181.00; May-08 - 140.00; Jun-08 - 184.00; Jul-08 - 287.00; Aug-08 - 251.00; Oct-08 - 328.00; Nov-08 - 388.00; Jan-09 - 438.00 and 417.00. | T11: 7775-1317-3171 (1418) transfer manifest NHSBAC CTA
A12: 15659/00 C | B12: 115659 | C12: 15659/00 C | E12: Prostate TURP (Chips) | F12: - | G12: - | H12: - | I12: - | J12: - | K12: - | L12: - | M12: - | Q12: - | R12: - | S12: Jun-00 - 27.0; Jan-02 - 83.20; Feb-03 - 3.50; Sep-03 - 0.10; Jan-04 - 0.20; Jul-04 - 1.60; Sep-04 - 0.40; Jan-05 - 6.10; May-05 - 0.10; Jul-05 - 9.70; Nov-05 - 1.70; Feb-06 - 65.40; Jun-06 - 512.00; Sep-06 - 1003.00; Feb-07 - 3648.00. | T12: 7775-1317-3171 (1418) transfer manifest NHSBAC CTA
A13: 21756/02 2D | B13: 2121756 | C13: 21756/02 2D | E13: Prostate TURP (Chips) | F13: - | G13: - | H13: - | I13: - | J13: - | K13: - | L13: - | M13: - | Q13: - | R13: - | S13: Jul-02 - 49.70; Mar-03 - 7.60; Jun-03 - 0.70; May-04 - 0.30; Aug-04 - 0.30; Nov-04 - 0.60; Feb-05 - 1.10; Aug-05 - 3.40; Dec-05 - 7.70; Mar-06 - 5.20; Apr-06 - 4.90; May-06 - 4.20; Jun-06 - 3.00; Nov-06 - 1.10; Mar-07 - 0.30; Jun-07 - 0.20; Oct-07 - 0.70; Nov-07 - 1.30; Mar-08 - 3.60; Jan-09 - 17.80; Feb-09 - 19.40; Apr-09 - 10.20; Jun-09 - 3.40; Jul-09 - 4.30; Sep-09 - 12.20; Oct-09 - 13.50; Dec-09 - 52.40 and 31.90. | T13: 7775-1317-3171 (1418) transfer manifest NHSBAC CTA
A14: 18455/01 F | B14: 1118455 | C14: 18455/01 F | E14: Prostate TURP (Chips) | F14: - | G14: - | H14: - | I14: - | J14: - | K14: - | L14: - | M14: - | Q14: - | R14: - | S14: Sep-01 - 92.7; Oct-01 - 82.60; Dec-01 - 3.80; Sep-02 - 0.10; Mar-03 - 0.10; Sep-03 - 0.10; Mar-04 - 0.10; Oct-04 - 0.10; Mar-05 - 0.10; Feb-06 - 0.10; Jul-10 - 2.10; Sep-10 - 0.58; Dec-15 - 31.20; May-16 - 49.80. | T14: 7775-1317-3171 (1418) transfer manifest NHSBAC CTA
A15: 14440/05 C | B15: 5114440 | C15: 14440/05 C | E15: Prostate TURP (Chips) | F15: - | G15: - | H15: - | I15: - | J15: - | K15: - | L15: - | M15: - | Q15: - | R15: - | S15: Oct-04 - 20.9; May-05 - 1.40; Aug-05 - 2.30; Dec-05 - 3.20; Mar-06 - 8.40; Apr-06 - 12.40; Jun-06 - 18.90; Jul-06 - 26.20; Sep-06 - 43.50; Oct-06 - 109.00. | T15: 7775-1317-3171 (1418) transfer manifest NHSBAC CTA
A16: 3152/06 D | B16: 6103152 | C16: 3152/06 D | E16: Prostate TURP (Chips) | F16: - | G16: - | H16: - | I16: - | J16: - | K16: - | L16: - | M16: - | Q16: - | R16: - | S16: Dec-02 - 6.00; Jan-03 - 6.30; Apr-03 - 0.10; Aug-03 - 0.10; Jan-04 - 0.20; Jul-04 - 0.80; Oct-04 - 1.60; Mar-05 - 2.60; Jun-05 - 2.40; Sep-05 - 3.80; Dec-05 - 6.10; Jun-06 - 3.90; Oct-06 - 6.50; Nov-06 - 18.80; Jan-07 - 17.40; Feb-07 - 6.40; Mar-07 - 3.50; Apr-07 - 3.10; May-07 - 2.10; Jun-07 - 3.80; Jul-07 - 3.20; Aug-07 - 3.70; Sep-07 - 5.10; Dec-07 - 21.70; Jan-08 - 55.30. | T16: 7775-1317-3171 (1418) transfer manifest NHSBAC CTA
A17: 2132/07 B | B17: 7102132 | C17: 2132/07 B | E17: Prostate TURP (Chips) | F17: - | G17: - | H17: - | I17: - | J17: - | K17: - | L17: - | M17: - | Q17: - | R17: - | S17: May-06 - 21.10; Apr-07 - 14.20; Sep-07 - 4.50; Feb-08 - 4.60; Sep-08 - 23.40; Dec-08 - 21.10; May-09 - 15.50; Sep-09 - 16.50; Jan-10 - 21.70; Apr-10 - 22.70; Aug-10 - 29.50; Dec-10 - 55.10; May-11 - 95.90; Aug-11 - 186.00. | T17: 7775-1317-3171 (1418) transfer manifest NHSBAC CTA
A18: 2190/07 B | B18: 7102190 | C18: 2190/07 B | E18: Prostate TURP (Chips) | F18: - | G18: - | H18: - | I18: - | J18: - | K18: - | L18: - | M18: - | Q18: - | R18: - | S18: Dec-06 - 37.00; Feb-07 - 35.0; Mar-07 - 15.10; Apr-07 - 29.20; Jun-07 - 7.30; Aug-07 - 3.70 and 2.00; Jan-08 - 0.60; May-08 - 1.10; Oct-08 - 3.80; Jan-09 - 6.40; Mar-09 - 8.70. | T18: 7775-1317-3171 (1418) transfer manifest NHSBAC CTA
A19: NO-SKU | B19: 7108760 | C19: 8760/07 B | E19: Prostate TURP (Chips) | F19: - | G19: - | H19: - | I19: - | J19: - | K19: - | L19: - | M19: - | Q19: - | R19: - | S19: May-96 - 101.0; Jul-96 - 0.4; Oct-96 - 0.1; Apr-97 - 0.1; Oct-97 - 0.1; Jul-98 - 0.1; Apr-99 - <0.1; Oct-99 - <0.1; Apr-00 - <0.1; May-01 - 0.8; Oct-06 - 6.80; Apr-07 - 9.80; Jul-07 - 6.60; Sep-07 - 7.50; Dec-07 - 9.70; May-08 - 12.30; Aug-08 - 14.30; Nov-08 - 13.10; Dec-08 - 16.90; Apr-09 - 22.00; Oct-10 - 62.90; May-11 - 33.50; Feb-12 - 266.00; Jun-12 - 441.00; Jul-12 - 680.00; Sep-12 - 1441.00. | T19: 7775-1317-3171 (1418) transfer manifest NHSBAC CTA
A20: 5746/07 B | B20: 7105746 | C20: 5746/07 B | E20: Prostate TURP (Chips) | F20: - | G20: - | H20: - | I20: - | J20: - | K20: - | L20: - | M20: - | Q20: - | R20: - | S20: Nov-06 - 47.90; Apr-08 - 3.10; Aug-08 - 2.30; Apr-09 - 2.30; Oct-09 - 1.70; Apr-10 - 1.50; Oct-10 - 1.60; Jun-11 - 2.30; Mar-12 - 14.10; Aug-12 - 27.80; Nov-12 - 12.70; Feb-13 - 10.30; May-13 - 8.00; Aug-13 - 3.80; Nov-13 - 10.70; Dec-13 - 6.60; Jan-14 - 8.80; Jan-14 - 15.10; Feb-14 - 8.30; Mar-14 - 3.30; Apr-14 - 2.40; May-14 - 1.90; Jun-14 - 1.60; Jul-14 - 1.40; Aug-14 - 1.40; Sep-14 - 1.20; Oct-14 - 1.20; Nov-14 - 1.10; Dec-14 - 0.96; Jan-15 - 0.90; Feb-15 - 0.89; Mar-15 - 1.30; Apr-15 - 1.30; May-15 - 1.30; Jun-15 - 1.50; Jul-15 - 1.20; Aug-15 - 1.40; Sep-15 - 1.60; Oct-15 - 2.00; Nov-15 - 2.30; Dec-15 - 2.50; Jan-16 - 2.90; Feb-16 - 4.40; Mar-16 - 4.20; Jun-16 - 2.40. | T20: 7775-1317-3171 (1418) transfer manifest NHSBAC CTA
A21: 3802/07 B | B21: 7103802 | C21: 3802/07 B | E21: Prostate TURP (Chips) | F21: - | G21: - | H21: - | I21: - | J21: - | K21: - | L21: - | M21: - | Q21: - | R21: - | S21: Nov-96 - 217.0; Jan-97 - 174.0; May-97 - 14.0; Sep-97 - 3.2; Dec-97 - 1.3; Mar-98 - 0.9; Jul-98 - 0.8; Jan-99 - 0.7; Apr-99 - 12.6; Jun-99 - 3.6; Aug-99 - 2.0; Nov-99 - 5.7; Feb-00 - 2.8; Aug-00 - 17.4; Dec-00 - 5.2; Mar-01 - 7.5; Apr-01 - 6.9; Jul-01 - 6.0; Oct-01 - 4.0; Oct-01 - 5.10; Feb-02 - 6.10; Aug-02 - 7.20; Oct-02 - 6.40; Feb-03 - 20.00 and 22.60; May-03 - 19.40; Aug-03 - 17.10; Jan-04 - 14.90; Mar-04 - 33.40; Apr-04 - 36.70; Jun-04 - 26.00; Sep-04 - 21.80; Dec-04 - 20.50; Jun-05 - 15.20; Jan-06 - 29.50; Apr-06 - 38.40; May-06 - 68.60; Jun-06 - 56.70; Aug-06 - 67.80; Sep-06 - 88.10; Oct-06 - 73.20; Jan-07 - 80.70; Jun-07 - 104.00; Aug-07 - 153.00; Nov-07 - 182.00; Jan-08 - 213.00; Feb-08 - 189.00; Apr-08 - 200.00; Jul-08 - 175.00; Aug-08 - 260.00; Oct-08 - 417.00; Jan-09 - 1566.00. | T21: 7775-1317-3171 (1418) transfer manifest NHSBAC CTA
A22: 2550/07 A | B22: 7102550 | C22: 2550/07 A | E22: Prostate TURP (Chips) | F22: - | G22: - | H22: - | I22: - | J22: - | K22: - | L22: - | M22: - | Q22: - | R22: - | S22: Jul-04 - 137.00; Feb-06 - 13.60; Aug-06 - 70.50; Nov-06 - 192.00. | T22: 7775-1317-3171 (1418) transfer manifest NHSBAC CTA
... A71: NO-SKU | B71: 6109597 | C71: 9497/06 D | E71: Prostate TURP (Chips) | F71: - | G71: - | H71: - | I71: - | J71: - | K71: - | L71: - | M71: - | Q71: - | R71: - | S71: Sep-06 - 79.20; Nov-06 - 146.00; Mar-07 - 1.60; Jul-07 - 1.20; Oct-07 - 1.20; Nov-07 - 1.00; Jan-08 - 1.40; Apr-08 - 1.20; Jul-08 - 1.60; Oct-08 - 2.20; Jan-09 - 2.80; Apr-09 - 6.00; Jul-09 - 7.40; Aug-09 - 6.90; Nov-09 - 8.10; Feb-10 - 23.70; Jun-10 - 17.20; Sep-10 - 22.00; Jan-11 - 34.50; May-11 - 49.70; Jul-11 - 25.10; Sep-11 - 30.00; Jan-12 - 76.50; May-12 - 44.40; Aug-12 - 30.30; Sep-12 - 28.10; Jan-13 - 45.70; Feb-13 - 44.30; Jun-13 - 50.00; Sep-13 - 58.30; Dec-13 - 68.50; Jul-14 - 157.00; Sep-14 - 184.00; Dec-14 - 323.00; Mar-16 - 2217.00. | T71: 7775-1317-3171 (1418) transfer manifest NHSBAC CTA
A72: TS-16 - 0868 | B72: 08A012588 | C72: 08A12588 A2 | E72: TURP | F72: 39826 | G72: 40057 | H72: mCRPC | I72: 60 | J72: 40 | K72: >30% | L72: No | M72: No | R72: mainly T | S72: - | T72: 7771 6591 7537 (1433-01) transfer manifest NHSBAC CTA LM QC-2
A73: TS-16 - 0869 | B73: 08A015508 | C73: 08A15508 A2 | E73: TURP | F73: 39468 | G73: 39898 | H73: mCRPC | I73: 50 | J73: 50 | K73: >30% | L73: No | M73: No | P73: Poor | R73: mainly T | S73: - | T73: 7771 6591 7537 (1433-01) transfer manifest NHSBAC CTA LM QC-2
A74: TS-16 - 0870 | B74: 08A018815 | C74: 08A18815 A3 | E74: TURP | F74: 39849 | G74: 39828 | H74: mHSPC | I74: 70 | J74: 30 | K74: >30% | L74: No | M74: No | Q74: - | R74: mainly T | S74: - | T74: 7771 6591 7537 (1433-01) transfer manifest NHSBAC CTA LM QC-2
A75: TS-16 - 0871 | B75: 08A007174 | C75: 08A7174 A3 | E75: TURP | F75: 39979 | G75: 40000 | H75: mCRPC | I75: 70 | J75: 30 | K75: >30% | L75: No | M75: No | Q75: - | R75: mainly T | S75: - | T75: 7771 6591 7537 (1433-01) transfer manifest NHSBAC CTA LM QC-2
A76: TS-16 - 0873 | B76: 08A007593 | C76: 08A7593 A2 | E76: TURP | F76: 39657 | G76: 39647 | H76: mCRPC | I76: 60-65 | J76: 35-40 | K76: >30% | L76: No | M76: No | Q76: - | R76: mainly T | S76: - | T76: 7771 6591 7537 (1433-01) transfer manifest NHSBAC CTA LM QC-2
A77: TS-16 - 0878 | B77: 09A000352 | C77: 09A352 A1 | E77: TURP | F77: 40330 | G77: 40317 | H77: mCRPC | I77: 40 | J77: 60 | K77: >30% | L77: No | M77: No | Q77: - | R77: mainly T | S77: - | T77: 7771 6591 7537 (1433-01) transfer manifest NHSBAC CTA LM QC-2
A78: TS-16 - 0881 | B78: 10A015316 | C78: 10A15316 A2 | E78: TURP | F78: 38642 | G78: 41376 | H78: mCRPC | I78: 75-80 | J78: 20-25 | K78: >30% | L78: No | M78: No | Q78: - | R78: mainly T | S78: - | T78: 7771 6591 7537 (1433-01) transfer manifest NHSBAC CTA LM QC-2
A79: TS-16 - 0883 | B79: 11A006982 | C79: 11A6982 A3 | E79: TURP | F79: 39148 | G79: 40841 | H79: mHSPC | I79: 50 | J79: 50 | K79: >30% | L79: No | M79: No | Q79: - | R79: mainly T | S79: - | T79: 7771 6591 7537 (1433-01) transfer manifest NHSBAC CTA LM QC-2
A80: TS-16 - 0886 | B80: 12D001927 | C80: 12D1927 A6 | E80: TURP | F80: 40976 | G80: 40950 | H80: mHSPC | I80: 65 | J80: 35 | K80: >30% | L80: No | M80: No | P80: Focally positive for CD56 and chromogranin, indicative of neuroendocrine differentiation | Q80: 1 cycle carboplatin and etoposide chemotherapy 2 months after TURP | R80: mainly T | S80: - | T80: 7771 6591 7537 (1433-01) transfer manifest NHSBAC CTA LM QC-2
A81: TS-16 - 0885 | B81: 12D052368 | C81: 12D52368 A3 | E81: TURP | F81: 42118 | G81: 42123 | H81: mCRPC | I81: 50 | J81: 50 | K81: >30% | L81: No | M81: No | Q81: - | R81: mainly T | S81: - | T81: 7771 6591 7537 (1433-01) transfer manifest NHSBAC CTA LM QC-2
A82: TS-16 - 0888 | B82: 13D052750 | C82: 13D052750 A2 | E82: TURP | F82: 41418 | G82: 41403 | H82: mCRPC | I82: 65 | J82: 35 | K82: >30% | L82: No | M82: No | Q82: - | R82: mainly T | S82: - | T82: 7771 6591 7537 (1433-01) transfer manifest NHSBAC CTA LM QC-2
A83: TS-16 - 0891 | B83: 3102763 | C83: 2763/03 C | E83: TURP | F83: 37875 | G83: 37861 | H83: mCRPC | I83: 60 | J83: 40 | K83: >30% | L83: No | M83: No | Q83: - | R83: mainly T | S83: - | T83: 7771 6591 7537 (1433-01) transfer manifest NHSBAC CTA LM QC-2
A84: TS-16 - 0892 | B84: 3108477 | C84: 8477/03 D | E84: TURP | F84: 39294 | G84: 39421 | H84: mCRPC | I84: 45 | J84: 55 | K84: >30% | L84: No | M84: No | Q84: - | R84: mainly T | S84: - | T84: 7771 6591 7537 (1433-01) transfer manifest NHSBAC CTA LM QC-2
A85: TS-16 - 0867 | B85: 08A011715 | C85: 08A11715 A2 | E85: TURP | F85: 39709 | G85: 39693 | H85: mCRPC | I85: 50-60 | J85: 40-50 | K85: >30% | L85: No | M85: No | Q85: - | R85: T+N | S85: - | T85: 7771 6591 7537 (1433-01) transfer manifest NHSBAC CTA LM QC-2
A86: TS-16 - 0872 | B86: 08A007457 | C86: 08A7457 A4 | E86: TURP | F86: 39686 | G86: 39639 | H86: mCRPC | I86: 60 | J86: 40 | K86: >30% | L86: No | M86: No | Q86: - | R86: T+N | S86: - | T86: 7771 6591 7537 (1433-01) transfer manifest NHSBAC CTA LM QC-2
A87: TS-16 - 0877 | B87: 09A016464 | C87: 09A16464 A4 | E87: TURP | F87: 40129 | G87: 40145 | H87: mCRPC | I87: 60-70 | J87: 30-40 | K87: >30% | L87: No | M87: No | Q87: - | R87: T+N | S87: - | T87: 7771 6591 7537 (1433-01) transfer manifest NHSBAC CTA LM QC-2
A88: TS-16 - 0879 | B88: 09A000709 | C88: 09A709 A6 | E88: Radical Prostatcetomy | F88: 41968 | G88: 42018 | H88: mCRPC | I88: 50-60 | J88: 50-60 | K88: >30% | L88: No | M88: No | Q88: - | R88: T+N | S88: - | T88: 7771 6591 7537 (1433-01) transfer manifest NHSBAC CTA LM QC-2
...

Sheet FISH
A1: TriStar ID | B1: Case | C1: Date of Procedure | D1: 4/1 (GR) | E1: 4/2 (GR) | F1: 3/2 (GR) | G1: 3/1 (GR) | H1: 1/0 (GR) | I1: 2/0 (GR) | J1: 2/1 (GR) | K1: 2/2 (GR) | L1: 1/2 (GR) | M1: 1/1 (GR) | N1: Total N Cells Count | O1: Total N Cells for Statistics | P1: Status | Q1: HRPC Status confirmed | R1: Manifest
A2: 09A16464 A3 | B2: 09A16464 A3 | C2: 42632 | D2: 0 (0%) | E2: 0 (0%) | F2: 6 (7%) | G2: 3 (3%) | H2: 3 (3%) | I2: 2 (2%) | J2: 14 (15%) | K2: 62 (67%) | L2: 2 (2%) | M2: 8 | N2: 100 | O2: 92 | P2: Negative | Q2: Yes | R2: 7773-9327-9932 (1397) transfer manifest NHSBAC CTA
A3: TS-16 - 1019 | B3: 08A12967 A6 | C3: 42632 | D3: 0 (0%) | E3: 0 (0%) | F3: 5 (5%) | G3: 20 (21%) | H3: 5 (5%) | I3: 6 (6%) | J3: 45 (48%) | K3: 11 (12%) | L3: 2 (2%) | M3: 10 | N3: 104 | O3: 94 | P3: PTEN Depleted | Q3: Yes | R3: 7773-9327-9932 (1397) transfer manifest NHSBAC CTA
A4: 09A709 A7 | B4: 09A709 A7 | C4: 42632 | D4: 0 (0%) | E4: 0 (0%) | F4: 1 (1%) | G4: 8 (8%) | H4: 1 (1%) | I4: 1 (1%) | J4: 49 (48%) | K4: 37 (36%) | L4: 7 (7%) | M4: 15 | N4: 117 | O4: 102 | P4: PTEN Depleted | Q4: Yes | R4: 7773-9327-9932 (1397) transfer manifest NHSBAC CTA
A5: 08A13674 A4 | B5: 08A13674 A4 | C5: 42632 | D5: 0 (0%) | E5: 0 (0%) | F5: 5 (4%) | G5: 3 (2%) | H5: 2 (2%) | I5: 4 (3%) | J5: 54 (42%) | K5: 38 (30%) | L5: 23 (18%) | M5: 8 | N5: 137 | O5: 129 | P5: Negative | Q5: Yes | R5: 7773-9327-9932 (1397) transfer manifest NHSBAC CTA
A6: 10A17124 A3 | B6: 10A17124 A3 | C6: 42632 | D6: 0 (0%) | E6: 0 (0%) | F6: 3 (3%) | G6: 3 (3%) | H6: 5 (4%) | I6: 2 (2%) | J6: 7 (6%) | K6: 83 (72%) | L6: 4 (3%) | M6: 9 | N6: 116 | O6: 107 | P6: Negative | Q6: Yes | R6: 7773-9327-9932 (1397) transfer manifest NHSBAC CTA
A7: 08A7457 A2 | B7: 08A7457 A2 | C7: 42632 | D7: 0 (0%) | E7: 0 (0%) | F7: 2 (2%) | G7: 20 (16%) | H7: 10 (9%) | I7: 12 (11%) | J7: 61 (57%) | K7: 9 (8%) | L7: 3 (3%) | M7: 12 | N7: 107 | O7: 95 | P7: PTEN Depleted | Q7: Yes | R7: 7773-9327-9932 (1397) transfer manifest NHSBAC CTA
A8: 593/02 D | B8: 593/02 D | C8: 42577 | D8: 2 (1%) | E8: 1 (≈ 0.0%) | F8: 5 (5%) | G8: 4 (4%) | H8: 4 (4%) | I8: 7 (7%) | J8: 55 (57%) | K8: 15 (15%) | L8: 2 (2%) | M8: 10 | N8: 105 | O8: 95 | P8: PTEN Depleted | Q8: Yes | R8: 7773-9327-9932 (1397) transfer manifest NHSBAC CTA
A9: 20718/02 B | B9: 20718/02 B | C9: 42597 | D9: 0 (0%) | E9: 0 (0%) | F9: 7 (8%) | G9: 3 (3%) | H9: 1 (1%) | I9: 5 (5%) | J9: 23 (26%) | K9: 45 (52%) | L9: 2 (2%) | M9: 23 | N9: 109 | O9: 86 | P9: Negative | Q9: Yes | R9: 7773-9327-9932 (1397) transfer manifest NHSBAC CTA
A10: 5391/02 C | B10: 5391/02 C | C10: 42597 | D10: 0 (0%) | E10: 3 (3%) | F10: 2 (2%) | G10: 20 (22%) | H10: 0 (0%) | I10: 0 (0%) | J10: 50 (56%) | K10: 11 (12%) | L10: 2 (2%) | M10: 41 | N10: 129 | O10: 88 | P10: PTEN Depleted | Q10: Yes | R10: 7773-9327-9932 (1397) transfer manifest NHSBAC CTA
A11: 17572/02 C | B11: 17572/02 C | C11: 42597 | D11: 0 (0%) | E11: 5 (3%) | F11: 4 (2%) | G11: 9 (6%) | H11: 6 (4%) | I11: 4 (2%) | J11: 36 (25%) | K11: 73 (51%) | L11: 6 (4%) | M11: 20 | N11: 163 | O11: 143 | P11: Negative | Q11: Yes | R11: 7773-9327-9932 (1397) transfer manifest NHSBAC CTA

Sheet Sheet4
A1: Original ID | B1: TriStar ID
A2: 08A13674 A4 | B2: 08A13674 A4
A3: 08A7021 A1 | B3: 08A7021 A1
A4: 08A7457 A2 | B4: 08A7457 A2
A5: 09A10605 A8 | B5: 09A10605 A8
A6: 09A15013 B10 | B6: 09A15013 B10
A7: 09A16004 A3 | B7: 09A16004 A3
A8: 09A16464 A3 | B8: 09A16464 A3
A9: 09A17429 A4 | B9: 09A17429 A4
A10: 09A4009 A4 | B10: 09A4009 A4
A11: 09A709 A7 | B11: 09A709 A7
A12: 09A7173 A14 | B12: 09A7173 A14
... A1065: 9479/98 | B1065: TS-15 - 0052
A1066: 14 | B1066: TS-15 - 0053
A1067: 40 | B1067: TS-15 - 0054
A1068: 49 | B1068: TS-15 - 0055
A1069: 55 | B1069: TS-15 - 0056
A1070: 60 | B1070: TS-15 - 0057
A1071: 68 | B1071: TS-15 - 0058
A1072: 71 | B1072: TS-15 - 0059
A1073: 75 | B1073: TS-15 - 0060
A1074: 88 | B1074: TS-15 - 0061
A1075: 94 | B1075: TS-15 - 0062
A1076: 96 | B1076: TS-15 - 0063
A1077: 97 | B1077: TS-15 - 0064
... A1090: 161 | B1090: TS-15 - 0077
A1091: 164 A | B1091: TS-15 - 0078
A1092: 164 B | B1092: TS-15 - 0079
A1093: 172 | B1093: TS-15 - 0080
A1094: 229 | B1094: TS-15 - 0081
A1095: 232 | B1095: TS-15 - 0082
A1096: 233 | B1096: TS-15 - 0083
A1097: 239 | B1097: TS-15 - 0084
A1098: 244 | B1098: TS-15 - 0085
A1099: 249 | B1099: TS-15 - 0086
A1100: 250 | B1100: TS-15 - 0087
A1101: 259 | B1101: TS-15 - 0088
A1102: 261 | B1102: TS-15 - 0089
A1103: 264 | B1103: TS-15 - 0090
A1104: 265 | B1104: TS-15 - 0091
...

Sheet Sheet2
A1: SAMPLE ID# | B1: Original ID | C1: Gender | D1: Age | E1: T | F1: N | G1: M | H1: Grade | I1: Stage | J1: Type | K1: Sub-Type | L1: KRAS Mutation | M1: EGFR Mutation
A2: 276H001 | B2: 276H001 | C2: M | D2: 66-70 | E2: 3 | F2: 2a | G2: 0 | H2: / | I2: / | J2: HeN Pri. | K2: SCC | L2: / | M2: /
A3: 276H002 | B3: 276H002 | C3: M | D3: 51-55 | E3: 4 | F3: 0 | G3: 0 | H3: / | I3: / | J3: HeN Pri. | K3: SCC | L3: / | M3: /
A4: 276H003 | B4: 276H003 | C4: M | D4: 65-70 | E4: 4 | F4: 0 | G4: 0 | H4: / | I4: / | J4: HeN Pri. | K4: SCC | L4: / | M4: /
A5: 276H004 | B5: 276H004 | C5: M | D5: 56-60 | E5: 2 | F5: 2 | G5: 0 | H5: / | I5: / | J5: HeN Pri. and Nodal Met. | K5: SCC | L5: / | M5: /
A6: 276H005 | B6: 276H005 | C6: M | D6: 71-73 | E6: 1 | F6: 2 | G6: 0 | H6: / | I6: / | J6: HeN Pri. | K6: SCC | L6: / | M6: /
A7: 276H006 | B7: 276H006 | C7: M | D7: 61-65 | E7: / | F7: / | G7: / | H7: / | I7: / | J7: HeN Nodal Met. | K7: SCC | L7: / | M7: /
A8: 276H008 | B8: 276H008 | C8: M | D8: 81-85 | E8: 2 | F8: 1 | G8: 0 | H8: / | I8: / | J8: HeN Pri. | K8: SCC | L8: / | M8: /
A9: 276H009 | B9: 276H009 | C9: M | D9: 76-80 | E9: 4 | F9: 0 | G9: 0 | H9: / | I9: / | J9: HeN Pri. | K9: SCC | L9: / | M9: /
A10: 276H011 | B10: 276H011 | C10: M | D10: 51-55 | E10: 4 | F10: 2 | G10: 0 | H10: / | I10: / | J10: HeN Pri. and Nodal Met. | K10: SCC | L10: / | M10: /
A11: 276H013 | B11: 276H013 | C11: M | D11: 53-60 | E11: 4 | F11: 0 | G11: 0 | H11: / | I11: / | J11: HeN Pri. | K11: SCC | L11: / | M11: /
A12: 276H014 | B12: 276H014 | C12: M | D12: 46-50 | E12: / | F12: / | G12: / | H12: / | I12: / | J12: HeN Pri. and Nodal Met. | K12: SCC | L12: / | M12: /
A13: 276H015 | B13: 276H015 | C13: M | D13: 51-55 | E13: 2 | F13: 2b | G13: 0 | H13: / | I13: / | J13: HeN Pri. and Nodal Met. | K13: SCC | L13: / | M13: /
A14: 276H016 | B14: 276H016 | C14: No Data Received | D14: No Data Received | E14: No Data Received | F14: No Data Received | G14: No Data Received | H14: No Data Received | I14: No Data Received | J14: HeN Pri. | K14: SCC | L14: / | M14: /
A15: 276H017 | B15: 276H017 | C15: M | D15: 41-45 | E15: / | F15: / | G15: / | H15: / | I15: / | J15: HeN Pri. | K15: SCC | L15: / | M15: /
A16: 276H018 | B16: 276H018 | C16: M | D16: 61-65 | E16: / | F16: / | G16: / | H16: / | I16: / | J16: HeN Pri. | K16: SCC | L16: / | M16: /
A17: 276H019 | B17: 276H019 | C17: F | D17: 71-75 | E17: 4 | F17: 0 | G17: 0 | H17: / | I17: / | J17: HeN Pri. | K17: SCC | L17: / | M17: /
A18: 276H020 | B18: 276H020 | C18: M | D18: 36-40 | E18: / | F18: / | G18: / | H18: / | I18: / | J18: HeN Pri. | K18: SCC | L18: / | M18: /
A19: 276H021 | B19: 276H021 | C19: M | D19: 51-55 | E19: 4 | F19: 2b | G19: x | H19: / | I19: / | J19: HeN Pri. and Nodal Met. | K19: SCC | L19: / | M19: /
A20: 276H022 | B20: 276H022 | C20: M | D20: 56-60 | E20: / | F20: / | G20: / | H20: / | I20: / | J20: HeN Pri. | K20: SCC | L20: / | M20: /
A21: 276H023 | B21: 276H023 | C21: M | D21: 61-65 | E21: 4 | F21: 2b | G21: 0 | H21: / | I21: / | J21: HeN Pri. and Nodal Met. | K21: SCC | L21: / | M21: /
A22: 276H024 | B22: 276H024 | C22: F | D22: 66-70 | E22: 4 | F22: 1 | G22: 0 | H22: / | I22: / | J22: HeN Pri. | K22: SCC | L22: / | M22: /
A23: 276H025 | B23: 276H025 | C23: M | D23: 61-65 | E23: 3 | F23: HD (nodular sclerosis) | G23: 0 | H23: / | I23: / | J23: HeN Pri. and Nodal Met. | K23: SCC | L23: / | M23: /
A24: 276H027 | B24: 276H027 | C24: M | D24: 76-80 | E24: 2 | F24: 2b | G24: 0 | H24: / | I24: / | J24: HeN Pri. | K24: SCC | L24: / | M24: /
A25: 276H028 | B25: 276H028 | C25: F | D25: 51-55 | E25: 4 | F25: 1a | G25: 0 | H25: / | I25: / | J25: HeN Pri. | K25: SCC | L25: / | M25: /
A26: 276H031 | B26: 276H031 | C26: M | D26: 46-50 | E26: 3 | F26: 2 | G26: 1 | H26: / | I26: / | J26: HeN Pri. and Nodal Met. | K26: SCC | L26: / | M26: /
A27: 276H032 | B27: 276H032 | C27: M | D27: 46-50 | E27: 4 | F27: 2 | G27: 0 | H27: / | I27: / | J27: HeN Pri. | K27: SCC | L27: / | M27: /
A28: 276H033 | B28: 276H033 | C28: M | D28: 66-70 | E28: 4 | F28: 2b | G28: 0 | H28: / | I28: / | J28: HeN Pri. and Nodal Met. | K28: SCC | L28: / | M28: /
A29: 276H034 | B29: 276H034 | C29: M | D29: 41-45 | E29: 2 | F29: 1 | G29: 0 | H29: / | I29: / | J29: HeN Pri. and Nodal Met. | K29: SCC | L29: / | M29: /
A30: 276H035 | B30: 276H035 | C30: F | D30: 66-70 | E30: 2 | F30: 0 | G30: 0 | H30: / | I30: / | J30: HeN Pri. | K30: SCC | L30: / | M30: /
A31: 276H036 | B31: 276H036 | C31: M | D31: 46-80 | E31: / | F31: / | G31: / | H31: / | I31: / | J31: HeN Pri. | K31: SCC | L31: / | M31: /
A32: 276H037 | B32: 276H037 | C32: M | D32: 51-55 | E32: 4 | F32: 2b | G32: 0 | H32: / | I32: / | J32: HeN Pri. and Nodal Met. | K32: SCC | L32: / | M32: /
A33: 276H038 | B33: 276H038 | C33: M | D33: 61-65 | E33: 4 | F33: 0 | G33: 0 | H33: / | I33: / | J33: HeN Pri. | K33: SCC | L33: / | M33: /
A34: 276H039 | B34: 276H039 | C34: M | D34: 66-70 | E34: / | F34: / | G34: / | H34: / | I34: / | J34: HeN Pri. | K34: SCC | L34: / | M34: /
A35: 276H040 | B35: 276H040 | C35: M | D35: 51-55 | E35: 3 | F35: 0 | G35: 0 | H35: / | I35: / | J35: HeN Pri. | K35: SCC | L35: / | M35: /
A36: 276H041 | B36: 276H041 | C36: M | D36: 56-60 | E36: 3 | F36: 2 | G36: 0 | H36: / | I36: / | J36: HeN Pri. and Nodal Met. | K36: SCC | L36: / | M36: /
A37: 276H042 | B37: 276H042 | C37: M | D37: 56-60 | E37: / | F37: / | G37: / | H37: / | I37: / | J37: HeN Pri. | K37: SCC | L37: / | M37: /
A38: 276H043 | B38: 276H043 | C38: / | D38: 56-60 | E38: 1 | F38: 0 | G38: 0 | H38: / | I38: / | J38: HeN Pri. | K38: SCC | L38: / | M38: /
A39: 276H044 | B39: 276H044 | C39: M | D39: 41-45 | E39: 2 | F39: 0 | G39: 0 | H39: / | I39: / | J39: HeN Pri. | K39: SCC | L39: / | M39: /
A40: 276H045 | B40: 276H045 | C40: / | D40: 61-65 | E40: / | F40: / | G40: / | H40: / | I40: / | J40: HeN Pri. | K40: SCC | L40: / | M40: /
...
