Workbook

Sheet Follow up (ship 1)
A2: Column1 | B2: Column2 | C2: Column3 | D2: Column4 | E2: Column5 | F2: Column6 | G2: Column7 | H2: Column8 | I2: Column9 | J2: Column10 | K2: Column11 | L2: Column12 | M2: Column13 | N2: Column14 | O2: Column15 | P2: Column16 | Q2: Column17 | R2: Column18 | S2: Column19 | T2: Column20 | U2: Column21 | V2: Column22 | W2: Column23 | X2: Column24 | Y2: Column25 | Z2: Column26 | AA2: Column27 | AB2: Column28 | AC2: Column29 | AD2: Column30 | AE2: Column31 | AF2: Column32 | AG2: Column33 | AH2: Column34 | AI2: Column35 | AJ2: Column36 | AK2: Column37 | AL2: Column38 | AM2: Column39 | AN2: Column40 | AO2: Column41 | AP2: Column42 | AQ2: Column43 | AR2: Column44 | AS2: Column45 | AT2: Column46 | AU2: Column47 | AV2: Column48 | AW2: Column49 | AX2: Column50 | AY2: Column51 | AZ2: Column52 | BA2: Column53 | BB2: Column54 | BC2: Column55 | BD2: Column56 | BE2: Column57 | BF2: Column58 | BG2: Column59 | BH2: Column60 | BI2: Column61 | BJ2: Column62 | BK2: Column63 | BL2: Column64 | BM2: Column65 | BN2: Column66 | BO2: Column67 | BP2: Column68 | BQ2: Column69 | BR2: Column70 | BS2: Column71 | BT2: Column72 | BU2: Column73 | BV2: Column74 | BW2: Column75 | BX2: Column76 | BY2: Column77 | BZ2: Column78 | CA2: Column79 | CB2: Column80 | CC2: Column81 | CD2: Column82 | CE2: Column83 | CF2: Column84 | CG2: Column85 | CH2: Column86 | CI2: Column87 | CJ2: Column88 | CK2: Column89 | CL2: Column90 | CM2: Column91 | CN2: Column92 | CO2: Column93 | CP2: Column94 | CQ2: Column95 | CR2: Column96 | CS2: Column97 | CT2: Column98 | CU2: Column99 | CV2: Column100 | CW2: Column101 | CX2: Column102 | CY2: Column103 | CZ2: Column104 | DA2: Column105 | DB2: Column106 | DC2: Column107 | DD2: Column108 | DE2: Column109 | DF2: Time to event (in months) | DG2: Column110 | DH2: Column111 | DI2: Column112 | DJ2: Column113 | DK2: Column114 | DL2: Column115 | DM2: Column116 | DN2: Column117 | DO2: Column118 | DP2: Column119 | DQ2: Column120 | DR2: Column121 | DS2: Column122 | DT2: Column123 | DU2: Column124 | DV2: Column125 | DW2: Column126 | DX2: Column127 | DY2: Column128 | DZ2: Column129 | EA2: Column130 | EB2: Column131 | EC2: Column132 | ED2: Column133 | EE2: Column134 | EF2: Column135 | EG2: Column136 | EH2: Column137 | EI2: Column138 | EJ2: Column139 | EK2: Column140 | EL2: Column141 | EM2: Column142 | EN2: Column143 | EO2: Column144 | EP2: Column145 | EQ2: Column146 | ER2: Column147 | ES2: Column148 | ET2: Column149 | EU2: Column150 | EV2: Column151 | EW2: Column152 | EX2: Column153 | EY2: Column154 | EZ2: Column155 | FA2: Column156 | FB2: Column157 | FC2: Column158 | FD2: Column159 | FE2: Column160
AB3: Neoadjuvant treatment | BB3: Adjuvant treatment | BU3: Relapse/progression | CM3: Metstatic treatment | DF3: Neoadjuvant treatment | DR3: Specimen collection | DV3: Adjuvant treatment | EF3: Relapse/progression | EM3: Metstatic treatment | EU3: OS/PFS
A4: NHS | B4: Any Immunotherapy | C4: Specimen is a recurrence (Y/N) | D4: Selected specimen Anonymised ID | E4: Specimen Block number | F4: Specimen Surgery Date (DD/MM/YYYY) | G4: Anonymized ID Normal tissue | H4: Matched Normal tissue Block Number | I4: Matched Normal tissue Site | J4: Matched Normal tissue Surgery Date (DD/MM/YY) | K4: Specimen surgery | L4: Specimen tumour site | M4: Primary tumour site | N4: Gender | O4: DOB (DD/MM/YYYY) | P4: Date of DX (DD/MM/YYYY) | Q4: Age at Diagnosis (years) | R4: Specimen Histological Diagnosis | S4: Resection margins clear (Y/N) | T4: pT | U4: pN | V4: pM | W4: cM | X4: FIGO Grade | Y4: Grade | Z4: TNM stage | AA4: Stage at DX (AJCC) | AB4: Neoadjuvant therapy (Y/N) | AC4: Response to neoadjuvant therapy (TRS score) | AD4: Neoadjuvant radioTx | AE4: Start Date | AF4: End Date | AG4: Tumour response | AH4: Neoadjuvant chemo Tx1 | AI4: Start Date | AJ4: End Date | AK4: Tumour response | AL4: Neoadjuvant chemo Tx2 | AM4: Start Date | AN4: End Date | AO4: Tumour response | AP4: Neoadjuvant chemoTx 3 | AQ4: Start Date | AR4: End Date | AS4: Tumour response | AT4: Neoadjuvant Immunotherapy Tx 1 | AU4: Start Date | AV4: End Date | AW4: Tumour response | AX4: Neoadjuvant Immunotherapy Tx 2 | AY4: Start Date | AZ4: End Date | BA4: Tumour response | BB4: Adjuvant radio Tx 1 | BC4: Start Date | BD4: End Date | BE4: Adjuvant ChemoTx 1 | BF4: Start Date | BG4: End Date | BH4: Tumour response | BI4: Adjuvant ChemoTx 2 | BJ4: Start Date | BK4: End Date | BL4: Tumour response | BM4: Adjuvant ChemoTx 3 | BN4: Start Date | BO4: End Date | BP4: Tumour response | BQ4: Adjuvant Imunnotherapy Tx1 | BR4: Start Date | BS4: End Date | BT4: Tumour response | BU4: Date relapse/ progression 1 | BV4: Sites relapse/ progression 1 | BW4: Date relapse/ progression 2 | BX4: Sites relapse/ progression 2 | BY4: Date relapse/ progression 3 | BZ4: Sites relapse/ progression 3 | CA4: Date relapse/ progression 4 | CB4: Sites relapse/ progression 4 | CC4: Date relapse/ progression 5 | CD4: Sites relapse/ progression 5 | CE4: Date relapse/ progression 6 | CF4: Sites relapse/ progression 6 | CG4: Date relapse/ progression 7 | CH4: Sites relapse/ progression 7 | CI4: Date relapse/ progression 8 | CJ4: Sites relapse/ progression 8 | CK4: Date relapse/ progression 9 | CL4: Sites relapse/ progression 9 | CM4: Metastatic/ recurrent Tx 1 | CN4: Start Date | CO4: Finish Date | CP4: Tumour response | CQ4: Metastatic/ recurrent Tx 2 | CR4: Start Date | CS4: Finish Date | CT4: Tumour response | CU4: Metastatic/ recurrent Tx 3 | CV4: Start Date | CW4: Finish Date | CX4: Tumour response | CY4: Current Status | CZ4: Death date | DA4: Death due to tumour/ assumed tumour related? (Y/N) | DB4: Cause of death | DC4: Date last follow-up | DD4: Date Last Seen | DE4: Concurrent Medical Conditions | DF4: Rx1 start | DG4: Rx1 end | DH4: Chemo Tx1 start | DI4: Chemo Tx1 end | DJ4: Chemo Tx2 start | DK4: Chemo Tx2 end | DL4: Chemo Tx3 start | DM4: Chemo Tx3 end | DN4: Immunotherapy Tx1 start | DO4: Immunotherapy Tx1 end | DP4: Immunotherapy Tx2 start | DQ4: Immunotherapy Tx2 end | DR4: Specimen surgery | DS4: Matched met 1 surgery | DT4: Matched met 2 surgery | DU4: Normal tissue surgery | DV4: Adjuvant Rx1 start | DW4: Adjuvant Rx1 end | DX4: Adjuvant Chemo Tx1 start | DY4: Adjuvant Chemo Tx1 end | DZ4: Adjuvant Chemo Tx2 start | EA4: Adjuvant Chemo Tx2 end | EB4: Adjuvant Chemo Tx3 start | EC4: Adjuvant Chemo Tx3 end | ED4: Immunotherapy Tx1 start | EE4: Immunotherapy Tx1 end | EF4: Relapse/ progression 1 | EG4: Relapse/ progression 2 | EH4: Relapse/ progression 3 | EI4: Relapse/ progression 4 | EJ4: Relapse/ progression 5 | EK4: Relapse/ progression 6 | EL4: Relapse/ progression 7 | EM4: Relapse/ progression 8 | EN4: Relapse/ progression 9 | EO4: Metastatic Tx1 start | EP4: Metastatic Tx1 end | EQ4: Metastatic Tx2 start | ER4: Metastatic Tx2 end | ES4: Metastatic Tx3 start | ET4: Metastatic Tx3 end | EU4: Recurrence (PFS) | EV4: Death (OS and PFS) | EW4: Date last follow-up (PFS) | EX4: Date last seen (OS) | EY4: Overall survival (OS) in months | EZ4: Progression free survival (PFS) in months | FA4: Event (recurrence/progression) | FB4: Event (cancer death) | FC4: Event (death; all causes) | FD4: Event (recurrence or cancer death) | FE4: Comments from clinical team
A5: 4520256615 | C5: N | D5: LH17-02702 | E5: A1, A12 | F5: 42753 | G5: N/A | H5: N/A | I5: N/A | J5: N/A | K5: Total abdominal hysterectomy | L5: Endometrium | M5: N/A | N5: F | O5: 18552 | P5: 42703 | Q5: =DATEDIF(O5, P5,"Y") -> 66 | R5: Carcinosarcoma with heterologous differentiation | S5: Y | T5: 2 | U5: 1 | V5: 0 | W5: 0 | X5: IIIC1 | Y5: NR | Z5: T2N1M0 | AA5: IIIC1 | DE5: Asthma, cervical spondylosis, high cholesterol, hypertension, hypothyroidism, ulcerative colitis, gout. | DF5: =IFERROR((YEARFRAC(P5,AE5)*12),"N/A") -> 1402.9667 | DG5: =IFERROR((YEARFRAC(P5,AF5)*12),"N/A") -> 1402.9667 | DH5: =IFERROR((YEARFRAC(P5,AI5)*12),"N/A") -> 1402.9667 | DI5: =IFERROR((YEARFRAC(P5,AJ5)*12),"N/A") -> 1402.9667 | DJ5: =IFERROR((YEARFRAC(P5,AM5)*12),"N/A") -> 1402.9667 | DK5: =IFERROR((YEARFRAC(P5,AN5)*12),"N/A") -> 1402.9667 | DL5: =IFERROR((YEARFRAC(P5,AQ5)*12),"N/A") -> 1402.9667 | DM5: =IFERROR((YEARFRAC(P5,AR5)*12),"N/A") -> 1402.9667 | DN5: =IFERROR((YEARFRAC(P5,AU5)*12),"N/A") -> 1402.9667 | DO5: =IFERROR((YEARFRAC(P5,AV5)*12),"N/A") -> 1402.9667 | DP5: =IFERROR((YEARFRAC(P5,AY5)*12),"N/A") -> 1402.9667 | DQ5: =IFERROR((YEARFRAC(P5,AZ5)*12),"N/A") -> 1402.9667 | DR5: =IFERROR((YEARFRAC(P5,F5)*12),"N/A") -> 1.6333333 | DS5: =IFERROR((YEARFRAC(P5,#REF!)*12),"N/A") -> N/A | DT5: =IFERROR((YEARFRAC(P5,#REF!)*12),"N/A") -> N/A | DU5: =IFERROR((YEARFRAC(P5,#REF!)*12),"N/A") -> N/A | DV5: =IFERROR((YEARFRAC(P5,BC5)*12),"N/A") -> 1402.9667 | DW5: =IFERROR((YEARFRAC(P5,BD5)*12),"N/A") -> 1402.9667 | DX5: =IFERROR((YEARFRAC(P5,BF5)*12),"N/A") -> 1402.9667 | DY5: =IFERROR((YEARFRAC(P5,BG5)*12),"N/A") -> 1402.9667 | DZ5: =IFERROR((YEARFRAC(P5,BJ5)*12),"N/A") -> 1402.9667 | EA5: =IFERROR((YEARFRAC(P5,BK5)*12),"N/A") -> 1402.9667 | EB5: =IFERROR((YEARFRAC(P5,BN5)*12),"N/A") -> 1402.9667 | EC5: =IFERROR((YEARFRAC(P5,BO5)*12),"N/A") -> 1402.9667 | ED5: =IFERROR((YEARFRAC(P5,BR5)*12),"N/A") -> 1402.9667 | EE5: =IFERROR((YEARFRAC(P5,BS5)*12),"N/A") -> 1402.9667 | EF5: =IFERROR((YEARFRAC(P5,BU5)*12),"N/A") -> 1402.9667 | EG5: =IFERROR((YEARFRAC(P5,BW5)*12),"N/A") -> 1402.9667 | EH5: =IFERROR((YEARFRAC(P5,BY5)*12),"N/A") -> 1402.9667 | EI5: =IFERROR((YEARFRAC(P5,CA5)*12),"N/A") -> 1402.9667 | EJ5: =IFERROR((YEARFRAC(P5,CC5)*12),"N/A") -> 1402.9667 | EK5: =IFERROR((YEARFRAC(P5,CE5)*12),"N/A") -> 1402.9667 | EL5: =IFERROR((YEARFRAC(P5,CG5)*12),"N/A") -> 1402.9667 | EM5: =IFERROR((YEARFRAC(P5,CI5)*12),"N/A") -> 1402.9667 | EN5: =IFERROR((YEARFRAC(P5,CK5)*12),"N/A") -> 1402.9667 | EO5: =IFERROR((YEARFRAC(P5,CN5)*12),"N/A") -> 1402.9667 | EP5: =IFERROR((YEARFRAC(P5,CO5)*12),"N/A") -> 1402.9667 | EQ5: =IFERROR((YEARFRAC(P5,CR5)*12),"N/A") -> 1402.9667 | ER5: =IFERROR((YEARFRAC(P5,CS5)*12),"N/A") -> 1402.9667 | ES5: =IFERROR((YEARFRAC(P5,CV5)*12),"N/A") -> 1402.9667 | ET5: =IFERROR((YEARFRAC(P5,CW5)*12),"N/A") -> 1402.9667 | EU5: =EF5 -> 1402.9667 | EV5: =IFERROR((YEARFRAC(P5,CZ5)*12),"N/A") -> 1402.9667 | EW5: =IFERROR((YEARFRAC(P5,DC5)*12),"N/A") -> 1402.9667 | EX5: =IFERROR((YEARFRAC(P5,DD5)*12),"N/A") -> 1402.9667 | EY5: =SUM(EV5,EX5) -> 2805.9333 | EZ5: {=INDEX(EU5:EX5,MATCH(TRUE,INDEX(ISNUMBER(EU5:EX5),0),0))} -> 1402.9667 | FA5: =IF(EU5="N/A",0,1) -> 1 | FB5: =IF(DA5="Y",1,0) -> 0 | FC5: =IF(EV5="N/A",0,1) -> 1 | FD5: =IF(OR(FA5=1,FB5=1),"1","0") -> 1
A6: 4250445798 | C6: N | D6: LH17-06069 | E6: A11, A12 | F6: 42774 | G6: LH17-06069 | H6: B3 | I6: Lymph node | J6: 42774 | K6: Total abdominal hysterectomy | L6: Endometrium | M6: N/A | N6: F | O6: 16856 | P6: 42740 | Q6: =DATEDIF(O6, P6,"Y") -> 70 | R6: Endometrioid adenocarcinoma | S6: Y | T6: 1b | U6: 0 | V6: x | W6: 0 | X6: IB | Y6: 1 | Z6: T1BN0M0 | AA6: IB
A7: 4946723307 | C7: N | D7: LH17-07381 | E7: A9, A8 | F7: 42783 | G7: LH17-07381 | H7: C1 | I7: Lymph node | J7: 42783 | K7: Total abdominal hysterectomy | L7: Endometrium | M7: N/A | N7: F | O7: 15135 | P7: 42751 | Q7: =DATEDIF(O7, P7,"Y") -> 75 | R7: Deeply invasive mixed adenocarcinoma (serous and endometroiod) | S7: Y | T7: 1b | U7: 0 | V7: 0 | W7: 0 | X7: IB | Y7: 3 | Z7: T1BN0M0 | AA7: IB
A8: 4362503161 | C8: N | D8: LH17-10008 | E8: A4, A6 | F8: 42801 | G8: N/A | H8: N/A | I8: N/A | J8: N/A | K8: Total abdominal hysterectomy | L8: Endometrium | M8: N/A | N8: F | O8: 9597 | P8: 42727 | Q8: =DATEDIF(O8, P8,"Y") -> 90 | R8: High grade serous adenocarcinoma | S8: Y | T8: 2 | U8: 0 | V8: 0 | W8: 0 | X8: II | Y8: 3 | Z8: T2N0M0 | AA8: II
A9: 4363753323 | C9: N | D9: LH17-10854 | E9: A6, A10 | F9: 42807 | G9: N/A | H9: N/A | I9: N/A | J9: N/A | K9: Total abdominal hysterectomy | L9: Endometrium | M9: N/A | N9: F | O9: 12131 | P9: 37568 | Q9: =DATEDIF(O9, P9,"Y") -> 69 | R9: Malignant mixed mullerian tumour with rhabdomyoblastic differentiation | S9: Y | T9: 3b | U9: 1 | V9: 0 | W9: 0 | X9: IIIC1 | Y9: 3 | Z9: T3BN1M0 | AA9: IIIC1 | DE9: Previous rectal cancer
A10: 4662799619 | B10: N/A | C10: N/A | D10: N/A | E10: N/A | F10: N/A | G10: LH17-11002 | H10: B5 | I10: Pelvic node | J10: 42808 | K10: N/A | L10: N/A | M10: N/A | N10: F | O10: 12867 | P10: 42808 | Q10: =DATEDIF(O10, P10,"Y") -> 81 | R10: N/A | S10: N/A | T10: N/A | U10: N/A | V10: N/A | W10: N/A | X10: N/A | Y10: N/A | Z10: N/A | AA10: N/A | AB10: N/A | AC10: N/A | AD10: N/A | AE10: N/A | AF10: N/A | AG10: N/A | AH10: N/A | AI10: N/A | AJ10: N/A | AK10: N/A | AL10: N/A | AM10: N/A | AN10: N/A | AO10: N/A | AP10: N/A | AQ10: N/A | AR10: N/A | AS10: N/A | AT10: N/A | AU10: N/A | AV10: N/A | AW10: N/A | AX10: N/A | AY10: N/A | AZ10: N/A | BA10: N/A | BB10: N/A | BC10: N/A | BD10: N/A | BE10: N/A | BF10: N/A | BG10: N/A | BH10: N/A | BI10: N/A | BJ10: N/A | BK10: N/A | BL10: N/A | BM10: N/A | BN10: N/A | BO10: N/A | BP10: N/A | BQ10: N/A | BR10: N/A | BS10: N/A | BT10: N/A | BU10: N/A | BV10: N/A | BW10: N/A | BX10: N/A | BY10: N/A | BZ10: N/A | CA10: N/A | CB10: N/A | CC10: N/A | CD10: N/A | CE10: N/A | CF10: N/A | CG10: N/A | CH10: N/A | CI10: N/A | CJ10: N/A | CK10: N/A | CL10: N/A | CM10: N/A | CN10: N/A | CO10: N/A | CP10: N/A | CQ10: N/A | CR10: N/A | CS10: N/A | CT10: N/A | CU10: N/A | CV10: N/A | CW10: N/A | CX10: N/A | CY10: N/A | CZ10: N/A | DA10: N/A | DB10: N/A | DC10: N/A | DD10: N/A | DE10: N/A
A11: 4367569659 | C11: N | D11: LH17-11093 | E11: A6,A8 | F11: 42808 | G11: LH17-11093 | H11: D1 | I11: Lymph node | J11: 42808 | K11: Total laparoscopic Hysterectomy | L11: Endometrium | M11: N/A | N11: F | O11: 12927 | P11: 42783 | Q11: =DATEDIF(O11, P11,"Y") -> 81 | R11: Endometrioid adenocarcinoma | S11: Y | T11: 1b | U11: 0 | V11: 0 | W11: 0 | X11: IB | Y11: 3 | Z11: T1BN0M0 | AA11: IB
A12: 4581564212 | C12: N | D12: LH17-11306 | E12: A8, A3 | F12: 42809 | G12: N/A | H12: N/A | I12: N/A | J12: N/A | K12: Total abdominal hysterectomy | L12: Endometrium | M12: N/A | N12: F | O12: 19418 | P12: 42739 | Q12: =DATEDIF(O12, P12,"Y") -> 63 | R12: High grade carcinosarcoma of homologous type | S12: Y | T12: 2 | U12: 0 | V12: 0 | W12: 0 | X12: II | Y12: 3 | Z12: T2N0M0 | AA12: II
A13: 4706490731 | C13: N | D13: LH17-12612 | E13: A10, A4 | F13: 42817 | G13: LH17-12612 | H13: C1 | I13: Pelvic node | J13: 42817 | K13: Total abdominal hysterectomy | L13: Endometrium | M13: N/A | N13: F | O13: 17832 | P13: 42748 | Q13: =DATEDIF(O13, P13,"Y") -> 68 | R13: Endometrioid adenocarcinoma | S13: Y | T13: 2 | U13: 0 | V13: 0 | W13: 0 | X13: II | Y13: 1 | Z13: T2N0M0 | AA13: II | DE13: Previous RCC and lung cancer
A14: 4366490994 | C14: N | D14: LH17-13646 | E14: A20, A21 | F14: 42824 | G14: N/A | H14: N/A | I14: N/A | J14: N/A | K14: Total abdominal hysterectomy | L14: Endometrium | M14: N/A | N14: F | O14: 11938 | P14: 42779 | Q14: =DATEDIF(O14, P14,"Y") -> 84 | R14: High-grade serous adenocarcinoma of the endometrium | S14: N/A | T14: N/R | U14: N/R | V14: 1 (Omentum) | W14: 1 (Lung and lymph node) | X14: IVB | Y14: 3 | Z14: N/A | AA14: IVB | DE14: Previous breast cancer.
A15: 4508221386 | C15: N | D15: LH17-15131 | E15: A15, A12 | F15: 42835 | G15: LH17-15131 | H15: G2 | I15: Lymph node | J15: 42835 | K15: Total abdominal hysterectomy | L15: Endometrium | M15: N/A | N15: F | O15: 17315 | P15: 42830 | Q15: =DATEDIF(O15, P15,"Y") -> 69 | R15: Mixed high grade endometrioid and serous adenocarcinoma | S15: Y | T15: 1b | U15: 0 | V15: 0 | W15: 0 | X15: IB | Y15: 3 | Z15: T1BN0M0 | AA15: IB
A16: 4905526434 | C16: N | D16: LH17-16034 | E16: A9, A15 | F16: 42843 | G16: N/A | H16: N/A | I16: N/A | J16: N/A | K16: Total abdominal hysterectomy | L16: Endometrium | M16: N/A | N16: F | O16: 17188 | P16: 42818 | Q16: =DATEDIF(O16, P16,"Y") -> 70 | R16: Papillary serous carcinoma | S16: Y | T16: 1b | U16: 0 | V16: 0 | W16: 0 | X16: IB | Y16: 3 | Z16: T1BN0M0 | AA16: IB
A17: 4663105459 | C17: N | D17: LH17-16275 | E17: A6, A15 | F17: 42844 | G17: N/A | H17: N/A | I17: N/A | J17: N/A | K17: Total abdominal hysterectomy | L17: Endometrium | M17: N/A | N17: F | O17: 14460 | P17: 42796 | Q17: =DATEDIF(O17, P17,"Y") -> 77 | R17: Adenocarcinoma. Mixed clear cell/endometriod | S17: Y | T17: 1a | U17: 0 | V17: 0 | W17: 0 | X17: IA | Y17: N/R | Z17: T1AN0M0 | AA17: IA
A18: 4389042653 | C18: N | D18: LH17-20256 | E18: 8, 10 | F18: 42870 | G18: N/A | H18: N/A | I18: N/A | J18: N/A | K18: Total laparoscopic hysterectomy | L18: Endometrium | M18: N/A | N18: F | O18: 13661 | P18: 42852 | Q18: =DATEDIF(O18, P18,"Y") -> 79 | R18: Endometrioid adenocarcinoma | S18: Y | T18: 1b | U18: 0 | V18: 0 | W18: 0 | X18: IB | Y18: 1 | Z18: T1BN0M0 | AA18: IB
A19: 6100474530 | C19: N | D19: LH17-22802 | E19: 3,5 | F19: 42886 | G19: N/A | H19: N/A | I19: N/A | J19: N/A | K19: Total laparoscopic hysterectomy | L19: Endometrium | M19: N/A | N19: F | O19: 13548 | P19: 42808 | Q19: =DATEDIF(O19, P19,"Y") -> 80 | R19: Endometrioid adenocarcinoma | S19: Y | T19: 1b | U19: 0 | V19: 0 | W19: 0 | X19: IB | Y19: 1 | Z19: T1BN0M0 | AA19: IB
A20: 4426025737 | C20: N | D20: LH17-25751 | E20: A16, A33 | F20: 42905 | G20: LH17-25751 | H20: C3 | I20: Pelvic node | J20: 42905 | K20: Total abdominal hysterectomy | L20: Endometrium | M20: N/A | N20: F | O20: 16269 | P20: 42843 | Q20: =DATEDIF(O20, P20,"Y") -> 72 | R20: Endometrioid adenocarcinoma | S20: Y | T20: 1a | U20: 0 | V20: 0 | W20: 0 | X20: IA | Y20: 2 | Z20: T1AN0M0 | AA20: IA
A21: 6189690610 | C21: N | D21: LH17-28006 | E21: A11, A13 | F21: 42919 | G21: N/A | H21: N/A | I21: N/A | J21: N/A | K21: Total laparoscopic hysterectomy/Bilateral salpingo-oophorectomy | L21: Endometrium | M21: N/A | N21: F | O21: 10969 | P21: 42879 | Q21: =DATEDIF(O21, P21,"Y") -> 87 | R21: Serous adenocarcinoma | S21: Y | T21: 1b | U21: 0 | V21: 0 | W21: 0 | X21: IB | Y21: 3 | Z21: T1BN0M0 | AA21: IB
A22: 4740277069 | C22: N | D22: LH17-28649 | E22: A6, A11 | F22: 42922 | G22: N/A | H22: N/A | I22: N/A | J22: N/A | K22: Total laparoscopic hysterectomy/Bilateral salpingo-oophorectomy | L22: Endometrium | M22: N/A | N22: F | O22: 16888 | P22: 42880 | Q22: =DATEDIF(O22, P22,"Y") -> 71 | R22: Endometrioid adenocarcinoma | S22: N/R | T22: 1b | U22: 0 | V22: 0 | W22: 0 | X22: IB | Y22: 1 | Z22: T1BN0M0 | AA22: IB
A23: 4100098251 | C23: N | D23: LH17-29718 | E23: 15, 6 | F23: 42929 | G23: N/A | H23: N/A | I23: N/A | J23: N/A | K23: Total laparoscopic hysterectomy/Bilateral salpingo-oophorectomy | L23: Endometrium | M23: N/A | N23: F | O23: 15527 | P23: 42786 | Q23: =DATEDIF(O23, P23,"Y") -> 74 | R23: Endometrioid adenocarcinoma | S23: N/R | T23: 1a | U23: 0 | V23: 0 | W23: 0 | X23: IA | Y23: 1 | Z23: T1AN0M0 | AA23: IA
A24: 4860460391 | C24: N | D24: LH17-30635 | E24: A13, A14 | F24: 42935 | G24: LH17-30635 | H24: D3 | I24: Pelvic node | J24: 42935 | K24: Total laparoscopic hysterectomy | L24: Endometrium | M24: N/A | N24: F | O24: 21181 | P24: 42921 | Q24: =DATEDIF(O24, P24,"Y") -> 59 | R24: Endometrioid adenocarcinoma | S24: Y | T24: 1b | U24: 0 | V24: 0 | W24: 0 | X24: IB | Y24: 3 | Z24: T1BN0M0 | AA24: IB
A25: 4424137554 | C25: N/A | D25: N/A | E25: N/A | F25: N/A | G25: LH17-30829 | H25: D4 | I25: Pelvic node | J25: 42936 | K25: N/A | L25: N/A | M25: N/A | N25: F | O25: 15088 | P25: 42936 | Q25: =DATEDIF(O25, P25,"Y") -> 76 | R25: N/A | S25: N/A | T25: N/A | U25: N/A | V25: N/A | W25: N/A | X25: N/A | Y25: N/A | Z25: N/A | AA25: N/A
A26: 4308926637 | C26: N | D26: LH17-30839 | E26: A15 | F26: 42936 | G26: N/A | H26: N/A | I26: N/A | J26: N/A | K26: Total abdominal hysterectomy with bilateral salpingo-oophorectomy. | L26: Endometrium | M26: N/A | N26: F | O26: 14734 | P26: 42895 | Q26: =DATEDIF(O26, P26,"Y") -> 77 | R26: Endometrioid carcinoma | S26: Y | T26: 1a | U26: 0 | V26: 0 | W26: 0 | X26: IA | Y26: 1 | Z26: T1AN0M0 | AA26: IA
A27: 4861789125 | C27: N | D27: LH17-30974 | E27: A12, A22 | F27: 42937 | G27: N/A | H27: N/A | I27: N/A | J27: N/A | K27: Total abdominal hysterectomy | L27: Endometrium | M27: N/A | N27: F | O27: 22500 | P27: 41233 | Q27: =DATEDIF(O27, P27,"Y") -> 51 | R27: Endometrioid adenocarcinoma | S27: Y | T27: 1a | U27: 0 | V27: 0 | W27: 0 | X27: IA | Y27: 1 | Z27: T1AN0M0 | AA27: IA
A28: 4520776414 | C28: N | D28: LH17-32555 | E28: A6 | F28: 42948 | G28: N/A | H28: N/A | I28: N/A | J28: N/A | K28: Total laparoscopic hysterectomy | L28: Endometrium | M28: N/A | N28: F | O28: 19253 | P28: 42891 | Q28: =DATEDIF(O28, P28,"Y") -> 64 | R28: Endometrioid adenocarcinoma | S28: Y | T28: 1b | U28: 0 | V28: 0 | W28: 0 | X28: IB | Y28: 1 | Z28: T1BN0M0 | AA28: IB
A29: 4582803245 | C29: N | D29: LH17-32987 | E29: 6,7 | F29: 42950 | G29: N/A | H29: N/A | I29: N/A | J29: N/A | K29: Total laparoscopic hysterectomy/Bilateral salpingo-oophorectomy | L29: Endometrium | M29: N/A | N29: F | O29: 20209 | P29: 42909 | Q29: =DATEDIF(O29, P29,"Y") -> 62 | R29: Endometrioid carcinoma | S29: N/R | T29: 2 | U29: 0 | V29: 0 | W29: 0 | X29: II | Y29: 2 | Z29: T2N0M0 | AA29: II
A30: 4948238384 | C30: N | D30: LH17-33790 | E30: A11, A12 | F30: 42956 | G30: LH17-33790 | H30: C3 | I30: Pelvic node | J30: 42956 | K30: Total abdominal hysterectomy | L30: Endometrium | M30: N/A | N30: F | O30: 12619 | P30: 42909 | Q30: =DATEDIF(O30, P30,"Y") -> 82 | R30: Endometrioid adenocarcinoma | S30: Y | T30: 3a | U30: 0 | V30: 0 | W30: 0 | X30: IIIA | Y30: 3 | Z30: T3AN0M0 | AA30: IIIA
A31: 4583815352 | C31: N | D31: LH17-34068 | E31: 4 | F31: 42957 | G31: N/A | H31: N/A | I31: N/A | J31: N/A | K31: Total laparoscopic hysterectomy | L31: Endometrium | M31: N/A | N31: F | O31: 20935 | P31: 42932 | Q31: =DATEDIF(O31, P31,"Y") -> 60 | R31: Endometrioid adenocarcinoma | S31: N/R | T31: 1a | U31: 0 | V31: 0 | W31: 0 | X31: IA | Y31: 1 | Z31: T1AN0M0 | AA31: IA
A32: 4109016088 | C32: N | D32: LH17-34353 | E32: A7, A6 | F32: 42961 | G32: N/A | H32: N/A | I32: N/A | J32: N/A | K32: Total abdominal hysterectomy | L32: Endometrium | M32: N/A | N32: F | O32: 16954 | P32: 42909 | Q32: =DATEDIF(O32, P32,"Y") -> 71 | R32: Carcinosarcoma with heterologous elements | S32: Y | T32: 3 | U32: 2 | V32: 0 | W32: 0 | X32: IIIC2 | Y32: N/R | Z32: T3CN2M0 | AA32: IIIC2
A33: 4343616568 | C33: N | D33: LH17-35617 | E33: A2 | F33: 42968 | G33: N/A | H33: N/A | I33: N/A | J33: N/A | K33: Total laparoscopic hysterectomy | L33: Endometrium | M33: N/A | N33: F | O33: 12808 | P33: 42916 | Q33: =DATEDIF(O33, P33,"Y") -> 82 | R33: Endometrioid carcinoma | S33: Y | T33: 1a | U33: 0 | V33: 0 | W33: 0 | X33: IA | Y33: 1 | Z33: T1AN0M0 | AA33: IA
A34: 4483680641 | C34: N | D34: LH17-35965 | E34: A9, A10 | F34: 42970 | G34: LH17-35965 | H34: B4 | I34: Lymph node | J34: 42970 | K34: Total laparoscopic hysterectomy,bso,omental biopsy, pelvic and pa lymph node sampling | L34: Endometrium | M34: N/A | N34: F | O34: 20760 | P34: 42927 | Q34: =DATEDIF(O34, P34,"Y") -> 60 | R34: Clear cell carcinoma of endometrium | S34: Y | T34: 2 | U34: 0 | V34: 0 | W34: 0 | X34: II | Y34: 3 | Z34: T2N0M0 | AA34: II
A35: 4347092857 | C35: N | D35: LH17-36526 | E35: A7, A6 | F35: 42976 | G35: N/A | H35: N/A | I35: N/A | J35: N/A | K35: Total laparoscopic hysterectomy | L35: Endometrium | M35: N/A | N35: F | O35: 12091 | P35: 42920 | Q35: =DATEDIF(O35, P35,"Y") -> 84 | R35: Endometrioid carcinoma | S35: Y | T35: 3 | U35: 1 | V35: 0 | W35: 0 | X35: IIIC1 | Y35: 2 | Z35: T3CN1M0 | AA35: IIIC1
A36: 4583119461 | C36: N | D36: LH17-36679 | E36: A9, A8 | F36: 42976 | G36: N/A | H36: N/A | I36: N/A | J36: N/A | K36: Total abdominal hysterectomy | L36: Endometrium | M36: N/A | N36: F | O36: 20795 | P36: 42909 | Q36: =DATEDIF(O36, P36,"Y") -> 60 | R36: Endometrioid carcinoma | S36: Y | T36: 3 | U36: 2 | V36: 0 | W36: 0 | X36: IIIC2 | Y36: 2 | Z36: T3CN2M0 | AA36: IIIC2
A37: 4425422260 | C37: N | D37: LH17-37241 | E37: A5, A6 | F37: 42979 | G37: N/A | H37: N/A | I37: N/A | J37: N/A | K37: Total abdominal hysterectomy | L37: Endometrium | M37: N/A | N37: F | O37: 15300 | P37: 42926 | Q37: =DATEDIF(O37, P37,"Y") -> 75 | R37: Carcinosarcoma with heterologous elements | S37: Y | T37: 1b | U37: 0 | V37: 0 | W37: 0 | X37: IB | Y37: 3 | Z37: T1BN0M0 | AA37: IB
A38: 4382637317 | C38: N | D38: LH17-37984 | E38: A4, A5 | F38: 42984 | G38: N/A | H38: N/A | I38: N/A | J38: N/A | K38: Total abdominal hysterectomy | L38: Endometrium | M38: N/A | N38: F | O38: 19707 | P38: 42936 | Q38: =DATEDIF(O38, P38,"Y") -> 63 | R38: Endometrioid adenocarcinoma with foci of clear cell differentiation | S38: Y | T38: 1b | U38: 0 | V38: 0 | W38: 0 | X38: IB | Y38: 2 | Z38: T1BN0M0 | AA38: IB
A39: 6263484020 | C39: N | D39: LH17-38467 | E39: A7, A6 | F39: 42989 | G39: N/A | H39: N/A | I39: N/A | J39: N/A | K39: Total abdominal hysterectomy | L39: Endometrium | M39: N/A | N39: F | O39: 19352 | P39: 42990 | Q39: =DATEDIF(O39, P39,"Y") -> 64 | R39: Endometrioid carcinoma | S39: Y | T39: 3 | U39: 1 | V39: 0 | W39: 0 | X39: IIIC1 | Y39: 2 | Z39: T3CN1M0 | AA39: IIIC1
A40: 4508116930 | C40: N | D40: LH17-40476 | E40: A6, A7 | F40: 43000 | G40: LH17-40476 | H40: D9 | I40: Pelvic node | J40: 43000 | K40: Laparotomy/Total abdominal hysterectomy/Bilateral salpingo-oophorectomy/Pelvic and para-aortic lymphadenectomy/Omentectomy | L40: Endometrium | M40: N/A | N40: F | O40: 17624 | P40: 42949 | Q40: =DATEDIF(O40, P40,"Y") -> 69 | R40: High-grade serous carcinoma | S40: Y | T40: 1b | U40: 0 | V40: 0 | W40: 0 | X40: IB | Y40: 3 | Z40: T1BN0M0 | AA40: IB
A41: 6164754372 | C41: N | D41: LH17-41239 | E41: A13, A22 | F41: 43005 | G41: N/A | H41: N/A | I41: N/A | J41: N/A | K41: Laparotomy, total abdominal hysterectomy, bilateral salpingo-oophorectomy, infracolic omentectomy, pelvic and PA node dissection | L41: Endometrium | M41: N/A | N41: F | O41: 15130 | P41: 43026 | Q41: =DATEDIF(O41, P41,"Y") -> 76 | R41: Carcinosarcoma showing rhabdomyoblastic differentiation | S41: Y | T41: 3 | U41: 2 | V41: 0 | W41: 0 | X41: IIIC2 | Y41: 3 | Z41: T3CN2M0 | AA41: IIIC2
...

Sheet Prelim (ship 1)
A1: Specimen is a recurrence (Y/N) | B1: Selected specimen Anonymised ID | C1: Specimen Block number | D1: Specimen Surgery Date (DD/MM/YYYY) | E1: Anonymized ID Normal tissue | F1: Matched Normal tissue Block Number | G1: Matched Normal tissue Site | H1: Matched Normal tissue Surgery Date (DD/MM/YY) | I1: Specimen surgery | J1: Specimen tumour site | K1: Primary tumour site | L1: Gender | M1: Date of DX (DD/MM/YYYY) | N1: Age at Diagnosis (years) | O1: Specimen Histological Diagnosis | P1: Resection margins clear (Y/N) | Q1: pT | R1: pN | S1: pM | T1: cM | U1: FIGO Grade | V1: Grade | W1: TNM stage | X1: Stage at DX (AJCC)
A2: N | B2: LH17-2702 | C2: A1, A12 | D2: =IFERROR("Q" &INT((MONTH('Follow up (ship 1)'!F5)+2)/3) & "-" & YEAR('Follow up (ship 1)'!F5),"N/A") -> Q1-2017 | E2: N/A | F2: N/A | G2: N/A | H2: =IFERROR("Q" &INT((MONTH('Follow up (ship 1)'!J5)+2)/3) & "-" & YEAR('Follow up (ship 1)'!J5),"N/A") -> N/A | I2: Total abdominal hysterectomy | J2: Endometrium | K2: N/A | L2: F | M2: =IFERROR("Q" &INT((MONTH('Follow up (ship 1)'!P5)+2)/3) & "-" & YEAR('Follow up (ship 1)'!P5),"N/A") -> Q4-2016 | N2: 66 | O2: Carcinosarcoma with heterologous differentiation | P2: Y | Q2: 3c | R2: 1 | S2: 0 | T2: 0 | U2: IIIC1 | V2: NR | W2: T3CN1M0 | X2: IIIC1
A3: N | B3: LH17-6069 | C3: A11, A12 | D3: =IFERROR("Q" &INT((MONTH('Follow up (ship 1)'!F6)+2)/3) & "-" & YEAR('Follow up (ship 1)'!F6),"N/A") -> Q1-2017 | E3: LH17-6069 | F3: B3 | G3: Lymph node | H3: =IFERROR("Q" &INT((MONTH('Follow up (ship 1)'!J6)+2)/3) & "-" & YEAR('Follow up (ship 1)'!J6),"N/A") -> Q1-2017 | I3: Total abdominal hysterectomy | J3: Endometrium | K3: N/A | L3: F | M3: =IFERROR("Q" &INT((MONTH('Follow up (ship 1)'!P6)+2)/3) & "-" & YEAR('Follow up (ship 1)'!P6),"N/A") -> Q1-2017 | N3: 70 | O3: Endometrioid adenocarcinoma | P3: Y | Q3: 1b | R3: 0 | S3: x | T3: 0 | U3: IB | V3: 1 | W3: T1BN0M0 | X3: IB
A4: N | B4: LH17-7381 | C4: A9, A8 | D4: =IFERROR("Q" &INT((MONTH('Follow up (ship 1)'!F7)+2)/3) & "-" & YEAR('Follow up (ship 1)'!F7),"N/A") -> Q1-2017 | E4: LH17-7381 | F4: C1 | G4: Lymph node | H4: =IFERROR("Q" &INT((MONTH('Follow up (ship 1)'!J7)+2)/3) & "-" & YEAR('Follow up (ship 1)'!J7),"N/A") -> Q1-2017 | I4: Total abdominal hysterectomy | J4: Endometrium | K4: N/A | L4: F | M4: =IFERROR("Q" &INT((MONTH('Follow up (ship 1)'!P7)+2)/3) & "-" & YEAR('Follow up (ship 1)'!P7),"N/A") -> Q1-2017 | N4: 75 | O4: Deeply invasive mixed adenocarcinoma (serous and endometroiod) | P4: Y | Q4: 1b | R4: 0 | S4: 0 | T4: 0 | U4: IB | V4: 3 | W4: T1BN0M0 | X4: IB
A5: N | B5: LH17-10008 | C5: A4, A6 | D5: =IFERROR("Q" &INT((MONTH('Follow up (ship 1)'!F8)+2)/3) & "-" & YEAR('Follow up (ship 1)'!F8),"N/A") -> Q1-2017 | E5: N/A | F5: N/A | G5: N/A | H5: =IFERROR("Q" &INT((MONTH('Follow up (ship 1)'!J8)+2)/3) & "-" & YEAR('Follow up (ship 1)'!J8),"N/A") -> N/A | I5: Total abdominal hysterectomy | J5: Endometrium | K5: N/A | L5: F | M5: =IFERROR("Q" &INT((MONTH('Follow up (ship 1)'!P8)+2)/3) & "-" & YEAR('Follow up (ship 1)'!P8),"N/A") -> Q4-2016 | N5: 90 | O5: High grade serous adenocarcinoma | P5: Y | Q5: 2 | R5: 0 | S5: 0 | T5: 0 | U5: II | V5: 3 | W5: T2N0M0 | X5: II
A6: N | B6: LH17-10854 | C6: A6, A10 | D6: =IFERROR("Q" &INT((MONTH('Follow up (ship 1)'!F9)+2)/3) & "-" & YEAR('Follow up (ship 1)'!F9),"N/A") -> Q1-2017 | E6: N/A | F6: N/A | G6: N/A | H6: =IFERROR("Q" &INT((MONTH('Follow up (ship 1)'!J9)+2)/3) & "-" & YEAR('Follow up (ship 1)'!J9),"N/A") -> N/A | I6: Total abdominal hysterectomy | J6: Endometrium | K6: N/A | L6: F | M6: =IFERROR("Q" &INT((MONTH('Follow up (ship 1)'!P9)+2)/3) & "-" & YEAR('Follow up (ship 1)'!P9),"N/A") -> Q4-2002 | N6: 69 | O6: Malignant mixed mullerian tumour with rhabdomyoblastic differentiation | P6: Y | Q6: 1b | R6: 2 | S6: 0 | T6: 0 | U6: IB | V6: 3 | W6: T1BN2M0 | X6: IB
A7: N/A | B7: N/A | C7: N/A | D7: =IFERROR("Q" &INT((MONTH('Follow up (ship 1)'!F10)+2)/3) & "-" & YEAR('Follow up (ship 1)'!F10),"N/A") -> N/A | E7: LH17-11002 | F7: B5 | G7: Pelvic node | H7: =IFERROR("Q" &INT((MONTH('Follow up (ship 1)'!J10)+2)/3) & "-" & YEAR('Follow up (ship 1)'!J10),"N/A") -> Q1-2017 | I7: N/A | J7: N/A | K7: N/A | L7: F | M7: =IFERROR("Q" &INT((MONTH('Follow up (ship 1)'!P10)+2)/3) & "-" & YEAR('Follow up (ship 1)'!P10),"N/A") -> Q1-2017 | N7: 81 | O7: N/A | P7: N/A | Q7: N/A | R7: N/A | S7: N/A | T7: N/A | U7: N/A | V7: N/A | W7: N/A | X7: N/A
A8: N | B8: LH17-11093 | C8: A6,A8 | D8: =IFERROR("Q" &INT((MONTH('Follow up (ship 1)'!F11)+2)/3) & "-" & YEAR('Follow up (ship 1)'!F11),"N/A") -> Q1-2017 | E8: LH17-11093 | F8: D1 | G8: Lymph node | H8: =IFERROR("Q" &INT((MONTH('Follow up (ship 1)'!J11)+2)/3) & "-" & YEAR('Follow up (ship 1)'!J11),"N/A") -> Q1-2017 | I8: Total laparoscopic Hysterectomy | J8: Endometrium | K8: N/A | L8: F | M8: =IFERROR("Q" &INT((MONTH('Follow up (ship 1)'!P11)+2)/3) & "-" & YEAR('Follow up (ship 1)'!P11),"N/A") -> Q1-2017 | N8: 81 | O8: Endometrioid adenocarcinoma | P8: Y | Q8: 1b | R8: 0 | S8: 0 | T8: 0 | U8: IB | V8: 3 | W8: T1BN0M0 | X8: IB
A9: N | B9: LH17-11306 | C9: A8, A3 | D9: =IFERROR("Q" &INT((MONTH('Follow up (ship 1)'!F12)+2)/3) & "-" & YEAR('Follow up (ship 1)'!F12),"N/A") -> Q1-2017 | E9: N/A | F9: N/A | G9: N/A | H9: =IFERROR("Q" &INT((MONTH('Follow up (ship 1)'!J12)+2)/3) & "-" & YEAR('Follow up (ship 1)'!J12),"N/A") -> N/A | I9: Total abdominal hysterectomy | J9: Endometrium | K9: N/A | L9: F | M9: =IFERROR("Q" &INT((MONTH('Follow up (ship 1)'!P12)+2)/3) & "-" & YEAR('Follow up (ship 1)'!P12),"N/A") -> Q1-2017 | N9: 63 | O9: High grade carcinosarcoma of homologous type | P9: Y | Q9: 2 | R9: 0 | S9: 0 | T9: 0 | U9: II | V9: 3 | W9: T2N0M0 | X9: II
A10: N | B10: LH17-12612 | C10: A10, A4 | D10: =IFERROR("Q" &INT((MONTH('Follow up (ship 1)'!F13)+2)/3) & "-" & YEAR('Follow up (ship 1)'!F13),"N/A") -> Q1-2017 | E10: LH17-12612 | F10: C1 | G10: Pelvic node | H10: =IFERROR("Q" &INT((MONTH('Follow up (ship 1)'!J13)+2)/3) & "-" & YEAR('Follow up (ship 1)'!J13),"N/A") -> Q1-2017 | I10: Total abdominal hysterectomy | J10: Endometrium | K10: N/A | L10: F | M10: =IFERROR("Q" &INT((MONTH('Follow up (ship 1)'!P13)+2)/3) & "-" & YEAR('Follow up (ship 1)'!P13),"N/A") -> Q1-2017 | N10: 68 | O10: Endometrioid adenocarcinoma | P10: Y | Q10: 2 | R10: 0 | S10: 0 | T10: 0 | U10: II | V10: 1 | W10: T2N0M0 | X10: II
A11: N | B11: LH17-13646 | C11: A20, A21 | D11: =IFERROR("Q" &INT((MONTH('Follow up (ship 1)'!F14)+2)/3) & "-" & YEAR('Follow up (ship 1)'!F14),"N/A") -> Q1-2017 | E11: N/A | F11: N/A | G11: N/A | H11: =IFERROR("Q" &INT((MONTH('Follow up (ship 1)'!J14)+2)/3) & "-" & YEAR('Follow up (ship 1)'!J14),"N/A") -> N/A | I11: Total abdominal hysterectomy | J11: Endometrium | K11: N/A | L11: F | M11: =IFERROR("Q" &INT((MONTH('Follow up (ship 1)'!P14)+2)/3) & "-" & YEAR('Follow up (ship 1)'!P14),"N/A") -> Q1-2017 | N11: 84 | O11: High-grade serous adenocarcinoma of the endometrium | P11: N/A | Q11: N/R | R11: N/R | S11: 1 (Omentum) | T11: 1 (Lung and lymph node) | U11: IVB | V11: 3 | W11: N/A | X11: IVB
A12: N | B12: LH17-15131 | C12: A15, A12 | D12: =IFERROR("Q" &INT((MONTH('Follow up (ship 1)'!F15)+2)/3) & "-" & YEAR('Follow up (ship 1)'!F15),"N/A") -> Q2-2017 | E12: LH17-15131 | F12: G2 | G12: Lymph node | H12: =IFERROR("Q" &INT((MONTH('Follow up (ship 1)'!J15)+2)/3) & "-" & YEAR('Follow up (ship 1)'!J15),"N/A") -> Q2-2017 | I12: Total abdominal hysterectomy | J12: Endometrium | K12: N/A | L12: F | M12: =IFERROR("Q" &INT((MONTH('Follow up (ship 1)'!P15)+2)/3) & "-" & YEAR('Follow up (ship 1)'!P15),"N/A") -> Q2-2017 | N12: 69 | O12: Mixed high grade endometrioid and serous adenocarcinoma | P12: Y | Q12: 1b | R12: 0 | S12: 0 | T12: 0 | U12: IB | V12: 3 | W12: T1BN0M0 | X12: IB
A13: N | B13: LH17-16034 | C13: A9, A15 | D13: =IFERROR("Q" &INT((MONTH('Follow up (ship 1)'!F16)+2)/3) & "-" & YEAR('Follow up (ship 1)'!F16),"N/A") -> Q2-2017 | E13: N/A | F13: N/A | G13: N/A | H13: =IFERROR("Q" &INT((MONTH('Follow up (ship 1)'!J16)+2)/3) & "-" & YEAR('Follow up (ship 1)'!J16),"N/A") -> N/A | I13: Total abdominal hysterectomy | J13: Endometrium | K13: N/A | L13: F | M13: =IFERROR("Q" &INT((MONTH('Follow up (ship 1)'!P16)+2)/3) & "-" & YEAR('Follow up (ship 1)'!P16),"N/A") -> Q1-2017 | N13: 70 | O13: Papillary serous carcinoma | P13: Y | Q13: 1b | R13: 0 | S13: 0 | T13: 0 | U13: IB | V13: 3 | W13: T1BN0M0 | X13: IB
A14: N | B14: LH17-16275 | C14: A6, A15 | D14: =IFERROR("Q" &INT((MONTH('Follow up (ship 1)'!F17)+2)/3) & "-" & YEAR('Follow up (ship 1)'!F17),"N/A") -> Q2-2017 | E14: N/A | F14: N/A | G14: N/A | H14: =IFERROR("Q" &INT((MONTH('Follow up (ship 1)'!J17)+2)/3) & "-" & YEAR('Follow up (ship 1)'!J17),"N/A") -> N/A | I14: Total abdominal hysterectomy | J14: Endometrium | K14: N/A | L14: F | M14: =IFERROR("Q" &INT((MONTH('Follow up (ship 1)'!P17)+2)/3) & "-" & YEAR('Follow up (ship 1)'!P17),"N/A") -> Q1-2017 | N14: 77 | O14: Adenocarcinoma. Mixed clear cell/endometriod | P14: Y | Q14: 1a | R14: 0 | S14: 0 | T14: 0 | U14: IA | V14: N/R | W14: T1AN0M0 | X14: IA
A15: N | B15: LH17-20256 | C15: 8, 10 | D15: =IFERROR("Q" &INT((MONTH('Follow up (ship 1)'!F18)+2)/3) & "-" & YEAR('Follow up (ship 1)'!F18),"N/A") -> Q2-2017 | E15: N/A | F15: N/A | G15: N/A | H15: =IFERROR("Q" &INT((MONTH('Follow up (ship 1)'!J18)+2)/3) & "-" & YEAR('Follow up (ship 1)'!J18),"N/A") -> N/A | I15: Total laparoscopic hysterectomy | J15: Endometrium | K15: N/A | L15: F | M15: =IFERROR("Q" &INT((MONTH('Follow up (ship 1)'!P18)+2)/3) & "-" & YEAR('Follow up (ship 1)'!P18),"N/A") -> Q2-2017 | N15: 79 | O15: Endometrioid adenocarcinoma | P15: Y | Q15: 1b | R15: 0 | S15: 0 | T15: 0 | U15: IB | V15: 1 | W15: T1BN0M0 | X15: IB
A16: N | B16: LH17-22802 | C16: 3,5 | D16: =IFERROR("Q" &INT((MONTH('Follow up (ship 1)'!F19)+2)/3) & "-" & YEAR('Follow up (ship 1)'!F19),"N/A") -> Q2-2017 | E16: N/A | F16: N/A | G16: N/A | H16: =IFERROR("Q" &INT((MONTH('Follow up (ship 1)'!J19)+2)/3) & "-" & YEAR('Follow up (ship 1)'!J19),"N/A") -> N/A | I16: Total laparoscopic hysterectomy | J16: Endometrium | K16: N/A | L16: F | M16: =IFERROR("Q" &INT((MONTH('Follow up (ship 1)'!P19)+2)/3) & "-" & YEAR('Follow up (ship 1)'!P19),"N/A") -> Q1-2017 | N16: 80 | O16: Endometrioid adenocarcinoma | P16: Y | Q16: 1b | R16: 0 | S16: 0 | T16: 0 | U16: IB | V16: 1 | W16: T1BN0M0 | X16: IB
A17: N | B17: LH17-25751 | C17: A16, A33 | D17: =IFERROR("Q" &INT((MONTH('Follow up (ship 1)'!F20)+2)/3) & "-" & YEAR('Follow up (ship 1)'!F20),"N/A") -> Q2-2017 | E17: LH17-25751 | F17: C3 | G17: Pelvic node | H17: =IFERROR("Q" &INT((MONTH('Follow up (ship 1)'!J20)+2)/3) & "-" & YEAR('Follow up (ship 1)'!J20),"N/A") -> Q2-2017 | I17: Total abdominal hysterectomy | J17: Endometrium | K17: N/A | L17: F | M17: =IFERROR("Q" &INT((MONTH('Follow up (ship 1)'!P20)+2)/3) & "-" & YEAR('Follow up (ship 1)'!P20),"N/A") -> Q2-2017 | N17: 72 | O17: Endometrioid adenocarcinoma | P17: Y | Q17: 1a | R17: 0 | S17: 0 | T17: 0 | U17: IA | V17: 2 | W17: T1AN0M0 | X17: IA
A18: N | B18: LH17-28006 | C18: A11, A13 | D18: =IFERROR("Q" &INT((MONTH('Follow up (ship 1)'!F21)+2)/3) & "-" & YEAR('Follow up (ship 1)'!F21),"N/A") -> Q3-2017 | E18: N/A | F18: N/A | G18: N/A | H18: =IFERROR("Q" &INT((MONTH('Follow up (ship 1)'!J21)+2)/3) & "-" & YEAR('Follow up (ship 1)'!J21),"N/A") -> N/A | I18: Total laparoscopic hysterectomy | J18: Endometrium | K18: N/A | L18: F | M18: =IFERROR("Q" &INT((MONTH('Follow up (ship 1)'!P21)+2)/3) & "-" & YEAR('Follow up (ship 1)'!P21),"N/A") -> Q2-2017 | N18: 87 | O18: Serous adenocarcinoma | P18: Y | Q18: 1b | R18: 0 | S18: 0 | T18: 0 | U18: IB | V18: 3 | W18: T1BN0M0 | X18: IB
A19: N | B19: LH17-28649 | C19: A6, A11 | D19: =IFERROR("Q" &INT((MONTH('Follow up (ship 1)'!F22)+2)/3) & "-" & YEAR('Follow up (ship 1)'!F22),"N/A") -> Q3-2017 | E19: N/A | F19: N/A | G19: N/A | H19: =IFERROR("Q" &INT((MONTH('Follow up (ship 1)'!J22)+2)/3) & "-" & YEAR('Follow up (ship 1)'!J22),"N/A") -> N/A | I19: Total laparoscopic hysterectomy | J19: Endometrium | K19: N/A | L19: F | M19: =IFERROR("Q" &INT((MONTH('Follow up (ship 1)'!P22)+2)/3) & "-" & YEAR('Follow up (ship 1)'!P22),"N/A") -> Q2-2017 | N19: 71 | O19: Endometrioid adenocarcinoma | P19: N/R | Q19: 1b | R19: 0 | S19: 0 | T19: 0 | U19: IB | V19: 1 | W19: T1BN0M0 | X19: IB
A20: N | B20: LH17-29718 | C20: 15, 6 | D20: =IFERROR("Q" &INT((MONTH('Follow up (ship 1)'!F23)+2)/3) & "-" & YEAR('Follow up (ship 1)'!F23),"N/A") -> Q3-2017 | E20: N/A | F20: N/A | G20: N/A | H20: =IFERROR("Q" &INT((MONTH('Follow up (ship 1)'!J23)+2)/3) & "-" & YEAR('Follow up (ship 1)'!J23),"N/A") -> N/A | I20: Total laparoscopic hysterectomy | J20: Endometrium | K20: N/A | L20: F | M20: =IFERROR("Q" &INT((MONTH('Follow up (ship 1)'!P23)+2)/3) & "-" & YEAR('Follow up (ship 1)'!P23),"N/A") -> Q1-2017 | N20: 74 | O20: Endometrioid adenocarcinoma | P20: N/R | Q20: 1a | R20: 0 | S20: 0 | T20: 0 | U20: IA | V20: 1 | W20: T1AN0M0 | X20: IA
A21: N | B21: LH17-30635 | C21: A13, A14 | D21: =IFERROR("Q" &INT((MONTH('Follow up (ship 1)'!F24)+2)/3) & "-" & YEAR('Follow up (ship 1)'!F24),"N/A") -> Q3-2017 | E21: LH17-30635 | F21: D3 | G21: Pelvic node | H21: =IFERROR("Q" &INT((MONTH('Follow up (ship 1)'!J24)+2)/3) & "-" & YEAR('Follow up (ship 1)'!J24),"N/A") -> Q3-2017 | I21: Total laparoscopic hysterectomy | J21: Endometrium | K21: N/A | L21: F | M21: =IFERROR("Q" &INT((MONTH('Follow up (ship 1)'!P24)+2)/3) & "-" & YEAR('Follow up (ship 1)'!P24),"N/A") -> Q3-2017 | N21: 59 | O21: Endometrioid adenocarcinoma | P21: Y | Q21: 1b | R21: 0 | S21: 0 | T21: 0 | U21: IB | V21: 3 | W21: T1BN0M0 | X21: IB
A22: N/A | B22: N/A | C22: N/A | D22: =IFERROR("Q" &INT((MONTH('Follow up (ship 1)'!F25)+2)/3) & "-" & YEAR('Follow up (ship 1)'!F25),"N/A") -> N/A | E22: LH17-30829 | F22: D4 | G22: Pelvic node | H22: =IFERROR("Q" &INT((MONTH('Follow up (ship 1)'!J25)+2)/3) & "-" & YEAR('Follow up (ship 1)'!J25),"N/A") -> Q3-2017 | I22: N/A | J22: N/A | K22: N/A | L22: F | M22: =IFERROR("Q" &INT((MONTH('Follow up (ship 1)'!P25)+2)/3) & "-" & YEAR('Follow up (ship 1)'!P25),"N/A") -> Q3-2017 | N22: 76 | O22: N/A | P22: N/A | Q22: N/A | R22: N/A | S22: N/A | T22: N/A | U22: N/A | V22: N/A | W22: N/A | X22: N/A
A23: N | B23: LH17-30839 | C23: A15 | D23: =IFERROR("Q" &INT((MONTH('Follow up (ship 1)'!F26)+2)/3) & "-" & YEAR('Follow up (ship 1)'!F26),"N/A") -> Q3-2017 | E23: N/A | F23: N/A | G23: N/A | H23: =IFERROR("Q" &INT((MONTH('Follow up (ship 1)'!J26)+2)/3) & "-" & YEAR('Follow up (ship 1)'!J26),"N/A") -> N/A | I23: Total abdominal hysterectomy | J23: Endometrium | K23: N/A | L23: F | M23: =IFERROR("Q" &INT((MONTH('Follow up (ship 1)'!P26)+2)/3) & "-" & YEAR('Follow up (ship 1)'!P26),"N/A") -> Q2-2017 | N23: 77 | O23: Endometrioid carcinoma | P23: Y | Q23: 1a | R23: 0 | S23: 0 | T23: 0 | U23: IA | V23: 1 | W23: T1AN0M0 | X23: IA
A24: N | B24: LH17-30974 | C24: A12, A22 | D24: =IFERROR("Q" &INT((MONTH('Follow up (ship 1)'!F27)+2)/3) & "-" & YEAR('Follow up (ship 1)'!F27),"N/A") -> Q3-2017 | E24: N/A | F24: N/A | G24: N/A | H24: =IFERROR("Q" &INT((MONTH('Follow up (ship 1)'!J27)+2)/3) & "-" & YEAR('Follow up (ship 1)'!J27),"N/A") -> N/A | I24: Total abdominal hysterectomy | J24: Endometrium | K24: N/A | L24: F | M24: =IFERROR("Q" &INT((MONTH('Follow up (ship 1)'!P27)+2)/3) & "-" & YEAR('Follow up (ship 1)'!P27),"N/A") -> Q4-2012 | N24: 51 | O24: Endometrioid adenocarcinoma | P24: Y | Q24: 1a | R24: 0 | S24: 0 | T24: 0 | U24: IA | V24: 1 | W24: T1AN0M0 | X24: IA
A25: N | B25: LH17-32555 | C25: A6 | D25: =IFERROR("Q" &INT((MONTH('Follow up (ship 1)'!F28)+2)/3) & "-" & YEAR('Follow up (ship 1)'!F28),"N/A") -> Q3-2017 | E25: N/A | F25: N/A | G25: N/A | H25: =IFERROR("Q" &INT((MONTH('Follow up (ship 1)'!J28)+2)/3) & "-" & YEAR('Follow up (ship 1)'!J28),"N/A") -> N/A | I25: Total laparoscopic hysterectomy | J25: Endometrium | K25: N/A | L25: F | M25: =IFERROR("Q" &INT((MONTH('Follow up (ship 1)'!P28)+2)/3) & "-" & YEAR('Follow up (ship 1)'!P28),"N/A") -> Q2-2017 | N25: 64 | O25: Endometrioid adenocarcinoma | P25: Y | Q25: 1b | R25: 0 | S25: 0 | T25: 0 | U25: IB | V25: 1 | W25: T1BN0M0 | X25: IB
A26: N | B26: LH17-32987 | C26: 6,7 | D26: =IFERROR("Q" &INT((MONTH('Follow up (ship 1)'!F29)+2)/3) & "-" & YEAR('Follow up (ship 1)'!F29),"N/A") -> Q3-2017 | E26: N/A | F26: N/A | G26: N/A | H26: =IFERROR("Q" &INT((MONTH('Follow up (ship 1)'!J29)+2)/3) & "-" & YEAR('Follow up (ship 1)'!J29),"N/A") -> N/A | I26: Total laparoscopic hysterectomy | J26: Endometrium | K26: N/A | L26: F | M26: =IFERROR("Q" &INT((MONTH('Follow up (ship 1)'!P29)+2)/3) & "-" & YEAR('Follow up (ship 1)'!P29),"N/A") -> Q2-2017 | N26: 62 | O26: Endometrioid carcinoma | P26: N/R | Q26: 2 | R26: 0 | S26: 0 | T26: 0 | U26: II | V26: 2 | W26: T2N0M0 | X26: II
A27: N | B27: LH17-33790 | C27: A11, A12 | D27: =IFERROR("Q" &INT((MONTH('Follow up (ship 1)'!F30)+2)/3) & "-" & YEAR('Follow up (ship 1)'!F30),"N/A") -> Q3-2017 | E27: LH17-33790 | F27: C3 | G27: Pelvic node | H27: =IFERROR("Q" &INT((MONTH('Follow up (ship 1)'!J30)+2)/3) & "-" & YEAR('Follow up (ship 1)'!J30),"N/A") -> Q3-2017 | I27: Total abdominal hysterectomy | J27: Endometrium | K27: N/A | L27: F | M27: =IFERROR("Q" &INT((MONTH('Follow up (ship 1)'!P30)+2)/3) & "-" & YEAR('Follow up (ship 1)'!P30),"N/A") -> Q2-2017 | N27: 82 | O27: Endometrioid adenocarcinoma | P27: Y | Q27: 3a | R27: 0 | S27: 0 | T27: 0 | U27: IIIA | V27: 3 | W27: T3AN0M0 | X27: IIIA
A28: N | B28: LH17-34068 | C28: 4 | D28: =IFERROR("Q" &INT((MONTH('Follow up (ship 1)'!F31)+2)/3) & "-" & YEAR('Follow up (ship 1)'!F31),"N/A") -> Q3-2017 | E28: N/A | F28: N/A | G28: N/A | H28: =IFERROR("Q" &INT((MONTH('Follow up (ship 1)'!J31)+2)/3) & "-" & YEAR('Follow up (ship 1)'!J31),"N/A") -> N/A | I28: Total laparoscopic hysterectomy | J28: Endometrium | K28: N/A | L28: F | M28: =IFERROR("Q" &INT((MONTH('Follow up (ship 1)'!P31)+2)/3) & "-" & YEAR('Follow up (ship 1)'!P31),"N/A") -> Q3-2017 | N28: 60 | O28: Endometrioid adenocarcinoma | P28: N/R | Q28: 1a | R28: 0 | S28: 0 | T28: 0 | U28: IA | V28: 1 | W28: T1AN0M0 | X28: IA
A29: N | B29: LH17-34353 | C29: A7, A6 | D29: =IFERROR("Q" &INT((MONTH('Follow up (ship 1)'!F32)+2)/3) & "-" & YEAR('Follow up (ship 1)'!F32),"N/A") -> Q3-2017 | E29: N/A | F29: N/A | G29: N/A | H29: =IFERROR("Q" &INT((MONTH('Follow up (ship 1)'!J32)+2)/3) & "-" & YEAR('Follow up (ship 1)'!J32),"N/A") -> N/A | I29: Total abdominal hysterectomy | J29: Endometrium | K29: N/A | L29: F | M29: =IFERROR("Q" &INT((MONTH('Follow up (ship 1)'!P32)+2)/3) & "-" & YEAR('Follow up (ship 1)'!P32),"N/A") -> Q2-2017 | N29: 71 | O29: Carcinosarcoma with heterologous elements | P29: Y | Q29: 3 | R29: 2 | S29: 0 | T29: 0 | U29: IIIC2 | V29: N/R | W29: T3CN2M0 | X29: IIIC2
A30: N | B30: LH17-35617 | C30: A2 | D30: =IFERROR("Q" &INT((MONTH('Follow up (ship 1)'!F33)+2)/3) & "-" & YEAR('Follow up (ship 1)'!F33),"N/A") -> Q3-2017 | E30: N/A | F30: N/A | G30: N/A | H30: =IFERROR("Q" &INT((MONTH('Follow up (ship 1)'!J33)+2)/3) & "-" & YEAR('Follow up (ship 1)'!J33),"N/A") -> N/A | I30: Total laparoscopic hysterectomy | J30: Endometrium | K30: N/A | L30: F | M30: =IFERROR("Q" &INT((MONTH('Follow up (ship 1)'!P33)+2)/3) & "-" & YEAR('Follow up (ship 1)'!P33),"N/A") -> Q2-2017 | N30: 82 | O30: Endometrioid carcinoma | P30: Y | Q30: 1a | R30: 0 | S30: 0 | T30: 0 | U30: IA | V30: 1 | W30: T1AN0M0 | X30: IA
A31: N | B31: LH17-35965 | C31: A9, A10 | D31: =IFERROR("Q" &INT((MONTH('Follow up (ship 1)'!F34)+2)/3) & "-" & YEAR('Follow up (ship 1)'!F34),"N/A") -> Q3-2017 | E31: LH17-35965 | F31: B4 | G31: Lymph node | H31: =IFERROR("Q" &INT((MONTH('Follow up (ship 1)'!J34)+2)/3) & "-" & YEAR('Follow up (ship 1)'!J34),"N/A") -> Q3-2017 | I31: Total laparoscopic hysterectomy | J31: Endometrium | K31: N/A | L31: F | M31: =IFERROR("Q" &INT((MONTH('Follow up (ship 1)'!P34)+2)/3) & "-" & YEAR('Follow up (ship 1)'!P34),"N/A") -> Q3-2017 | N31: 60 | O31: Clear cell carcinoma of endometrium | P31: Y | Q31: 2 | R31: 0 | S31: 0 | T31: 0 | U31: II | V31: 3 | W31: T2N0M0 | X31: II
A32: N | B32: LH17-36526 | C32: A7, A6 | D32: =IFERROR("Q" &INT((MONTH('Follow up (ship 1)'!F35)+2)/3) & "-" & YEAR('Follow up (ship 1)'!F35),"N/A") -> Q3-2017 | E32: N/A | F32: N/A | G32: N/A | H32: =IFERROR("Q" &INT((MONTH('Follow up (ship 1)'!J35)+2)/3) & "-" & YEAR('Follow up (ship 1)'!J35),"N/A") -> N/A | I32: Total laparoscopic hysterectomy | J32: Endometrium | K32: N/A | L32: F | M32: =IFERROR("Q" &INT((MONTH('Follow up (ship 1)'!P35)+2)/3) & "-" & YEAR('Follow up (ship 1)'!P35),"N/A") -> Q3-2017 | N32: 84 | O32: Endometrioid carcinoma | P32: Y | Q32: 3 | R32: 1 | S32: 0 | T32: 0 | U32: IIIC1 | V32: 2 | W32: T3CN1M0 | X32: IIIC1
A33: N | B33: LH17-36679 | C33: A9, A8 | D33: =IFERROR("Q" &INT((MONTH('Follow up (ship 1)'!F36)+2)/3) & "-" & YEAR('Follow up (ship 1)'!F36),"N/A") -> Q3-2017 | E33: N/A | F33: N/A | G33: N/A | H33: =IFERROR("Q" &INT((MONTH('Follow up (ship 1)'!J36)+2)/3) & "-" & YEAR('Follow up (ship 1)'!J36),"N/A") -> N/A | I33: Total abdominal hysterectomy | J33: Endometrium | K33: N/A | L33: F | M33: =IFERROR("Q" &INT((MONTH('Follow up (ship 1)'!P36)+2)/3) & "-" & YEAR('Follow up (ship 1)'!P36),"N/A") -> Q2-2017 | N33: 60 | O33: Endometrioid carcinoma | P33: Y | Q33: 3 | R33: 2 | S33: 0 | T33: 0 | U33: IIIC2 | V33: 2 | W33: T3CN2M0 | X33: IIIC2
A34: N | B34: LH17-37241 | C34: A5, A6 | D34: =IFERROR("Q" &INT((MONTH('Follow up (ship 1)'!F37)+2)/3) & "-" & YEAR('Follow up (ship 1)'!F37),"N/A") -> Q3-2017 | E34: N/A | F34: N/A | G34: N/A | H34: =IFERROR("Q" &INT((MONTH('Follow up (ship 1)'!J37)+2)/3) & "-" & YEAR('Follow up (ship 1)'!J37),"N/A") -> N/A | I34: Total abdominal hysterectomy | J34: Endometrium | K34: N/A | L34: F | M34: =IFERROR("Q" &INT((MONTH('Follow up (ship 1)'!P37)+2)/3) & "-" & YEAR('Follow up (ship 1)'!P37),"N/A") -> Q3-2017 | N34: 75 | O34: Carcinosarcoma with heterologous elements | P34: Y | Q34: 1b | R34: 0 | S34: 0 | T34: 0 | U34: IB | V34: 3 | W34: T1BN0M0 | X34: IB
A35: N | B35: LH17-37984 | C35: A4, A5 | D35: =IFERROR("Q" &INT((MONTH('Follow up (ship 1)'!F38)+2)/3) & "-" & YEAR('Follow up (ship 1)'!F38),"N/A") -> Q3-2017 | E35: N/A | F35: N/A | G35: N/A | H35: =IFERROR("Q" &INT((MONTH('Follow up (ship 1)'!J38)+2)/3) & "-" & YEAR('Follow up (ship 1)'!J38),"N/A") -> N/A | I35: Total abdominal hysterectomy | J35: Endometrium | K35: N/A | L35: F | M35: =IFERROR("Q" &INT((MONTH('Follow up (ship 1)'!P38)+2)/3) & "-" & YEAR('Follow up (ship 1)'!P38),"N/A") -> Q3-2017 | N35: 63 | O35: Endometrioid adenocarcinoma with foci of clear cell differentiation | P35: Y | Q35: 1b | R35: 0 | S35: 0 | T35: 0 | U35: IB | V35: 2 | W35: T1BN0M0 | X35: IB
A36: N | B36: LH17-38467 | C36: A7, A6 | D36: =IFERROR("Q" &INT((MONTH('Follow up (ship 1)'!F39)+2)/3) & "-" & YEAR('Follow up (ship 1)'!F39),"N/A") -> Q3-2017 | E36: N/A | F36: N/A | G36: N/A | H36: =IFERROR("Q" &INT((MONTH('Follow up (ship 1)'!J39)+2)/3) & "-" & YEAR('Follow up (ship 1)'!J39),"N/A") -> N/A | I36: Total abdominal hysterectomy | J36: Endometrium | K36: N/A | L36: F | M36: =IFERROR("Q" &INT((MONTH('Follow up (ship 1)'!P39)+2)/3) & "-" & YEAR('Follow up (ship 1)'!P39),"N/A") -> Q3-2017 | N36: 64 | O36: Endometrioid carcinoma | P36: Y | Q36: 3 | R36: 1 | S36: 0 | T36: 0 | U36: IIIC1 | V36: 2 | W36: T3CN1M0 | X36: IIIC1
A37: N | B37: LH17-40476 | C37: A6, A7 | D37: =IFERROR("Q" &INT((MONTH('Follow up (ship 1)'!F40)+2)/3) & "-" & YEAR('Follow up (ship 1)'!F40),"N/A") -> Q3-2017 | E37: LH17-40476 | F37: D9 | G37: Pelvic node | H37: =IFERROR("Q" &INT((MONTH('Follow up (ship 1)'!J40)+2)/3) & "-" & YEAR('Follow up (ship 1)'!J40),"N/A") -> Q3-2017 | I37: Total abdominal hysterectomy | J37: Endometrium | K37: N/A | L37: F | M37: =IFERROR("Q" &INT((MONTH('Follow up (ship 1)'!P40)+2)/3) & "-" & YEAR('Follow up (ship 1)'!P40),"N/A") -> Q3-2017 | N37: 69 | O37: High-grade serous carcinoma | P37: Y | Q37: 1b | R37: 0 | S37: 0 | T37: 0 | U37: IB | V37: 3 | W37: T1BN0M0 | X37: IB
A38: N | B38: LH17-41239 | C38: A13, A22 | D38: =IFERROR("Q" &INT((MONTH('Follow up (ship 1)'!F41)+2)/3) & "-" & YEAR('Follow up (ship 1)'!F41),"N/A") -> Q3-2017 | E38: N/A | F38: N/A | G38: N/A | H38: =IFERROR("Q" &INT((MONTH('Follow up (ship 1)'!J41)+2)/3) & "-" & YEAR('Follow up (ship 1)'!J41),"N/A") -> N/A | I38: Total abdominal hysterectomy | J38: Endometrium | K38: N/A | L38: F | M38: =IFERROR("Q" &INT((MONTH('Follow up (ship 1)'!P41)+2)/3) & "-" & YEAR('Follow up (ship 1)'!P41),"N/A") -> Q4-2017 | N38: 76 | O38: Carcinosarcoma showing rhabdomyoblastic differentiation | P38: Y | Q38: 3 | R38: 2 | S38: 0 | T38: 0 | U38: IIIC2 | V38: 3 | W38: T3CN2M0 | X38: IIIC2
A39: N | B39: LH17-41484 | C39: A4, A5 | D39: =IFERROR("Q" &INT((MONTH('Follow up (ship 1)'!F42)+2)/3) & "-" & YEAR('Follow up (ship 1)'!F42),"N/A") -> Q3-2017 | E39: N/A | F39: N/A | G39: N/A | H39: =IFERROR("Q" &INT((MONTH('Follow up (ship 1)'!J42)+2)/3) & "-" & YEAR('Follow up (ship 1)'!J42),"N/A") -> N/A | I39: Total abdominal hysterectomy nec | J39: Endometrium | K39: N/A | L39: F | M39: =IFERROR("Q" &INT((MONTH('Follow up (ship 1)'!P42)+2)/3) & "-" & YEAR('Follow up (ship 1)'!P42),"N/A") -> Q2-2017 | N39: 74 | O39: Endometrioid adenocarcinoma | P39: Y | Q39: 3 | R39: 1 | S39: 0 | T39: 0 | U39: IIIC1 | V39: 3 | W39: T3CN1M0 | X39: IIIC1
A40: N | B40: LH17-41775 | C40: A8, A16 | D40: =IFERROR("Q" &INT((MONTH('Follow up (ship 1)'!F43)+2)/3) & "-" & YEAR('Follow up (ship 1)'!F43),"N/A") -> Q3-2017 | E40: N/A | F40: N/A | G40: N/A | H40: =IFERROR("Q" &INT((MONTH('Follow up (ship 1)'!J43)+2)/3) & "-" & YEAR('Follow up (ship 1)'!J43),"N/A") -> N/A | I40: Total abdominal hysterectomy | J40: Endometrium | K40: N/A | L40: F | M40: =IFERROR("Q" &INT((MONTH('Follow up (ship 1)'!P43)+2)/3) & "-" & YEAR('Follow up (ship 1)'!P43),"N/A") -> Q3-2017 | N40: 64 | O40: Endometrioid adenocarcinoma | P40: Y | Q40: 1a | R40: 0 | S40: 0 | T40: 0 | U40: IA | V40: 1 | W40: T1AN0M0 | X40: IA
...

Sheet Follow up (ship 2)
A1: NHS | B1: Any Immunotherapy | C1: Specimen is a recurrence (Y/N) | D1: Specimen IO naive (Y/N) | E1: Selected specimen Anonymised ID | F1: Specimen Block number | G1: Specimen Surgery Date (DD/MM/YYYY) | H1: Specimen surgery | I1: Specimen tumour site | J1: Primary tumour site | K1: Gender | L1: DOB (DD/MM/YYYY) | M1: Date of DX (DD/MM/YYYY) | N1: Age at Diagnosis (years) | O1: Specimen Histological Diagnosis | P1: Resection margins clear (Y/N) | Q1: FIGO Grade | R1: Stage at DX (FIGO) | S1: Neoadjuvant therapy (Y/N) | T1: Response to neoadjuvant therapy (TRS score) | U1: Neoadjuvant radioTx | V1: Start Date | W1: End Date | X1: Tumour response | Y1: Neoadjuvant chemo Tx1 | Z1: Start Date2 | AA1: End Date3 | AB1: Tumour response4 | AC1: Neoadjuvant chemo Tx2 | AD1: Start Date5 | AE1: End Date6 | AF1: Tumour response7 | AG1: Neoadjuvant chemoTx 3 | AH1: Start Date8 | AI1: End Date9 | AJ1: Tumour response10 | AK1: Neoadjuvant Immunotherapy Tx 1 | AL1: Start Date11 | AM1: End Date12 | AN1: Tumour response13 | AO1: Neoadjuvant Immunotherapy Tx 2 | AP1: Start Date14 | AQ1: End Date15 | AR1: Tumour response16 | AS1: Adjuvant radio Tx 1 | AT1: Start Date | AU1: End Date17 | AV1: Adjuvant ChemoTx 1 | AW1: Start Date18 | AX1: End Date19 | AY1: Tumour response20 | AZ1: Adjuvant ChemoTx 2 | BA1: Start Date21 | BB1: End Date22 | BC1: Tumour response | BD1: Adjuvant ChemoTx 3 | BE1: Start Date23 | BF1: End Date24 | BG1: Tumour response25 | BH1: Adjuvant Imunnotherapy Tx1 | BI1: Start Date26 | BJ1: End Date27 | BK1: Tumour response 28 | BL1: Date relapse/ progression 1 | BM1: Sites relapse/ progression 1 | BN1: Date relapse/ progression 2 | BO1: Sites relapse/ progression 2 | BP1: Date relapse/ progression 3 | BQ1: Sites relapse/ progression 3 | BR1: Date relapse/ progression 4 | BS1: Sites relapse/ progression 4 | BT1: Date relapse/ progression 5 | BU1: Sites relapse/ progression 5 | BV1: Date relapse/ progression 6 | BW1: Sites relapse/ progression 6 | BX1: Date relapse/ progression 7 | BY1: Sites relapse/ progression 7 | BZ1: Date relapse/ progression 8 | CA1: Sites relapse/ progression 8 | CB1: Date relapse/ progression 9 | CC1: Sites relapse/ progression 9 | CD1: Metastatic/ recurrent Tx 1 | CE1: Start Date29 | CF1: Finish Date | CG1: Tumour response30 | CH1: Metastatic/ recurrent Tx 2 | CI1: Start Date31 | CJ1: Finish Date32 | CK1: Tumour response33 | CL1: Metastatic/ recurrent Tx 3 | CM1: Start Date34 | CN1: Finish Date35 | CO1: Tumour response36 | CP1: Current Status | CQ1: Death date | CR1: Death due to tumour/ assumed tumour related? (Y/N) | CS1: Cause of death | CT1: Date last follow-up | CU1: Date Last Seen | CV1: Concurrent Medical Conditions | CW1: Rx1 start | CX1: Rx1 end | CY1: Chemo Tx1 start | CZ1: Chemo Tx1 end | DA1: Chemo Tx2 start | DB1: Chemo Tx2 end | DC1: Chemo Tx3 start | DD1: Chemo Tx3 end | DE1: Immunotherapy Tx1 start | DF1: Immunotherapy Tx1 end | DG1: Immunotherapy Tx2 start | DH1: Immunotherapy Tx2 end | DI1: Specimen surgery37 | DJ1: Matched met 1 surgery | DK1: Matched met 2 surgery | DL1: Normal tissue surgery | DM1: Adjuvant Rx1 start | DN1: Adjuvant Rx1 end | DO1: Adjuvant Chemo Tx1 start | DP1: Adjuvant Chemo Tx1 end | DQ1: Adjuvant Chemo Tx2 start | DR1: Adjuvant Chemo Tx2 end | DS1: Adjuvant Chemo Tx3 start | DT1: Adjuvant Chemo Tx3 end | DU1: Immunotherapy Tx1 start38 | DV1: Immunotherapy Tx1 end 39 | DW1: Relapse/ progression 1 | DX1: Relapse/ progression 2 | DY1: Relapse/ progression 3 | DZ1: Relapse/ progression 4 | EA1: Relapse/ progression 5 | EB1: Relapse/ progression 6 | EC1: Relapse/ progression 7 | ED1: Relapse/ progression 8 | EE1: Relapse/ progression 9 | EF1: Metastatic Tx1 start | EG1: Metastatic Tx1 end | EH1: Metastatic Tx2 start | EI1: Metastatic Tx2 end | EJ1: Metastatic Tx3 start | EK1: Metastatic Tx3 end | EL1: Recurrence (PFS) | EM1: Death (OS and PFS) | EN1: Date last follow-up (PFS) | EO1: Date last seen (OS) | EP1: Overall survival (OS) in months | EQ1: Progression free survival (PFS) in months | ER1: Event (recurrence/progression) | ES1: Event (cancer death) | ET1: Event (death; all causes) | EU1: Event (recurrence or cancer death) | EV1: Comments from clinical team
A2: 4329209322 | B2: N | C2: N | D2: Y | E2: LH18-15364 | F2: A7,A6 | G2: 43201 | H2: Total Abdominal Hysterectomy; Bilateral Salpingo-oophorectomy; Bilateral Pelvic Lymphadenectomy; Infracolic Omental Biopsy; Peritoneal Washings. | I2: Endometrium | J2: N/A | K2: F | L2: 13592 | M2: 43172 | N2: =DATEDIF(L2, M2,"Y") -> 80 | O2: Endometrioid adenocarcinoma, NOS | P2: Y | Q2: 3 | R2: 1A
A3: 4860738853 | B3: N | C3: N | D3: Y | E3: LH18-15484 | F3: A14,A15, | G3: 43201 | H3: Total abdominal hysterectomy nec | I3: Endometrium | J3: N/A | K3: F | L3: 23226 | M3: 43194 | N3: =DATEDIF(L3, M3,"Y") -> 54 | O3: Endometrioid adenocarcinoma, NOS | P3: Y | Q3: 3 | R3: 2
A4: 4383572731 | B4: N | C4: N | D4: Y | E4: LH18-15845 | F4: A9(L),A11 | G4: 43203 | H4: Total laparoscopic hysterectomy | I4: Endometrium | J4: N/A | K4: F | L4: 14889 | M4: 43145 | N4: =DATEDIF(L4, M4,"Y") -> 77 | O4: Endometrioid adenocarcinoma, NOS | P4: Y | Q4: 2 | R4: 2
A5: 4303155993 | B5: N | C5: N | D5: Y | E5: LH18-16236 | F5: A5,A2 | G5: 43206 | H5: Total laparoscopic hysterectomy | I5: Endometrium | J5: N/A | K5: F | L5: 15806 | M5: 43076 | N5: =DATEDIF(L5, M5,"Y") -> 74 | O5: Endometrioid carcinoma, focal squamous differentiation | P5: Y | Q5: 1 | R5: 1a
A6: 4861956706 | B6: N | C6: N | D6: Y | E6: LH18-17511 | F6: A8,A3 | G6: 43214 | H6: Total laparoscopic hysterectomy | I6: Endometrium | J6: N/A | K6: F | L6: 22762 | M6: 43174 | N6: =DATEDIF(L6, M6,"Y") -> 55 | O6: Endometrioid carcinoma, squamous differentiation | P6: Y | Q6: 1 | R6: 2
A7: 4848783208 | B7: N | C7: N | D7: Y | E7: LH18-20193 | F7: A7, A8 | G7: 43230 | H7: Total laparoscopic hysterectomy | I7: Endometrium | J7: N/A | K7: F | L7: 21767 | M7: 43201 | N7: =DATEDIF(L7, M7,"Y") -> 58 | O7: Endometrioid adenocarcinoma, NOS | P7: Y | Q7: 1 | R7: 1b
A8: 4482209414 | B8: N | C8: N | D8: Y | E8: LH18-20274 | F8: A13, A14 | G8: 43231 | H8: Total laparoscopic hysterectomy | I8: Endometrium | J8: N/A | K8: F | L8: 18581 | M8: 43186 | N8: =DATEDIF(L8, M8,"Y") -> 67 | O8: Endometrioid adenocarcinoma, NOS | P8: Y | Q8: 3 | R8: 2
A9: 4849472818 | B9: N | C9: N | D9: Y | E9: LH18-20302 | F9: A10, A8 | G9: 43231 | H9: Total abdominal hysterectomy | I9: Endometrium | J9: N/A | K9: F | L9: 23252 | M9: 43195 | N9: =DATEDIF(L9, M9,"Y") -> 54 | O9: Endometrioid adenocarcinoma with mucinous and secretory differentiation | P9: Y | Q9: 1 | R9: 3a
A10: 4423755157 | B10: N | C10: N | D10: Y | E10: LH18-21046 | F10: A9, A6(L) | G10: 43236 | H10: Total abdominal hysterectomy nec | I10: Endometrium | J10: N/A | K10: F | L10: 16964 | M10: 43208 | N10: =DATEDIF(L10, M10,"Y") -> 71 | O10: Carcinosarcoma with heterologous elements; Squamous and Rhabdomyosarcomatous differentiation | P10: Y | Q10: 3 | R10: 1a
A11: 4606237317 | B11: N | C11: N | D11: Y | E11: LH18-22036 | F11: A6, A7 | G11: 43242 | H11: Total abdominal hysterectomy nec | I11: Endometrium | J11: N/A | K11: F | L11: 19419 | M11: 43215 | N11: =DATEDIF(L11, M11,"Y") -> 65 | O11: Mixed carcinoma: clear cell and endometrioid | P11: Y | Q11: 3 | R11: 4b
A12: 6311634686 | B12: N | C12: N | D12: Y | E12: LH18-22454 | F12: A4, A5 | G12: 43244 | H12: Total laparoscopic hysterectomy | I12: Endometrium | J12: N/A | K12: F | L12: 19906 | M12: 43193 | N12: =DATEDIF(L12, M12,"Y") -> 63 | O12: Endometrioid adenocarcinoma, NOS | P12: Y | Q12: 2 | R12: 1b
A13: 4381431065 | B13: N | C13: N | D13: Y | E13: LH18-22773 | F13: A6, A5 | G13: 43245 | H13: Total abdominal hysterectomy nec | I13: Endometrium | J13: N/A | K13: F | L13: 16307 | M13: 43216 | N13: =DATEDIF(L13, M13,"Y") -> 73 | O13: Serous carcinoma | P13: N | Q13: 3 | R13: 3c2
