Workbook

Sheet Follow up (ship 1)
A1: PLEASE BE AWARE COLUMNS MAY BE 'HIDDEN' OR 'COLLAPSED'
A3: NHS number | B3: Any Immunotherapy | C3: Specimen treatment subgrouping | D3: Specimen is a recurrence | E3: Selected specimen Anonymised ID | F3: Specimen Block number 1 | G3: Specimen Block number 2 | H3: Specimen surgery date | I3: Specimen surgery | J3: Specimen tumour site | K3: Primary Surgery date | L3: Primary tumour site | M3: Anonymized ID Matched met 1 | N3: Matched met 1 Block Number | O3: Matched met 1 Site | P3: Matched met 1 Surgery Date | Q3: Matched met 1 treatment subgrouping | R3: Anonymized ID Matched met 2 | S3: Matched met 2 Block Number | T3: Matched met 2 Site | U3: Matched met 2 Surgery Date | V3: Matched met 2 treatment subgrouping | W3: Anonymized ID Normal tissue | X3: Matched Normal tissue Block Number | Y3: Matched Normal tissue Site | Z3: Matched Normal tissue Surgery Date | AA3: Matched Normal treatment subgrouping | AB3: Gender | AC3: DOB | AD3: Date of DX | AE3: Age at Diagnosis | AF3: Specimen Histological Diagnosis | AG3: Staging/grading info provided for: | AH3: Resection margins clear | AI3: pT | AJ3: pN | AK3: pM | AL3: cM | AM3: TNM stage | AN3: Grade | AO3: Stage at DX (AJCC) | AP3: Any Neoadjuvant therapy | AQ3: Response to neoadjuvant therapy (TRS score) | AR3: Neoadjuvant Tx1 | AS3: Neoadjuvant Tx1 Agent | AT3: Neoadjuvant Tx1 Start Date | AU3: Neoadjuvant Tx1 End Date | AV3: Tumour response Neoadjuvant Tx1 | AW3: Neoadjuvant Tx2 | AX3: Neoadjuvant Tx2 Agent | AY3: Neoadjuvant Tx2 Start Date | AZ3: Neoadjuvant Tx2 End Date | BA3: Tumour response Neoadjuvant Tx2 | BB3: Neoadjuvant Tx3 | BC3: Neoadjuvant Tx3 Agent | BD3: Neoadjuvant Tx3 Start Date | BE3: Neoadjuvant Tx3 End Date | BF3: Tumour response Neoadjuvant Tx3 | BG3: Neoadjuvant Tx4 | BH3: Neoadjuvant Tx4 Agent | BI3: Neoadjuvant Tx4 Start Date | BJ3: Neoadjuvant Tx4 End Date | BK3: Tumour response Neoadjuvant Tx4 | BL3: Neoadjuvant Tx5 | BM3: Neoadjuvant Tx5 Agent | BN3: Neoadjuvant Tx5 Start Date | BO3: Neoadjuvant Tx5 End Date | BP3: Tumour response Neoadjuvant Tx5 | BQ3: Neoadjuvant Tx6 | BR3: Neoadjuvant Tx6 Agent | BS3: Neoadjuvant Tx6 Start Date | BT3: Neoadjuvant Tx6 End Date | BU3: Tumour response Neoadjuvant Tx6 | BV3: Neoadjuvant Tx7 | BW3: Neoadjuvant Tx7 Agent | BX3: Neoadjuvant Tx7 Start Date | BY3: Neoadjuvant Tx7 End Date | BZ3: Tumour response Neoadjuvant Tx7 | CA3: Neoadjuvant Tx8 | CB3: Neoadjuvant Tx8 Agent | CC3: Neoadjuvant Tx8 Start Date | CD3: Neoadjuvant Tx8 End Date | CE3: Tumour response Neoadjuvant Tx8 | CF3: Neoadjuvant Tx9 | CG3: Neoadjuvant Tx9 Agent | CH3: Neoadjuvant Tx9 Start Date | CI3: Neoadjuvant Tx9 End Date | CJ3: Tumour response Neoadjuvant Tx9 | CK3: Neoadjuvant Tx10 | CL3: Neoadjuvant Tx10 Agent | CM3: Neoadjuvant Tx10 Start Date | CN3: Neoadjuvant Tx10 End Date | CO3: Tumour response Neoadjuvant Tx10 | CP3: Adjuvant Tx1 | CQ3: Adjuvant Tx1 Agent | CR3: Adjuvant Tx1 Start Date | CS3: Adjuvant Tx1 End Date | CT3: Tumour response Adjuvant Tx1 | CU3: Adjuvant Tx2 | CV3: Adjuvant Tx2 Agent | CW3: Adjuvant Tx2 Start Date | CX3: Adjuvant Tx2 End Date | CY3: Tumour response Adjuvant Tx2 | CZ3: Adjuvant Tx3 | DA3: Adjuvant Tx3 Agent | DB3: Adjuvant Tx3 Start Date | DC3: Adjuvant Tx3 End Date | DD3: Tumour response Adjuvant Tx3 | DE3: Adjuvant Tx4 | DF3: Adjuvant Tx4 Agent | DG3: Adjuvant Tx4 Start Date | DH3: Adjuvant Tx4 End Date | DI3: Tumour response Adjuvant Tx4 | DJ3: Adjuvant Tx5 | DK3: Adjuvant Tx5 Agent | DL3: Adjuvant Tx5 Start Date | DM3: Adjuvant Tx5 End Date | DN3: Tumour response Adjuvant Tx5 | DO3: Adjuvant Tx6 | DP3: Adjuvant Tx6 Agent | DQ3: Adjuvant Tx6 Start Date | DR3: Adjuvant Tx6 End Date | DS3: Tumour response Adjuvant Tx6 | DT3: Adjuvant Tx7 | DU3: Adjuvant Tx7 Agent | DV3: Adjuvant Tx7 Start Date | DW3: Adjuvant Tx7 End Date | DX3: Tumour response Adjuvant Tx7 | DY3: Adjuvant Tx8 | DZ3: Adjuvant Tx8 Agent | EA3: Adjuvant Tx8 Start Date | EB3: Adjuvant Tx8 End Date | EC3: Tumour response Adjuvant Tx8 | ED3: Adjuvant Tx9 | EE3: Adjuvant Tx9 Agent | EF3: Adjuvant Tx9 Start Date | EG3: Adjuvant Tx9 End Date | EH3: Tumour response Adjuvant Tx9 | EI3: Adjuvant Tx10 | EJ3: Adjuvant Tx10 Agent | EK3: Adjuvant Tx10 Start Date | EL3: Adjuvant Tx10 End Date | EM3: Tumour response Adjuvant Tx10 | EN3: Adjuvant Tx11 | EO3: Adjuvant Tx11 Agent | EP3: Adjuvant Tx11 Start Date | EQ3: Adjuvant Tx11 End Date | ER3: Tumour response Adjuvant Tx11 | ES3: Adjuvant Tx12 | ET3: Adjuvant Tx12 Agent | EU3: Adjuvant Tx12 Start Date | EV3: Adjuvant Tx12 End Date | EW3: Tumour response Adjuvant Tx12 | EX3: Adjuvant Tx13 | EY3: Adjuvant Tx13 Agent | EZ3: Adjuvant Tx13 Start Date | FA3: Adjuvant Tx13 End Date | FB3: Tumour response Adjuvant Tx13 | FC3: Adjuvant Tx14 | FD3: Adjuvant Tx14 Agent | FE3: Adjuvant Tx14 Start Date | FF3: Adjuvant Tx14 End Date | FG3: Tumour response Adjuvant Tx14 | FH3: Adjuvant Tx15 | FI3: Adjuvant Tx15 Agent | FJ3: Adjuvant Tx15 Start Date | FK3: Adjuvant Tx15 End Date | FL3: Date recurrence/ progression 1 | FM3: Sites recurrence/ progression 1 | FN3: Date recurrence/ progression 2 | FO3: Sites recurrence/ progression 2 | FP3: Date recurrence/ progression 3 | FQ3: Sites recurrence/ progression 3 | FR3: Date recurrence/ progression 4 | FS3: Sites recurrence/ progression 4 | FT3: Date recurrence/ progression 5 | FU3: Sites recurrence/ progression 5 | FV3: Date recurrence/ progression 6 | FW3: Sites recurrence/ progression 6 | FX3: Date recurrence/ progression 7 | FY3: Sites recurrence/ progression 7 | FZ3: Date recurrence/ progression 8 | GA3: Sites recurrence/ progression 8 | GB3: Date recurrence/ progression 9 | GC3: Sites recurrence/ progression 9 | GD3: Date recurrence/ progression 10 | GE3: Sites recurrence/ progression 10 | GF3: Date recurrence/ progression 11 | GG3: Sites recurrence/ progression 11 | GH3: Date recurrence/ progression 12 | GI3: Sites recurrence/ progression 12 | GJ3: Date recurrence/ progression 13 | GK3: Sites recurrence/ progression 13 | GL3: Date recurrence/ progression 14 | GM3: Sites recurrence/ progression 14 | GN3: Date recurrence/ progression 15 | GO3: Sites recurrence/ progression 15 | GP3: Subsequent Tx1 | GQ3: Subsequent Tx1 Agent | GR3: Subsequent Tx1 Start Date | GS3: Subsequent Tx1 Finish Date | GT3: Tumour response to Subsequent Tx1 | GU3: Subsequent Tx2 | GV3: Subsequent Tx2 Agent | GW3: Subsequent Tx2 Start Date | GX3: Subsequent Tx2 Finish Date | GY3: Tumour response to Subsequent Tx2 | GZ3: Subsequent Tx3 | HA3: Subsequent Tx3 Agent | HB3: Subsequent Tx3 Start Date | HC3: Subsequent Tx3 Finish Date | HD3: Tumour response to Subsequent Tx3 | HE3: Subsequent Tx4 | HF3: Subsequent Tx4 Agent | HG3: Subsequent Tx4 Start Date | HH3: Subsequent Tx4 Finish Date | HI3: Tumour response to Subsequent Tx4 | HJ3: Subsequent Tx5 | HK3: Subsequent Tx5 Agent | HL3: Subsequent Tx5 Start Date | HM3: Subsequent Tx5 Finish Date | HN3: Tumour response to Subsequent Tx5 | HO3: Subsequent Tx6 | HP3: Subsequent Tx6 Agent | HQ3: Subsequent Tx6 Start Date | HR3: Subsequent Tx6 Finish Date | HS3: Tumour response to Subsequent Tx6 | HT3: Subsequent Tx7 | HU3: Subsequent Tx7 Agent | HV3: Subsequent Tx7 Start Date | HW3: Subsequent Tx7 Finish Date | HX3: Tumour response to Subsequent Tx7 | HY3: Subsequent Tx8 | HZ3: Subsequent Tx8 Agent | IA3: Subsequent Tx8 Start Date | IB3: Subsequent Tx8 Finish Date | IC3: Tumour response to Subsequent Tx8 | ID3: Subsequent Tx9 | IE3: Subsequent Tx9 Agent | IF3: Subsequent Tx9 Start Date | IG3: Subsequent Tx9 Finish Date | IH3: Tumour response to Subsequent Tx9 | II3: Subsequent Tx10 | IJ3: Subsequent Tx10 Agent | IK3: Subsequent Tx10 Start Date | IL3: Subsequent Tx10 Finish Date | IM3: Tumour response to Subsequent Tx10 | IN3: Subsequent Tx11 | IO3: Subsequent Tx11 Agent | IP3: Subsequent Tx11 Start Date | IQ3: Subsequent Tx11 Finish Date | IR3: Tumour response to Subsequent Tx11 | IS3: Subsequent Tx12 | IT3: Subsequent Tx12 Agent | IU3: Subsequent Tx12 Start Date | IV3: Subsequent Tx12 Finish Date | IW3: Tumour response to Subsequent Tx12 | IX3: Subsequent Tx13 | IY3: Subsequent Tx13 Agent | IZ3: Subsequent Tx13 Start Date | JA3: Subsequent Tx13 Finish Date | JB3: Tumour response to Subsequent Tx13 | JC3: Subsequent Tx14 | JD3: Subsequent Tx14 Agent | JE3: Subsequent Tx14 Start Date | JF3: Subsequent Tx14 Finish Date | JG3: Tumour response to Subsequent Tx14 | JH3: Subsequent Tx15 | JI3: Subsequent Tx15 Agent | JJ3: Subsequent Tx15 Start Date | JK3: Subsequent Tx15 Finish Date | JL3: Tumour response to Subsequent Tx15 | JM3: Current Status | JN3: Death date | JO3: Death tumour related | JP3: Cause of death | JQ3: Date last follow-up | JR3: Date Last Seen | JS3: Concurrent Medical Conditions | JT3: Comments from clinical team | JU3: TTE Neoadjuvant Tx1 Start Date | JV3: TTE Neoadjuvant Tx1 End Date | JW3: TTE Neoadjuvant Tx2 Start Date | JX3: TTE Neoadjuvant Tx2 End Date | JY3: TTE Neoadjuvant Tx3 Start Date | JZ3: TTE Neoadjuvant Tx3 End Date | KA3: TTE Neoadjuvant Tx4 Start Date | KB3: TTE Neoadjuvant Tx4 End Date | KC3: TTE Neoadjuvant Tx5 Start Date | KD3: TTE Neoadjuvant Tx5 End Date | KE3: TTE Neoadjuvant Tx6 Start Date | KF3: TTE Neoadjuvant Tx6 End Date | KG3: TTE Neoadjuvant Tx7 Start Date | KH3: TTE Neoadjuvant Tx7 End Date | KI3: TTE Neoadjuvant Tx8 Start Date | KJ3: TTE Neoadjuvant Tx8 End Date | KK3: TTE Neoadjuvant Tx9 Start Date | KL3: TTE Neoadjuvant Tx9 End Date | KM3: TTE Neoadjuvant Tx10 Start Date | KN3: TTE Neoadjuvant Tx10 End Date | KO3: TTE Specimen surgery date | KP3: TTE Primary Surgery date | KQ3: TTE Matched met 1 Surgery Date | KR3: TTE Matched met 2 Surgery Date | KS3: TTE Matched Normal tissue Surgery Date | KT3: TTE Adjuvant Tx1 Start Date | KU3: TTE Adjuvant Tx1 End Date | KV3: TTE Adjuvant Tx2 Start Date | KW3: TTE Adjuvant Tx2 End Date | KX3: TTE Adjuvant Tx3 Start Date | KY3: TTE Adjuvant Tx3 End Date | KZ3: TTE Adjuvant Tx4 Start Date | LA3: TTE Adjuvant Tx4 End Date | LB3: TTE Adjuvant Tx5 Start Date | LC3: TTE Adjuvant Tx5 End Date | LD3: TTE Adjuvant Tx6 Start Date | LE3: TTE Adjuvant Tx6 End Date | LF3: TTE Adjuvant Tx7 Start Date | LG3: TTE Adjuvant Tx7 End Date | LH3: TTE Adjuvant Tx8 Start Date | LI3: TTE Adjuvant Tx8 End Date | LJ3: TTE Adjuvant Tx9 Start Date | LK3: TTE Adjuvant Tx9 End Date | LL3: TTE Adjuvant Tx10 Start Date | LM3: TTE Adjuvant Tx10 End Date | LN3: TTE Adjuvant Tx11 Start Date | LO3: TTE Adjuvant Tx11 End Date | LP3: TTE Adjuvant Tx12 Start Date | LQ3: TTE Adjuvant Tx12 End Date | LR3: TTE Adjuvant Tx13 Start Date | LS3: TTE Adjuvant Tx13 End Date | LT3: TTE Adjuvant Tx14 Start Date | LU3: TTE Adjuvant Tx14 End Date | LV3: TTE Adjuvant Tx15 Start Date | LW3: TTE Adjuvant Tx15 End Date | LX3: TTE Date recurrence/ progression 1 | LY3: TTE Date recurrence/ progression 2 | LZ3: TTE Date recurrence/ progression 3 | MA3: TTE Date recurrence/ progression 4 | MB3: TTE Date recurrence/ progression 5 | MC3: TTE Date recurrence/ progression 6 | MD3: TTE Date recurrence/ progression 7 | ME3: TTE Date recurrence/ progression 8 | MF3: TTE Date recurrence/ progression 9 | MG3: TTE Date recurrence/ progression 10 | MH3: TTE Date recurrence/ progression 11 | MI3: TTE Date recurrence/ progression 12 | MJ3: TTE Date recurrence/ progression 13 | MK3: TTE Date recurrence/ progression 14 | ML3: TTE Date recurrence/ progression 15 | MM3: TTE Subsequent Tx1 Start Date | MN3: TTE Subsequent Tx1 Finish Date | MO3: TTE Subsequent Tx2 Start Date | MP3: TTE Subsequent Tx2 Finish Date | MQ3: TTE Subsequent Tx3 Start Date | MR3: TTE Subsequent Tx3 Finish Date | MS3: TTE Subsequent Tx4 Start Date | MT3: TTE Subsequent Tx4 Finish Date | MU3: TTE Subsequent Tx5 Start Date | MV3: TTE Subsequent Tx5 Finish Date | MW3: TTE Subsequent Tx6 Start Date | MX3: TTE Subsequent Tx6 Finish Date | MY3: TTE Subsequent Tx7 Start Date | MZ3: TTE Subsequent Tx7 Finish Date | NA3: TTE Subsequent Tx8 Start Date | NB3: TTE Subsequent Tx8 Finish Date | NC3: TTE Subsequent Tx9 Start Date | ND3: TTE Subsequent Tx9 Finish Date | NE3: TTE Subsequent Tx10 Start Date | NF3: TTE Subsequent Tx10 Finish Date | NG3: TTE Subsequent Tx11 Start Date | NH3: TTE Subsequent Tx11 Finish Date | NI3: TTE Subsequent Tx12 Start Date | NJ3: TTE Subsequent Tx12 Finish Date | NK3: TTE Subsequent Tx13 Start Date | NL3: TTE Subsequent Tx13 Finish Date | NM3: TTE Subsequent Tx14 Start Date | NN3: TTE Subsequent Tx14 Finish Date | NO3: TTE Subsequent Tx15 Start Date | NP3: TTE Subsequent Tx15 Finish Date | NQ3: TTE Recurrence (PFS) | NR3: TTE Death (OS and PFS) | NS3: TTE Date last follow-up (PFS) | NT3: TTE Date last seen (OS) | NU3: TTE Overall survival (OS) in months | NV3: TTE Progression free survival (PFS) in months | NW3: Event (recurrence/progression) | NX3: Event (cancer death) | NY3: Event (death; all causes) | NZ3: Event (recurrence or cancer death)
A4: 4520256615 | B4: No | C4: Treatment naïve | D4: No | E4: LH17-02702 | F4: A1 | G4: A12 | H4: 42753 | I4: Total abdominal hysterectomy | J4: Endometrium | K4: N/A | L4: N/A | M4: N/A | N4: N/A | O4: N/A | P4: N/A | Q4: N/A | R4: N/A | S4: N/A | T4: N/A | U4: N/A | V4: N/A | W4: N/A | X4: N/A | Y4: N/A | Z4: N/A | AA4: N/A | AB4: F | AC4: 18552 | AD4: 42746 | AE4: =DATEDIF(AC4, AD4,"Y") -> 66 | AF4: Carcinosarcoma with heterologous differentiation | AG4: Specimen | AH4: Yes | AI4: 2 | AJ4: 1 | AK4: 0 | AL4: 0 | AM4: T2N1M0 | AN4: NR | AO4: N/A | AP4: No | JS4: hypertension, hypercholesteremia, asthma, ulcerative colitis and hypothyroidism | JU4: =IFERROR((YEARFRAC($AD4,$AT4)*12),"N/A") -> 1404.3667 | JV4: =IFERROR((YEARFRAC($AD4,$AU4)*12),"N/A") -> 1404.3667 | JW4: =IFERROR((YEARFRAC($AD4,$AY4)*12),"N/A") -> 1404.3667 | JX4: =IFERROR((YEARFRAC($AD4,$AZ4)*12),"N/A") -> 1404.3667 | JY4: =IFERROR((YEARFRAC($AD4,$BD4)*12),"N/A") -> 1404.3667 | JZ4: =IFERROR((YEARFRAC($AD4,$BE4)*12),"N/A") -> 1404.3667 | KA4: =IFERROR((YEARFRAC($AD4,$BI4)*12),"N/A") -> 1404.3667 | KB4: =IFERROR((YEARFRAC($AD4,$BJ4)*12),"N/A") -> 1404.3667 | KC4: =IFERROR((YEARFRAC($AD4,$BN4)*12),"N/A") -> 1404.3667 | KD4: =IFERROR((YEARFRAC($AD4,$BO4)*12),"N/A") -> 1404.3667 | KE4: =IFERROR((YEARFRAC($AD4,$BS4)*12),"N/A") -> 1404.3667 | KF4: =IFERROR((YEARFRAC($AD4,$BT4)*12),"N/A") -> 1404.3667 | KG4: =IFERROR((YEARFRAC($AD4,$BX4)*12),"N/A") -> 1404.3667 | KH4: =IFERROR((YEARFRAC($AD4,$BY4)*12),"N/A") -> N/A | KI4: =IFERROR((YEARFRAC($AD4,$CC4)*12),"N/A") -> 1404.3667 | KJ4: =IFERROR((YEARFRAC($AD4,$CD4)*12),"N/A") -> 1404.3667 | KK4: =IFERROR((YEARFRAC($AD4,$CH4)*12),"N/A") -> 1404.3667 | KL4: =IFERROR((YEARFRAC($AD4,$CI4)*12),"N/A") -> 1404.3667 | KM4: =IFERROR((YEARFRAC($AD4,$CM4)*12),"N/A") -> 1404.3667 | KN4: =IFERROR((YEARFRAC($AD4,$CN4)*12),"N/A") -> 1404.3667 | KO4: =IFERROR((YEARFRAC($AD4,$H4)*12),"N/A") -> 0.23333333 | KP4: =IFERROR((YEARFRAC($AD4,$K4)*12),"N/A") -> N/A | KQ4: =IFERROR((YEARFRAC($AD4,$P4)*12),"N/A") -> N/A | KR4: =IFERROR((YEARFRAC($AD4,$U4)*12),"N/A") -> N/A | KS4: =IFERROR((YEARFRAC($AD4,$Z4)*12),"N/A") -> N/A | KT4: =IFERROR((YEARFRAC($AD4,$CR4)*12),"N/A") -> 1404.3667 | KU4: =IFERROR((YEARFRAC($AD4,$CS4)*12),"N/A") -> 1404.3667 | KV4: =IFERROR((YEARFRAC($AD4,$CW4)*12),"N/A") -> 1404.3667 | KW4: =IFERROR((YEARFRAC($AD4,$CX4)*12),"N/A") -> 1404.3667 | KX4: =IFERROR((YEARFRAC($AD4,$DB4)*12),"N/A") -> 1404.3667 | KY4: =IFERROR((YEARFRAC($AD4,$DC4)*12),"N/A") -> 1404.3667 | KZ4: =IFERROR((YEARFRAC($AD4,$DG4)*12),"N/A") -> 1404.3667 | LA4: =IFERROR((YEARFRAC($AD4,$DH4)*12),"N/A") -> 1404.3667 | LB4: =IFERROR((YEARFRAC($AD4,$DL4)*12),"N/A") -> 1404.3667 | LC4: =IFERROR((YEARFRAC($AD4,$DM4)*12),"N/A") -> 1404.3667 | LD4: =IFERROR((YEARFRAC($AD4,$DQ4)*12),"N/A") -> 1404.3667 | LE4: =IFERROR((YEARFRAC($AD4,$DR4)*12),"N/A") -> 1404.3667 | LF4: =IFERROR((YEARFRAC($AD4,$DV4)*12),"N/A") -> 1404.3667 | LG4: =IFERROR((YEARFRAC($AD4,$DW4)*12),"N/A") -> 1404.3667 | LH4: =IFERROR((YEARFRAC($AD4,$EA4)*12),"N/A") -> 1404.3667 | LI4: =IFERROR((YEARFRAC($AD4,$EB4)*12),"N/A") -> 1404.3667 | LJ4: =IFERROR((YEARFRAC($AD4,$EF4)*12),"N/A") -> 1404.3667 | LK4: =IFERROR((YEARFRAC($AD4,$EG4)*12),"N/A") -> 1404.3667 | LL4: =IFERROR((YEARFRAC($AD4,$EK4)*12),"N/A") -> 1404.3667 | LM4: =IFERROR((YEARFRAC($AD4,$EL4)*12),"N/A") -> 1404.3667 | LN4: =IFERROR((YEARFRAC($AD4,$EP4)*12),"N/A") -> 1404.3667 | LO4: =IFERROR((YEARFRAC($AD4,$EQ4)*12),"N/A") -> 1404.3667 | LP4: =IFERROR((YEARFRAC($AD4,$EU4)*12),"N/A") -> 1404.3667 | LQ4: =IFERROR((YEARFRAC($AD4,$EV4)*12),"N/A") -> 1404.3667 | LR4: =IFERROR((YEARFRAC($AD4,$EZ4)*12),"N/A") -> 1404.3667 | LS4: =IFERROR((YEARFRAC($AD4,$FA4)*12),"N/A") -> 1404.3667 | LT4: =IFERROR((YEARFRAC($AD4,$EE4)*12),"N/A") -> 1404.3667 | LU4: =IFERROR((YEARFRAC($AD4,$EF4)*12),"N/A") -> 1404.3667 | LV4: =IFERROR((YEARFRAC($AD4,$FJ4)*12),"N/A") -> 1404.3667 | LW4: =IFERROR((YEARFRAC($AD4,$FK4)*12),"N/A") -> 1404.3667 | LX4: =IFERROR((YEARFRAC($AD4,$FL4)*12),"N/A") -> 1404.3667 | LY4: =IFERROR((YEARFRAC($AD4,$FN4)*12),"N/A") -> 1404.3667 | LZ4: =IFERROR((YEARFRAC($AD4,$FP4)*12),"N/A") -> 1404.3667 | MA4: =IFERROR((YEARFRAC($AD4,$FR4)*12),"N/A") -> 1404.3667 | MB4: =IFERROR((YEARFRAC($AD4,$FT4)*12),"N/A") -> 1404.3667 | MC4: =IFERROR((YEARFRAC($AD4,$FV4)*12),"N/A") -> 1404.3667 | MD4: =IFERROR((YEARFRAC($AD4,$FX4)*12),"N/A") -> 1404.3667 | ME4: =IFERROR((YEARFRAC($AD4,$FZ4)*12),"N/A") -> 1404.3667 | MF4: =IFERROR((YEARFRAC($AD4,$GB4)*12),"N/A") -> 1404.3667 | MG4: =IFERROR((YEARFRAC($AD4,$GD4)*12),"N/A") -> 1404.3667 | MH4: =IFERROR((YEARFRAC($AD4,$GF4)*12),"N/A") -> 1404.3667 | MI4: =IFERROR((YEARFRAC($AD4,$GH4)*12),"N/A") -> 1404.3667 | MJ4: =IFERROR((YEARFRAC($AD4,$GJ4)*12),"N/A") -> 1404.3667 | MK4: =IFERROR((YEARFRAC($AD4,$GL4)*12),"N/A") -> 1404.3667 | ML4: =IFERROR((YEARFRAC($AD4,$GN4)*12),"N/A") -> 1404.3667 | MM4: =IFERROR((YEARFRAC($AD4,$GR4)*12),"N/A") -> 1404.3667 | MN4: =IFERROR((YEARFRAC($AD4,$GS4)*12),"N/A") -> 1404.3667 | MO4: =IFERROR((YEARFRAC($AD4,$GW4)*12),"N/A") -> 1404.3667 | MP4: =IFERROR((YEARFRAC($AD4,$GX4)*12),"N/A") -> 1404.3667 | MQ4: =IFERROR((YEARFRAC($AD4,$HB4)*12),"N/A") -> 1404.3667 | MR4: =IFERROR((YEARFRAC($AD4,$HC4)*12),"N/A") -> 1404.3667 | MS4: =IFERROR((YEARFRAC($AD4,$HG4)*12),"N/A") -> 1404.3667 | MT4: =IFERROR((YEARFRAC($AD4,$HH4)*12),"N/A") -> 1404.3667 | MU4: =IFERROR((YEARFRAC($AD4,$HL4)*12),"N/A") -> 1404.3667 | MV4: =IFERROR((YEARFRAC($AD4,$HM4)*12),"N/A") -> 1404.3667 | MW4: =IFERROR((YEARFRAC($AD4,$HQ4)*12),"N/A") -> 1404.3667 | MX4: =IFERROR((YEARFRAC($AD4,$HR4)*12),"N/A") -> 1404.3667 | MY4: =IFERROR((YEARFRAC($AD4,$HV4)*12),"N/A") -> 1404.3667 | MZ4: =IFERROR((YEARFRAC($AD4,$HW4)*12),"N/A") -> 1404.3667 | NA4: =IFERROR((YEARFRAC($AD4,$IA4)*12),"N/A") -> 1404.3667 | NB4: =IFERROR((YEARFRAC($AD4,$IB4)*12),"N/A") -> 1404.3667 | NC4: =IFERROR((YEARFRAC($AD4,$IF4)*12),"N/A") -> 1404.3667 | ND4: =IFERROR((YEARFRAC($AD4,$IG4)*12),"N/A") -> 1404.3667 | NE4: =IFERROR((YEARFRAC($AD4,$IK4)*12),"N/A") -> 1404.3667 | NF4: =IFERROR((YEARFRAC($AD4,$IL4)*12),"N/A") -> 1404.3667 | NG4: =IFERROR((YEARFRAC($AD4,$IP4)*12),"N/A") -> 1404.3667 | NH4: =IFERROR((YEARFRAC($AD4,$IQ4)*12),"N/A") -> 1404.3667 | NI4: =IFERROR((YEARFRAC($AD4,$IU4)*12),"N/A") -> 1404.3667 | NJ4: =IFERROR((YEARFRAC($AD4,$IV4)*12),"N/A") -> 1404.3667 | NK4: =IFERROR((YEARFRAC($AD4,$IZ4)*12),"N/A") -> 1404.3667 | NL4: =IFERROR((YEARFRAC($AD4,$JA4)*12),"N/A") -> 1404.3667 | NM4: =IFERROR((YEARFRAC($AD4,$JE4)*12),"N/A") -> 1404.3667 | NN4: =IFERROR((YEARFRAC($AD4,$JF4)*12),"N/A") -> 1404.3667 | NO4: =IFERROR((YEARFRAC($AD4,$JJ4)*12),"N/A") -> 1404.3667 | NP4: =IFERROR((YEARFRAC($AD4,$JK4)*12),"N/A") -> 1404.3667 | NQ4: =$LX4 -> 1404.3667 | NR4: =IFERROR((YEARFRAC($AD4,$JN4)*12),"N/A") -> 1404.3667 | NS4: =IFERROR((YEARFRAC($AD4,$JQ4)*12),"N/A") -> 1404.3667 | NT4: =IFERROR((YEARFRAC($AD4,$JR4)*12),"N/A") -> 1404.3667 | NU4: =SUM($NR4,$NT4) -> 2808.7333 | NV4: {=INDEX($NQ4:$NS4,MATCH(TRUE,INDEX(ISNUMBER($NQ4:$NS4),0),0))} -> 1404.3667 | NW4: =IF($NQ4="N/A",0,1) -> 1 | NX4: =IF($JO4="Yes",1,0) -> 0 | NY4: =IF($NR4="N/A",0,1) -> 1 | NZ4: =IF(OR($NW4=1,$NX4=1),"1","0") -> 1
A5: 4250445798 | B5: No | C5: Treatment naïve | D5: No | E5: LH17-06069 | F5: A11 | G5: A12 | H5: 42774 | I5: Total abdominal hysterectomy | J5: Endometrium | K5: N/A | L5: N/A | M5: N/A | N5: N/A | O5: N/A | P5: N/A | Q5: N/A | R5: N/A | S5: N/A | T5: N/A | U5: N/A | V5: N/A | W5: LH17-06069 | X5: B3 | Y5: Lymph node | Z5: 42774 | AA5: N/A | AB5: F | AC5: 16856 | AD5: 42773 | AE5: =DATEDIF(AC5, AD5,"Y") -> 70 | AF5: Endometrioid adenocarcinoma | AG5: Specimen | AH5: Yes | AI5: 1b | AJ5: 0 | AK5: x | AL5: 0 | AM5: T1BN0M0 | AN5: 1 | AO5: N/A
A6: 4946723307 | D6: No | E6: LH17-07381 | F6: A9 | G6: A8 | H6: 42783 | I6: Total abdominal hysterectomy | J6: Endometrium | K6: N/A | L6: N/A | M6: N/A | N6: N/A | O6: N/A | P6: N/A | Q6: N/A | R6: N/A | S6: N/A | T6: N/A | U6: N/A | V6: N/A | W6: LH17-07381 | X6: C1 | Y6: Lymph node | Z6: 42783 | AB6: F | AC6: 15135 | AE6: =DATEDIF(AC6, AD6,"Y") -> #NUM! | AF6: Deeply invasive mixed adenocarcinoma (serous and endometroiod) | AG6: Specimen | AH6: Yes | AI6: 1b | AJ6: 0 | AK6: 0 | AL6: 0 | AM6: T1BN0M0 | AN6: 3 | AO6: N/A
A7: 4362503161 | D7: No | E7: LH17-10008 | F7: A4 | G7: A6 | H7: 42801 | I7: Total abdominal hysterectomy | J7: Endometrium | K7: N/A | L7: N/A | M7: N/A | N7: N/A | O7: N/A | P7: N/A | Q7: N/A | R7: N/A | S7: N/A | T7: N/A | U7: N/A | V7: N/A | W7: N/A | X7: N/A | Y7: N/A | Z7: N/A | AB7: F | AC7: 9597 | AE7: =DATEDIF(AC7, AD7,"Y") -> #NUM! | AF7: High grade serous adenocarcinoma | AG7: Specimen | AH7: Yes | AI7: 2 | AJ7: 0 | AK7: 0 | AL7: 0 | AM7: T2N0M0 | AN7: 3 | AO7: N/A
A8: 4363753323 | D8: No | E8: LH17-10854 | F8: A6 | G8: A10 | H8: 42807 | I8: Total abdominal hysterectomy | J8: Endometrium | K8: N/A | L8: N/A | M8: N/A | N8: N/A | O8: N/A | P8: N/A | Q8: N/A | R8: N/A | S8: N/A | T8: N/A | U8: N/A | V8: N/A | W8: N/A | X8: N/A | Y8: N/A | Z8: N/A | AB8: F | AC8: 12131 | AE8: =DATEDIF(AC8, AD8,"Y") -> #NUM! | AF8: Malignant mixed mullerian tumour with rhabdomyoblastic differentiation | AG8: Specimen | AH8: Yes | AI8: 3b | AJ8: 1 | AK8: 0 | AL8: 0 | AM8: T3BN1M0 | AN8: 3 | AO8: N/A
A9: 4662799619 | B9: N/A | C9: N/A | D9: N/A | E9: N/A | F9: N/A | G9: N/A | H9: N/A | I9: N/A | J9: N/A | K9: N/A | L9: N/A | M9: N/A | N9: N/A | O9: N/A | P9: N/A | Q9: N/A | R9: N/A | S9: N/A | T9: N/A | U9: N/A | V9: N/A | W9: LH17-11002 | X9: B5 | Y9: Pelvic node | Z9: 42808 | AB9: F | AC9: 12867 | AE9: =DATEDIF(AC9, AD9,"Y") -> #NUM! | AF9: N/A | AG9: N/A | AH9: N/A | AI9: N/A | AJ9: N/A | AK9: N/A | AL9: N/A | AM9: N/A | AN9: N/A | AO9: N/A | AP9: N/A | AQ9: N/A | AR9: N/A | AS9: N/A | AT9: N/A | AU9: N/A | AV9: N/A | AW9: N/A | AX9: N/A | AY9: N/A | AZ9: N/A | BA9: N/A | BB9: N/A | BC9: N/A | BD9: N/A | BE9: N/A | BF9: N/A | BG9: N/A | BH9: N/A | BI9: N/A | BJ9: N/A | BK9: N/A | BL9: N/A | BM9: N/A | BN9: N/A | BO9: N/A | BP9: N/A | BQ9: N/A | BR9: N/A | BS9: N/A | BT9: N/A | BU9: N/A | BV9: N/A | BW9: N/A | BX9: N/A | BY9: N/A | BZ9: N/A | CA9: N/A | CB9: N/A | CC9: N/A | CD9: N/A | CE9: N/A | CF9: N/A | CG9: N/A | CH9: N/A | CI9: N/A | CJ9: N/A | CK9: N/A | CL9: N/A | CM9: N/A | CN9: N/A | CO9: N/A | CP9: N/A | CQ9: N/A | CR9: N/A | CS9: N/A | CT9: N/A | CU9: N/A | CV9: N/A | CW9: N/A | CX9: N/A | CY9: N/A | CZ9: N/A | DA9: N/A | DB9: N/A | DC9: N/A | DD9: N/A | DE9: N/A | DF9: N/A | DG9: N/A | DH9: N/A | DI9: N/A | DJ9: N/A | DK9: N/A | DL9: N/A | DM9: N/A | DN9: N/A | DO9: N/A | DP9: N/A | DQ9: N/A | DR9: N/A | DS9: N/A | DT9: N/A | DU9: N/A | DV9: N/A | DW9: N/A | DX9: N/A | DY9: N/A | DZ9: N/A | EA9: N/A | EB9: N/A | EC9: N/A | ED9: N/A | EE9: N/A | EF9: N/A | EG9: N/A | EH9: N/A | EI9: N/A | EJ9: N/A | EK9: N/A | EL9: N/A | EM9: N/A | EN9: N/A | EO9: N/A | EP9: N/A | EQ9: N/A | ER9: N/A | ES9: N/A | ET9: N/A | EU9: N/A | EV9: N/A | EW9: N/A | EX9: N/A | EY9: N/A | EZ9: N/A | FA9: N/A | FB9: N/A | FC9: N/A | FD9: N/A | FE9: N/A | FF9: N/A | FG9: N/A | FH9: N/A | FI9: N/A | FJ9: N/A | FK9: N/A | FL9: N/A | FM9: N/A | FN9: N/A | FO9: N/A | FP9: N/A | FQ9: N/A | FR9: N/A | FS9: N/A | FT9: N/A | FU9: N/A | FV9: N/A | FW9: N/A | FX9: N/A | FY9: N/A | FZ9: N/A | GA9: N/A | GB9: N/A | GC9: N/A | GD9: N/A | GE9: N/A | GF9: N/A | GG9: N/A | GH9: N/A | GI9: N/A | GJ9: N/A | GK9: N/A | GL9: N/A | GM9: N/A | GN9: N/A | GO9: N/A | GP9: N/A | GQ9: N/A | GR9: N/A | GS9: N/A | GT9: N/A | GU9: N/A | GV9: N/A | GW9: N/A | GX9: N/A | GY9: N/A | GZ9: N/A | HA9: N/A | HB9: N/A | HC9: N/A | HD9: N/A | HE9: N/A | HF9: N/A | HG9: N/A | HH9: N/A | HI9: N/A | HJ9: N/A | HK9: N/A | HL9: N/A | HM9: N/A | HN9: N/A | HO9: N/A | HP9: N/A | HQ9: N/A | HR9: N/A | HS9: N/A | HT9: N/A | HU9: N/A | HV9: N/A | HW9: N/A | HX9: N/A | HY9: N/A | HZ9: N/A | IA9: N/A | IB9: N/A | IC9: N/A | ID9: N/A | IE9: N/A | IF9: N/A | IG9: N/A | IH9: N/A | II9: N/A | IJ9: N/A | IK9: N/A | IL9: N/A | IM9: N/A | IN9: N/A | IO9: N/A | IP9: N/A | IQ9: N/A | IR9: N/A | IS9: N/A | IT9: N/A | IU9: N/A | IV9: N/A | IW9: N/A | IX9: N/A | IY9: N/A | IZ9: N/A | JA9: N/A | JB9: N/A | JC9: N/A | JD9: N/A | JE9: N/A | JF9: N/A | JG9: N/A | JH9: N/A | JI9: N/A | JJ9: N/A | JK9: N/A | JL9: N/A | JM9: N/A | JN9: N/A | JO9: N/A | JP9: N/A | JQ9: N/A | JR9: N/A | JS9: N/A | JT9: N/A | JU9: N/A | JV9: N/A | JW9: N/A | JX9: N/A | JY9: N/A | JZ9: N/A | KA9: N/A | KB9: N/A | KC9: N/A | KD9: N/A | KE9: N/A | KF9: N/A | KG9: N/A | KH9: N/A | KI9: N/A | KJ9: N/A | KK9: N/A | KL9: N/A | KM9: N/A | KN9: N/A | KO9: N/A | KP9: N/A | KQ9: N/A | KR9: N/A | KS9: N/A | KT9: N/A | KU9: N/A | KV9: N/A | KW9: N/A | KX9: N/A | KY9: N/A | KZ9: N/A | LA9: N/A | LB9: N/A | LC9: N/A | LD9: N/A | LE9: N/A | LF9: N/A | LG9: N/A | LH9: N/A | LI9: N/A | LJ9: N/A | LK9: N/A | LL9: N/A | LM9: N/A | LN9: N/A | LO9: N/A | LP9: N/A | LQ9: N/A | LR9: N/A | LS9: N/A | LT9: N/A | LU9: N/A | LV9: N/A | LW9: N/A | LX9: N/A | LY9: N/A | LZ9: N/A | MA9: N/A | MB9: N/A | MC9: N/A | MD9: N/A | ME9: N/A | MF9: N/A | MG9: N/A | MH9: N/A | MI9: N/A | MJ9: N/A | MK9: N/A | ML9: N/A | MM9: N/A | MN9: N/A | MO9: N/A | MP9: N/A | MQ9: N/A | MR9: N/A | MS9: N/A | MT9: N/A | MU9: N/A | MV9: N/A | MW9: N/A | MX9: N/A | MY9: N/A | MZ9: N/A | NA9: N/A | NB9: N/A | NC9: N/A | ND9: N/A | NE9: N/A | NF9: N/A | NG9: N/A | NH9: N/A | NI9: N/A | NJ9: N/A | NK9: N/A | NL9: N/A | NM9: N/A | NN9: N/A | NO9: N/A | NP9: N/A | NQ9: N/A | NR9: N/A | NS9: N/A | NT9: N/A | NU9: N/A | NV9: N/A | NW9: N/A | NX9: N/A | NY9: N/A | NZ9: N/A
A10: 4367569659 | D10: No | E10: LH17-11093 | F10: A6 | G10: A8 | H10: 42808 | I10: Total laparoscopic Hysterectomy | J10: Endometrium | K10: N/A | L10: N/A | M10: N/A | N10: N/A | O10: N/A | P10: N/A | Q10: N/A | R10: N/A | S10: N/A | T10: N/A | U10: N/A | V10: N/A | W10: LH17-11093 | X10: D1 | Y10: Lymph node | Z10: 42808 | AB10: F | AC10: 12927 | AE10: =DATEDIF(AC10, AD10,"Y") -> #NUM! | AF10: Endometrioid adenocarcinoma | AG10: Specimen | AH10: Yes | AI10: 1b | AJ10: 0 | AK10: 0 | AL10: 0 | AM10: T1BN0M0 | AN10: 3 | AO10: N/A
A11: 4581564212 | D11: No | E11: LH17-11306 | F11: A8 | G11: A3 | H11: 42809 | I11: Total abdominal hysterectomy | J11: Endometrium | K11: N/A | L11: N/A | M11: N/A | N11: N/A | O11: N/A | P11: N/A | Q11: N/A | R11: N/A | S11: N/A | T11: N/A | U11: N/A | V11: N/A | W11: N/A | X11: N/A | Y11: N/A | Z11: N/A | AB11: F | AC11: 19418 | AE11: =DATEDIF(AC11, AD11,"Y") -> #NUM! | AF11: High grade carcinosarcoma of homologous type | AG11: Specimen | AH11: Yes | AI11: 2 | AJ11: 0 | AK11: 0 | AL11: 0 | AM11: T2N0M0 | AN11: 3 | AO11: N/A
A12: 4706490731 | D12: No | E12: LH17-12612 | F12: A10 | G12: A4 | H12: 42817 | I12: Total abdominal hysterectomy | J12: Endometrium | K12: N/A | L12: N/A | M12: N/A | N12: N/A | O12: N/A | P12: N/A | Q12: N/A | R12: N/A | S12: N/A | T12: N/A | U12: N/A | V12: N/A | W12: LH17-12612 | X12: C1 | Y12: Pelvic node | Z12: 42817 | AB12: F | AC12: 17832 | AE12: =DATEDIF(AC12, AD12,"Y") -> #NUM! | AF12: Endometrioid adenocarcinoma | AG12: Specimen | AH12: Yes | AI12: 2 | AJ12: 0 | AK12: 0 | AL12: 0 | AM12: T2N0M0 | AN12: 1 | AO12: N/A
A13: 4366490994 | D13: No | E13: LH17-13646 | F13: A20 | G13: A21 | H13: 42824 | I13: Total abdominal hysterectomy | J13: Endometrium | K13: N/A | L13: N/A | M13: N/A | N13: N/A | O13: N/A | P13: N/A | Q13: N/A | R13: N/A | S13: N/A | T13: N/A | U13: N/A | V13: N/A | W13: N/A | X13: N/A | Y13: N/A | Z13: N/A | AB13: F | AC13: 11938 | AE13: =DATEDIF(AC13, AD13,"Y") -> #NUM! | AF13: High-grade serous adenocarcinoma of the endometrium | AG13: Specimen | AH13: N/A | AI13: N/R | AJ13: N/R | AK13: 1 (Omentum) | AL13: 1 (Lung and lymph node) | AM13: N/A | AN13: 3 | AO13: N/A
A14: 4508221386 | D14: No | E14: LH17-15131 | F14: A15 | G14: A12 | H14: 42835 | I14: Total abdominal hysterectomy | J14: Endometrium | K14: N/A | L14: N/A | M14: N/A | N14: N/A | O14: N/A | P14: N/A | Q14: N/A | R14: N/A | S14: N/A | T14: N/A | U14: N/A | V14: N/A | W14: LH17-15131 | X14: G2 | Y14: Lymph node | Z14: 42835 | AB14: F | AC14: 17315 | AE14: =DATEDIF(AC14, AD14,"Y") -> #NUM! | AF14: Mixed high grade endometrioid and serous adenocarcinoma | AG14: Specimen | AH14: Yes | AI14: 1b | AJ14: 0 | AK14: 0 | AL14: 0 | AM14: T1BN0M0 | AN14: 3 | AO14: N/A
A15: 4905526434 | D15: No | E15: LH17-16034 | F15: A9 | G15: A15 | H15: 42843 | I15: Total abdominal hysterectomy | J15: Endometrium | K15: N/A | L15: N/A | M15: N/A | N15: N/A | O15: N/A | P15: N/A | Q15: N/A | R15: N/A | S15: N/A | T15: N/A | U15: N/A | V15: N/A | W15: N/A | X15: N/A | Y15: N/A | Z15: N/A | AB15: F | AC15: 17188 | AE15: =DATEDIF(AC15, AD15,"Y") -> #NUM! | AF15: Papillary serous carcinoma | AG15: Specimen | AH15: Yes | AI15: 1b | AJ15: 0 | AK15: 0 | AL15: 0 | AM15: T1BN0M0 | AN15: 3 | AO15: N/A
A16: 4663105459 | D16: No | E16: LH17-16275 | F16: A6 | G16: A15 | H16: 42844 | I16: Total abdominal hysterectomy | J16: Endometrium | K16: N/A | L16: N/A | M16: N/A | N16: N/A | O16: N/A | P16: N/A | Q16: N/A | R16: N/A | S16: N/A | T16: N/A | U16: N/A | V16: N/A | W16: N/A | X16: N/A | Y16: N/A | Z16: N/A | AB16: F | AC16: 14460 | AE16: =DATEDIF(AC16, AD16,"Y") -> #NUM! | AF16: Adenocarcinoma. Mixed clear cell/endometriod | AG16: Specimen | AH16: Yes | AI16: 1a | AJ16: 0 | AK16: 0 | AL16: 0 | AM16: T1AN0M0 | AN16: N/R | AO16: N/A
A17: 4389042653 | D17: No | E17: LH17-20256 | F17: 8 | G17: 10 | H17: 42870 | I17: Total laparoscopic hysterectomy | J17: Endometrium | K17: N/A | L17: N/A | M17: N/A | N17: N/A | O17: N/A | P17: N/A | Q17: N/A | R17: N/A | S17: N/A | T17: N/A | U17: N/A | V17: N/A | W17: N/A | X17: N/A | Y17: N/A | Z17: N/A | AB17: F | AC17: 13661 | AE17: =DATEDIF(AC17, AD17,"Y") -> #NUM! | AF17: Endometrioid adenocarcinoma | AG17: Specimen | AH17: Yes | AI17: 1b | AJ17: 0 | AK17: 0 | AL17: 0 | AM17: T1BN0M0 | AN17: 1 | AO17: N/A
A18: 6100474530 | D18: No | E18: LH17-22802 | F18: 3 | G18: 5 | H18: 42886 | I18: Total laparoscopic hysterectomy | J18: Endometrium | K18: N/A | L18: N/A | M18: N/A | N18: N/A | O18: N/A | P18: N/A | Q18: N/A | R18: N/A | S18: N/A | T18: N/A | U18: N/A | V18: N/A | W18: N/A | X18: N/A | Y18: N/A | Z18: N/A | AB18: F | AC18: 13548 | AE18: =DATEDIF(AC18, AD18,"Y") -> #NUM! | AF18: Endometrioid adenocarcinoma | AG18: Specimen | AH18: Yes | AI18: 1b | AJ18: 0 | AK18: 0 | AL18: 0 | AM18: T1BN0M0 | AN18: 1 | AO18: N/A
A19: 4426025737 | D19: No | E19: LH17-25751 | F19: A16 | G19: A33 | H19: 42905 | I19: Total abdominal hysterectomy | J19: Endometrium | K19: N/A | L19: N/A | M19: N/A | N19: N/A | O19: N/A | P19: N/A | Q19: N/A | R19: N/A | S19: N/A | T19: N/A | U19: N/A | V19: N/A | W19: LH17-25751 | X19: C3 | Y19: Pelvic node | Z19: 42905 | AB19: F | AC19: 16269 | AE19: =DATEDIF(AC19, AD19,"Y") -> #NUM! | AF19: Endometrioid adenocarcinoma | AG19: Specimen | AH19: Yes | AI19: 1a | AJ19: 0 | AK19: 0 | AL19: 0 | AM19: T1AN0M0 | AN19: 2 | AO19: N/A
A20: 6189690610 | D20: No | E20: LH17-28006 | F20: A11 | G20: A13 | H20: 42919 | I20: Total laparoscopic hysterectomy/Bilateral salpingo-oophorectomy | J20: Endometrium | K20: N/A | L20: N/A | M20: N/A | N20: N/A | O20: N/A | P20: N/A | Q20: N/A | R20: N/A | S20: N/A | T20: N/A | U20: N/A | V20: N/A | W20: N/A | X20: N/A | Y20: N/A | Z20: N/A | AB20: F | AC20: 10969 | AE20: =DATEDIF(AC20, AD20,"Y") -> #NUM! | AF20: Serous adenocarcinoma | AG20: Specimen | AH20: Yes | AI20: 1b | AJ20: 0 | AK20: 0 | AL20: 0 | AM20: T1BN0M0 | AN20: 3 | AO20: N/A
A21: 4740277069 | D21: No | E21: LH17-28649 | F21: A6 | G21: A11 | H21: 42922 | I21: Total laparoscopic hysterectomy/Bilateral salpingo-oophorectomy | J21: Endometrium | K21: N/A | L21: N/A | M21: N/A | N21: N/A | O21: N/A | P21: N/A | Q21: N/A | R21: N/A | S21: N/A | T21: N/A | U21: N/A | V21: N/A | W21: N/A | X21: N/A | Y21: N/A | Z21: N/A | AB21: F | AC21: 16888 | AE21: =DATEDIF(AC21, AD21,"Y") -> #NUM! | AF21: Endometrioid adenocarcinoma | AG21: Specimen | AH21: N/R | AI21: 1b | AJ21: 0 | AK21: 0 | AL21: 0 | AM21: T1BN0M0 | AN21: 1 | AO21: N/A
A22: 4100098251 | D22: No | E22: LH17-29718 | F22: 15 | G22: 6 | H22: 42929 | I22: Total laparoscopic hysterectomy/Bilateral salpingo-oophorectomy | J22: Endometrium | K22: N/A | L22: N/A | M22: N/A | N22: N/A | O22: N/A | P22: N/A | Q22: N/A | R22: N/A | S22: N/A | T22: N/A | U22: N/A | V22: N/A | W22: N/A | X22: N/A | Y22: N/A | Z22: N/A | AB22: F | AC22: 15527 | AE22: =DATEDIF(AC22, AD22,"Y") -> #NUM! | AF22: Endometrioid adenocarcinoma | AG22: Specimen | AH22: N/R | AI22: 1a | AJ22: 0 | AK22: 0 | AL22: 0 | AM22: T1AN0M0 | AN22: 1 | AO22: N/A
A23: 4860460391 | D23: No | E23: LH17-30635 | F23: A13 | G23: A14 | H23: 42935 | I23: Total laparoscopic hysterectomy | J23: Endometrium | K23: N/A | L23: N/A | M23: N/A | N23: N/A | O23: N/A | P23: N/A | Q23: N/A | R23: N/A | S23: N/A | T23: N/A | U23: N/A | V23: N/A | W23: LH17-30635 | X23: D3 | Y23: Pelvic node | Z23: 42935 | AB23: F | AC23: 21181 | AE23: =DATEDIF(AC23, AD23,"Y") -> #NUM! | AF23: Endometrioid adenocarcinoma | AG23: Specimen | AH23: Yes | AI23: 1b | AJ23: 0 | AK23: 0 | AL23: 0 | AM23: T1BN0M0 | AN23: 3 | AO23: N/A
A24: 4424137554 | B24: N/A | C24: N/A | D24: N/A | E24: N/A | F24: N/A | G24: N/A | H24: N/A | I24: N/A | J24: N/A | K24: N/A | L24: N/A | M24: N/A | N24: N/A | O24: N/A | P24: N/A | Q24: N/A | R24: N/A | S24: N/A | T24: N/A | U24: N/A | V24: N/A | W24: LH17-30829 | X24: D4 | Y24: Pelvic node | Z24: 42936 | AB24: F | AC24: 15088 | AE24: =DATEDIF(AC24, AD24,"Y") -> #NUM! | AF24: N/A | AG24: N/A | AH24: N/A | AI24: N/A | AJ24: N/A | AK24: N/A | AL24: N/A | AM24: N/A | AN24: N/A | AO24: N/A | AP24: N/A | AQ24: N/A | AR24: N/A | AS24: N/A | AT24: N/A | AU24: N/A | AV24: N/A | AW24: N/A | AX24: N/A | AY24: N/A | AZ24: N/A | BA24: N/A | BB24: N/A | BC24: N/A | BD24: N/A | BE24: N/A | BF24: N/A | BG24: N/A | BH24: N/A | BI24: N/A | BJ24: N/A | BK24: N/A | BL24: N/A | BM24: N/A | BN24: N/A | BO24: N/A | BP24: N/A | BQ24: N/A | BR24: N/A | BS24: N/A | BT24: N/A | BU24: N/A | BV24: N/A | BW24: N/A | BX24: N/A | BY24: N/A | BZ24: N/A | CA24: N/A | CB24: N/A | CC24: N/A | CD24: N/A | CE24: N/A | CF24: N/A | CG24: N/A | CH24: N/A | CI24: N/A | CJ24: N/A | CK24: N/A | CL24: N/A | CM24: N/A | CN24: N/A | CO24: N/A | CP24: N/A | CQ24: N/A | CR24: N/A | CS24: N/A | CT24: N/A | CU24: N/A | CV24: N/A | CW24: N/A | CX24: N/A | CY24: N/A | CZ24: N/A | DA24: N/A | DB24: N/A | DC24: N/A | DD24: N/A | DE24: N/A | DF24: N/A | DG24: N/A | DH24: N/A | DI24: N/A | DJ24: N/A | DK24: N/A | DL24: N/A | DM24: N/A | DN24: N/A | DO24: N/A | DP24: N/A | DQ24: N/A | DR24: N/A | DS24: N/A | DT24: N/A | DU24: N/A | DV24: N/A | DW24: N/A | DX24: N/A | DY24: N/A | DZ24: N/A | EA24: N/A | EB24: N/A | EC24: N/A | ED24: N/A | EE24: N/A | EF24: N/A | EG24: N/A | EH24: N/A | EI24: N/A | EJ24: N/A | EK24: N/A | EL24: N/A | EM24: N/A | EN24: N/A | EO24: N/A | EP24: N/A | EQ24: N/A | ER24: N/A | ES24: N/A | ET24: N/A | EU24: N/A | EV24: N/A | EW24: N/A | EX24: N/A | EY24: N/A | EZ24: N/A | FA24: N/A | FB24: N/A | FC24: N/A | FD24: N/A | FE24: N/A | FF24: N/A | FG24: N/A | FH24: N/A | FI24: N/A | FJ24: N/A | FK24: N/A | FL24: N/A | FM24: N/A | FN24: N/A | FO24: N/A | FP24: N/A | FQ24: N/A | FR24: N/A | FS24: N/A | FT24: N/A | FU24: N/A | FV24: N/A | FW24: N/A | FX24: N/A | FY24: N/A | FZ24: N/A | GA24: N/A | GB24: N/A | GC24: N/A | GD24: N/A | GE24: N/A | GF24: N/A | GG24: N/A | GH24: N/A | GI24: N/A | GJ24: N/A | GK24: N/A | GL24: N/A | GM24: N/A | GN24: N/A | GO24: N/A | GP24: N/A | GQ24: N/A | GR24: N/A | GS24: N/A | GT24: N/A | GU24: N/A | GV24: N/A | GW24: N/A | GX24: N/A | GY24: N/A | GZ24: N/A | HA24: N/A | HB24: N/A | HC24: N/A | HD24: N/A | HE24: N/A | HF24: N/A | HG24: N/A | HH24: N/A | HI24: N/A | HJ24: N/A | HK24: N/A | HL24: N/A | HM24: N/A | HN24: N/A | HO24: N/A | HP24: N/A | HQ24: N/A | HR24: N/A | HS24: N/A | HT24: N/A | HU24: N/A | HV24: N/A | HW24: N/A | HX24: N/A | HY24: N/A | HZ24: N/A | IA24: N/A | IB24: N/A | IC24: N/A | ID24: N/A | IE24: N/A | IF24: N/A | IG24: N/A | IH24: N/A | II24: N/A | IJ24: N/A | IK24: N/A | IL24: N/A | IM24: N/A | IN24: N/A | IO24: N/A | IP24: N/A | IQ24: N/A | IR24: N/A | IS24: N/A | IT24: N/A | IU24: N/A | IV24: N/A | IW24: N/A | IX24: N/A | IY24: N/A | IZ24: N/A | JA24: N/A | JB24: N/A | JC24: N/A | JD24: N/A | JE24: N/A | JF24: N/A | JG24: N/A | JH24: N/A | JI24: N/A | JJ24: N/A | JK24: N/A | JL24: N/A | JM24: N/A | JN24: N/A | JO24: N/A | JP24: N/A | JQ24: N/A | JR24: N/A | JS24: N/A | JT24: N/A | JU24: N/A | JV24: N/A | JW24: N/A | JX24: N/A | JY24: N/A | JZ24: N/A | KA24: N/A | KB24: N/A | KC24: N/A | KD24: N/A | KE24: N/A | KF24: N/A | KG24: N/A | KH24: N/A | KI24: N/A | KJ24: N/A | KK24: N/A | KL24: N/A | KM24: N/A | KN24: N/A | KO24: N/A | KP24: N/A | KQ24: N/A | KR24: N/A | KS24: N/A | KT24: N/A | KU24: N/A | KV24: N/A | KW24: N/A | KX24: N/A | KY24: N/A | KZ24: N/A | LA24: N/A | LB24: N/A | LC24: N/A | LD24: N/A | LE24: N/A | LF24: N/A | LG24: N/A | LH24: N/A | LI24: N/A | LJ24: N/A | LK24: N/A | LL24: N/A | LM24: N/A | LN24: N/A | LO24: N/A | LP24: N/A | LQ24: N/A | LR24: N/A | LS24: N/A | LT24: N/A | LU24: N/A | LV24: N/A | LW24: N/A | LX24: N/A | LY24: N/A | LZ24: N/A | MA24: N/A | MB24: N/A | MC24: N/A | MD24: N/A | ME24: N/A | MF24: N/A | MG24: N/A | MH24: N/A | MI24: N/A | MJ24: N/A | MK24: N/A | ML24: N/A | MM24: N/A | MN24: N/A | MO24: N/A | MP24: N/A | MQ24: N/A | MR24: N/A | MS24: N/A | MT24: N/A | MU24: N/A | MV24: N/A | MW24: N/A | MX24: N/A | MY24: N/A | MZ24: N/A | NA24: N/A | NB24: N/A | NC24: N/A | ND24: N/A | NE24: N/A | NF24: N/A | NG24: N/A | NH24: N/A | NI24: N/A | NJ24: N/A | NK24: N/A | NL24: N/A | NM24: N/A | NN24: N/A | NO24: N/A | NP24: N/A | NQ24: N/A | NR24: N/A | NS24: N/A | NT24: N/A | NU24: N/A | NV24: N/A | NW24: N/A | NX24: N/A | NY24: N/A | NZ24: N/A
A25: 4308926637 | D25: No | E25: LH17-30839 | F25: A15 | G25: N/A | H25: 42936 | I25: Total abdominal hysterectomy with bilateral salpingo-oophorectomy. | J25: Endometrium | K25: N/A | L25: N/A | M25: N/A | N25: N/A | O25: N/A | P25: N/A | Q25: N/A | R25: N/A | S25: N/A | T25: N/A | U25: N/A | V25: N/A | W25: N/A | X25: N/A | Y25: N/A | Z25: N/A | AB25: F | AC25: 14734 | AE25: =DATEDIF(AC25, AD25,"Y") -> #NUM! | AF25: Endometrioid carcinoma | AG25: Specimen | AH25: Yes | AI25: 1a | AJ25: 0 | AK25: 0 | AL25: 0 | AM25: T1AN0M0 | AN25: 1 | AO25: N/A
A26: 4861789125 | D26: No | E26: LH17-30974 | F26: A12 | G26: A22 | H26: 42937 | I26: Total abdominal hysterectomy | J26: Endometrium | K26: N/A | L26: N/A | M26: N/A | N26: N/A | O26: N/A | P26: N/A | Q26: N/A | R26: N/A | S26: N/A | T26: N/A | U26: N/A | V26: N/A | W26: N/A | X26: N/A | Y26: N/A | Z26: N/A | AB26: F | AC26: 22500 | AE26: =DATEDIF(AC26, AD26,"Y") -> #NUM! | AF26: Endometrioid adenocarcinoma | AG26: Specimen | AH26: Yes | AI26: 1a | AJ26: 0 | AK26: 0 | AL26: 0 | AM26: T1AN0M0 | AN26: 1 | AO26: N/A
A27: 4520776414 | D27: No | E27: LH17-32555 | F27: A6 | G27: N/A | H27: 42948 | I27: Total laparoscopic hysterectomy | J27: Endometrium | K27: N/A | L27: N/A | M27: N/A | N27: N/A | O27: N/A | P27: N/A | Q27: N/A | R27: N/A | S27: N/A | T27: N/A | U27: N/A | V27: N/A | W27: N/A | X27: N/A | Y27: N/A | Z27: N/A | AB27: F | AC27: 19253 | AE27: =DATEDIF(AC27, AD27,"Y") -> #NUM! | AF27: Endometrioid adenocarcinoma | AG27: Specimen | AH27: Yes | AI27: 1b | AJ27: 0 | AK27: 0 | AL27: 0 | AM27: T1BN0M0 | AN27: 1 | AO27: N/A
A28: 4582803245 | D28: No | E28: LH17-32987 | F28: 6 | G28: 7 | H28: 42950 | I28: Total laparoscopic hysterectomy/Bilateral salpingo-oophorectomy | J28: Endometrium | K28: N/A | L28: N/A | M28: N/A | N28: N/A | O28: N/A | P28: N/A | Q28: N/A | R28: N/A | S28: N/A | T28: N/A | U28: N/A | V28: N/A | W28: N/A | X28: N/A | Y28: N/A | Z28: N/A | AB28: F | AC28: 20209 | AE28: =DATEDIF(AC28, AD28,"Y") -> #NUM! | AF28: Endometrioid carcinoma | AG28: Specimen | AH28: N/R | AI28: 2 | AJ28: 0 | AK28: 0 | AL28: 0 | AM28: T2N0M0 | AN28: 2 | AO28: N/A
A29: 4948238384 | D29: No | E29: LH17-33790 | F29: A11 | G29: A12 | H29: 42956 | I29: Total abdominal hysterectomy | J29: Endometrium | K29: N/A | L29: N/A | M29: N/A | N29: N/A | O29: N/A | P29: N/A | Q29: N/A | R29: N/A | S29: N/A | T29: N/A | U29: N/A | V29: N/A | W29: LH17-33790 | X29: C3 | Y29: Pelvic node | Z29: 42956 | AB29: F | AC29: 12619 | AE29: =DATEDIF(AC29, AD29,"Y") -> #NUM! | AF29: Endometrioid adenocarcinoma | AG29: Specimen | AH29: Yes | AI29: 3a | AJ29: 0 | AK29: 0 | AL29: 0 | AM29: T3AN0M0 | AN29: 3 | AO29: N/A
A30: 4583815352 | D30: No | E30: LH17-34068 | F30: 4 | G30: N/A | H30: 42957 | I30: Total laparoscopic hysterectomy | J30: Endometrium | K30: N/A | L30: N/A | M30: N/A | N30: N/A | O30: N/A | P30: N/A | Q30: N/A | R30: N/A | S30: N/A | T30: N/A | U30: N/A | V30: N/A | W30: N/A | X30: N/A | Y30: N/A | Z30: N/A | AB30: F | AC30: 20935 | AE30: =DATEDIF(AC30, AD30,"Y") -> #NUM! | AF30: Endometrioid adenocarcinoma | AG30: Specimen | AH30: N/R | AI30: 1a | AJ30: 0 | AK30: 0 | AL30: 0 | AM30: T1AN0M0 | AN30: 1 | AO30: N/A
A31: 4109016088 | D31: No | E31: LH17-34353 | F31: A7 | G31: A6 | H31: 42961 | I31: Total abdominal hysterectomy | J31: Endometrium | K31: N/A | L31: N/A | M31: N/A | N31: N/A | O31: N/A | P31: N/A | Q31: N/A | R31: N/A | S31: N/A | T31: N/A | U31: N/A | V31: N/A | W31: N/A | X31: N/A | Y31: N/A | Z31: N/A | AB31: F | AC31: 16954 | AE31: =DATEDIF(AC31, AD31,"Y") -> #NUM! | AF31: Carcinosarcoma with heterologous elements | AG31: Specimen | AH31: Yes | AI31: 3 | AJ31: 2 | AK31: 0 | AL31: 0 | AM31: T3CN2M0 | AN31: N/R | AO31: N/A
A32: 4343616568 | D32: No | E32: LH17-35617 | F32: A2 | G32: N/A | H32: 42968 | I32: Total laparoscopic hysterectomy | J32: Endometrium | K32: N/A | L32: N/A | M32: N/A | N32: N/A | O32: N/A | P32: N/A | Q32: N/A | R32: N/A | S32: N/A | T32: N/A | U32: N/A | V32: N/A | W32: N/A | X32: N/A | Y32: N/A | Z32: N/A | AB32: F | AC32: 12808 | AE32: =DATEDIF(AC32, AD32,"Y") -> #NUM! | AF32: Endometrioid carcinoma | AG32: Specimen | AH32: Yes | AI32: 1a | AJ32: 0 | AK32: 0 | AL32: 0 | AM32: T1AN0M0 | AN32: 1 | AO32: N/A
A33: 4483680641 | D33: No | E33: LH17-35965 | F33: A9 | G33: A10 | H33: 42970 | I33: Total laparoscopic hysterectomy,bso,omental biopsy, pelvic and pa lymph node sampling | J33: Endometrium | K33: N/A | L33: N/A | M33: N/A | N33: N/A | O33: N/A | P33: N/A | Q33: N/A | R33: N/A | S33: N/A | T33: N/A | U33: N/A | V33: N/A | W33: LH17-35965 | X33: B4 | Y33: Lymph node | Z33: 42970 | AB33: F | AC33: 20760 | AE33: =DATEDIF(AC33, AD33,"Y") -> #NUM! | AF33: Clear cell carcinoma of endometrium | AG33: Specimen | AH33: Yes | AI33: 2 | AJ33: 0 | AK33: 0 | AL33: 0 | AM33: T2N0M0 | AN33: 3 | AO33: N/A
A34: 4347092857 | D34: No | E34: LH17-36526 | F34: A7 | G34: A6 | H34: 42976 | I34: Total laparoscopic hysterectomy | J34: Endometrium | K34: N/A | L34: N/A | M34: N/A | N34: N/A | O34: N/A | P34: N/A | Q34: N/A | R34: N/A | S34: N/A | T34: N/A | U34: N/A | V34: N/A | W34: N/A | X34: N/A | Y34: N/A | Z34: N/A | AB34: F | AC34: 12091 | AE34: =DATEDIF(AC34, AD34,"Y") -> #NUM! | AF34: Endometrioid carcinoma | AG34: Specimen | AH34: Yes | AI34: 3 | AJ34: 1 | AK34: 0 | AL34: 0 | AM34: T3CN1M0 | AN34: 2 | AO34: N/A
A35: 4583119461 | D35: No | E35: LH17-36679 | F35: A9 | G35: A8 | H35: 42976 | I35: Total abdominal hysterectomy | J35: Endometrium | K35: N/A | L35: N/A | M35: N/A | N35: N/A | O35: N/A | P35: N/A | Q35: N/A | R35: N/A | S35: N/A | T35: N/A | U35: N/A | V35: N/A | W35: N/A | X35: N/A | Y35: N/A | Z35: N/A | AB35: F | AC35: 20795 | AE35: =DATEDIF(AC35, AD35,"Y") -> #NUM! | AF35: Endometrioid carcinoma | AG35: Specimen | AH35: Yes | AI35: 3 | AJ35: 2 | AK35: 0 | AL35: 0 | AM35: T3CN2M0 | AN35: 2 | AO35: N/A
A36: 4425422260 | D36: No | E36: LH17-37241 | F36: A5 | G36: A6 | H36: 42979 | I36: Total abdominal hysterectomy | J36: Endometrium | K36: N/A | L36: N/A | M36: N/A | N36: N/A | O36: N/A | P36: N/A | Q36: N/A | R36: N/A | S36: N/A | T36: N/A | U36: N/A | V36: N/A | W36: N/A | X36: N/A | Y36: N/A | Z36: N/A | AB36: F | AC36: 15300 | AE36: =DATEDIF(AC36, AD36,"Y") -> #NUM! | AF36: Carcinosarcoma with heterologous elements | AG36: Specimen | AH36: Yes | AI36: 1b | AJ36: 0 | AK36: 0 | AL36: 0 | AM36: T1BN0M0 | AN36: 3 | AO36: N/A
A37: 4382637317 | D37: No | E37: LH17-37984 | F37: A4 | G37: A5 | H37: 42984 | I37: Total abdominal hysterectomy | J37: Endometrium | K37: N/A | L37: N/A | M37: N/A | N37: N/A | O37: N/A | P37: N/A | Q37: N/A | R37: N/A | S37: N/A | T37: N/A | U37: N/A | V37: N/A | W37: N/A | X37: N/A | Y37: N/A | Z37: N/A | AB37: F | AC37: 19707 | AE37: =DATEDIF(AC37, AD37,"Y") -> #NUM! | AF37: Endometrioid adenocarcinoma with foci of clear cell differentiation | AG37: Specimen | AH37: Yes | AI37: 1b | AJ37: 0 | AK37: 0 | AL37: 0 | AM37: T1BN0M0 | AN37: 2 | AO37: N/A
A38: 6263484020 | D38: No | E38: LH17-38467 | F38: A7 | G38: A6 | H38: 42989 | I38: Total abdominal hysterectomy | J38: Endometrium | K38: N/A | L38: N/A | M38: N/A | N38: N/A | O38: N/A | P38: N/A | Q38: N/A | R38: N/A | S38: N/A | T38: N/A | U38: N/A | V38: N/A | W38: N/A | X38: N/A | Y38: N/A | Z38: N/A | AB38: F | AC38: 19352 | AE38: =DATEDIF(AC38, AD38,"Y") -> #NUM! | AF38: Endometrioid carcinoma | AG38: Specimen | AH38: Yes | AI38: 3 | AJ38: 1 | AK38: 0 | AL38: 0 | AM38: T3CN1M0 | AN38: 2 | AO38: N/A
A39: 4508116930 | D39: No | E39: LH17-40476 | F39: A6 | G39: A7 | H39: 43000 | I39: Laparotomy/Total abdominal hysterectomy/Bilateral salpingo-oophorectomy/Pelvic and para-aortic lymphadenectomy/Omentectomy | J39: Endometrium | K39: N/A | L39: N/A | M39: N/A | N39: N/A | O39: N/A | P39: N/A | Q39: N/A | R39: N/A | S39: N/A | T39: N/A | U39: N/A | V39: N/A | W39: LH17-40476 | X39: D9 | Y39: Pelvic node | Z39: 43000 | AB39: F | AC39: 17624 | AE39: =DATEDIF(AC39, AD39,"Y") -> #NUM! | AF39: High-grade serous carcinoma | AG39: Specimen | AH39: Yes | AI39: 1b | AJ39: 0 | AK39: 0 | AL39: 0 | AM39: T1BN0M0 | AN39: 3 | AO39: N/A
A40: 6164754372 | D40: No | E40: LH17-41239 | F40: A13 | G40: A22 | H40: 43005 | I40: Laparotomy, total abdominal hysterectomy, bilateral salpingo-oophorectomy, infracolic omentectomy, pelvic and PA node dissection | J40: Endometrium | K40: N/A | L40: N/A | M40: N/A | N40: N/A | O40: N/A | P40: N/A | Q40: N/A | R40: N/A | S40: N/A | T40: N/A | U40: N/A | V40: N/A | W40: N/A | X40: N/A | Y40: N/A | Z40: N/A | AB40: F | AC40: 15130 | AE40: =DATEDIF(AC40, AD40,"Y") -> #NUM! | AF40: Carcinosarcoma showing rhabdomyoblastic differentiation | AG40: Specimen | AH40: Yes | AI40: 3 | AJ40: 2 | AK40: 0 | AL40: 0 | AM40: T3CN2M0 | AN40: 3 | AO40: N/A
A41: 4041363497 | D41: No | E41: LH17-41484 | F41: A4 | G41: A5 | H41: 43006 | I41: Total abdominal hysterectomy nec | J41: Endometrium | K41: N/A | L41: N/A | M41: N/A | N41: N/A | O41: N/A | P41: N/A | Q41: N/A | R41: N/A | S41: N/A | T41: N/A | U41: N/A | V41: N/A | W41: N/A | X41: N/A | Y41: N/A | Z41: N/A | AB41: F | AC41: 15879 | AE41: =DATEDIF(AC41, AD41,"Y") -> #NUM! | AF41: Endometrioid adenocarcinoma | AG41: Specimen | AH41: Yes | AI41: 3 | AJ41: 1 | AK41: 0 | AL41: 0 | AM41: T3CN1M0 | AN41: 3 | AO41: N/A
...

Sheet Supplementary (ship 1)
A1: NHS number | B1: Donor ID | C1: Specimen number | D1: FIGO grading
A2: 4520256615 | C2: LH17-02702 | D2: IIIC1
A3: 4250445798 | C3: LH17-06069 | D3: IB
A4: 4946723307 | C4: LH17-07381 | D4: IB
A5: 4362503161 | C5: LH17-10008 | D5: II
A6: 4363753323 | C6: LH17-10854 | D6: IIIC1
A7: 4367569659 | C7: LH17-11093 | D7: IB
A8: 4581564212 | C8: LH17-11306 | D8: II
A9: 4706490731 | C9: LH17-12612 | D9: II
A10: 4366490994 | C10: LH17-13646 | D10: IVB
A11: 4508221386 | C11: LH17-15131 | D11: IB
A12: 4905526434 | C12: LH17-16034 | D12: IB
A13: 4663105459 | C13: LH17-16275 | D13: IA
... A74: 6302622166 | C74: LH18-14629 | D74: IA

Sheet Follow up (ship 2)
A1: PLEASE BE AWARE COLUMNS MAY BE 'HIDDEN' OR 'COLLAPSED'
