Workbook

Sheet MMR proficient
A1: PLEASE BE AWARE COLUMNS MAY BE 'HIDDEN' OR 'COLLAPSED'
F2: Not in path report
A3: NHS number | B3: Any Immunotherapy | C3: Specimen treatment subgrouping | D3: Specimen is a recurrence | E3: Selected specimen Anonymised ID | F3: Specimen Block number 1 | G3: Specimen Block number 2 | H3: Specimen surgery date | I3: Specimen surgery | J3: Specimen tumour site | K3: Primary Surgery date | L3: Primary tumour site | M3: Anonymized ID Matched met 1 | N3: Matched met 1 Block Number | O3: Matched met 1 Site | P3: Matched met 1 Surgery Date | Q3: Matched met 1 treatment subgrouping | R3: Anonymized ID Matched met 2 | S3: Matched met 2 Block Number | T3: Matched met 2 Site | U3: Matched met 2 Surgery Date | V3: Matched met 2 treatment subgrouping | W3: Anonymized ID Normal tissue | X3: Matched Normal tissue Block Number | Y3: Matched Normal tissue Site | Z3: Matched Normal tissue Surgery Date | AA3: Matched Normal treatment subgrouping | AB3: Gender | AC3: DOB | AD3: Date of DX | AE3: Age at Diagnosis | AF3: Specimen Histological Diagnosis | AG3: Staging/grading info provided for: | AH3: Resection margins clear | AI3: pT | AJ3: pN | AK3: pM | AL3: cM | AM3: TNM stage | AN3: Grade | AO3: Stage at DX (AJCC) | AP3: Any Neoadjuvant therapy | AQ3: Response to neoadjuvant therapy (TRS score) | AR3: Neoadjuvant Tx1 | AS3: Neoadjuvant Tx1 Agent | AT3: Neoadjuvant Tx1 Start Date | AU3: Neoadjuvant Tx1 End Date | AV3: Tumour response Neoadjuvant Tx1 | AW3: Neoadjuvant Tx2 | AX3: Neoadjuvant Tx2 Agent | AY3: Neoadjuvant Tx2 Start Date | AZ3: Neoadjuvant Tx2 End Date | BA3: Tumour response Neoadjuvant Tx2 | BB3: Neoadjuvant Tx3 | BC3: Neoadjuvant Tx3 Agent | BD3: Neoadjuvant Tx3 Start Date | BE3: Neoadjuvant Tx3 End Date | BF3: Tumour response Neoadjuvant Tx3 | BG3: Neoadjuvant Tx4 | BH3: Neoadjuvant Tx4 Agent | BI3: Neoadjuvant Tx4 Start Date | BJ3: Neoadjuvant Tx4 End Date | BK3: Tumour response Neoadjuvant Tx4 | BL3: Neoadjuvant Tx5 | BM3: Neoadjuvant Tx5 Agent | BN3: Neoadjuvant Tx5 Start Date | BO3: Neoadjuvant Tx5 End Date | BP3: Tumour response Neoadjuvant Tx5 | BQ3: Neoadjuvant Tx6 | BR3: Neoadjuvant Tx6 Agent | BS3: Neoadjuvant Tx6 Start Date | BT3: Neoadjuvant Tx6 End Date | BU3: Tumour response Neoadjuvant Tx6 | BV3: Neoadjuvant Tx7 | BW3: Neoadjuvant Tx7 Agent | BX3: Neoadjuvant Tx7 Start Date | BY3: Neoadjuvant Tx7 End Date | BZ3: Tumour response Neoadjuvant Tx7 | CA3: Neoadjuvant Tx8 | CB3: Neoadjuvant Tx8 Agent | CC3: Neoadjuvant Tx8 Start Date | CD3: Neoadjuvant Tx8 End Date | CE3: Tumour response Neoadjuvant Tx8 | CF3: Neoadjuvant Tx9 | CG3: Neoadjuvant Tx9 Agent | CH3: Neoadjuvant Tx9 Start Date | CI3: Neoadjuvant Tx9 End Date | CJ3: Tumour response Neoadjuvant Tx9 | CK3: Neoadjuvant Tx10 | CL3: Neoadjuvant Tx10 Agent | CM3: Neoadjuvant Tx10 Start Date | CN3: Neoadjuvant Tx10 End Date | CO3: Tumour response Neoadjuvant Tx10 | CP3: Adjuvant Tx1 | CQ3: Adjuvant Tx1 Agent | CR3: Adjuvant Tx1 Start Date | CS3: Adjuvant Tx1 End Date | CT3: Tumour response Adjuvant Tx1 | CU3: Adjuvant Tx2 | CV3: Adjuvant Tx2 Agent | CW3: Adjuvant Tx2 Start Date | CX3: Adjuvant Tx2 End Date | CY3: Tumour response Adjuvant Tx2 | CZ3: Adjuvant Tx3 | DA3: Adjuvant Tx3 Agent | DB3: Adjuvant Tx3 Start Date | DC3: Adjuvant Tx3 End Date | DD3: Tumour response Adjuvant Tx3 | DE3: Adjuvant Tx4 | DF3: Adjuvant Tx4 Agent | DG3: Adjuvant Tx4 Start Date | DH3: Adjuvant Tx4 End Date | DI3: Tumour response Adjuvant Tx4 | DJ3: Adjuvant Tx5 | DK3: Adjuvant Tx5 Agent | DL3: Adjuvant Tx5 Start Date | DM3: Adjuvant Tx5 End Date | DN3: Tumour response Adjuvant Tx5 | DO3: Adjuvant Tx6 | DP3: Adjuvant Tx6 Agent | DQ3: Adjuvant Tx6 Start Date | DR3: Adjuvant Tx6 End Date | DS3: Tumour response Adjuvant Tx6 | DT3: Adjuvant Tx7 | DU3: Adjuvant Tx7 Agent | DV3: Adjuvant Tx7 Start Date | DW3: Adjuvant Tx7 End Date | DX3: Tumour response Adjuvant Tx7 | DY3: Adjuvant Tx8 | DZ3: Adjuvant Tx8 Agent | EA3: Adjuvant Tx8 Start Date | EB3: Adjuvant Tx8 End Date | EC3: Tumour response Adjuvant Tx8 | ED3: Adjuvant Tx9 | EE3: Adjuvant Tx9 Agent | EF3: Adjuvant Tx9 Start Date | EG3: Adjuvant Tx9 End Date | EH3: Tumour response Adjuvant Tx9 | EI3: Adjuvant Tx10 | EJ3: Adjuvant Tx10 Agent | EK3: Adjuvant Tx10 Start Date | EL3: Adjuvant Tx10 End Date | EM3: Tumour response Adjuvant Tx10 | EN3: Adjuvant Tx11 | EO3: Adjuvant Tx11 Agent | EP3: Adjuvant Tx11 Start Date | EQ3: Adjuvant Tx11 End Date | ER3: Tumour response Adjuvant Tx11 | ES3: Adjuvant Tx12 | ET3: Adjuvant Tx12 Agent | EU3: Adjuvant Tx12 Start Date | EV3: Adjuvant Tx12 End Date | EW3: Tumour response Adjuvant Tx12 | EX3: Adjuvant Tx13 | EY3: Adjuvant Tx13 Agent | EZ3: Adjuvant Tx13 Start Date | FA3: Adjuvant Tx13 End Date | FB3: Tumour response Adjuvant Tx13 | FC3: Adjuvant Tx14 | FD3: Adjuvant Tx14 Agent | FE3: Adjuvant Tx14 Start Date | FF3: Adjuvant Tx14 End Date | FG3: Tumour response Adjuvant Tx14 | FH3: Adjuvant Tx15 | FI3: Adjuvant Tx15 Agent | FJ3: Adjuvant Tx15 Start Date | FK3: Adjuvant Tx15 End Date | FL3: Date recurrence/ progression 1 | FM3: Sites recurrence/ progression 1 | FN3: Date recurrence/ progression 2 | FO3: Sites recurrence/ progression 2 | FP3: Date recurrence/ progression 3 | FQ3: Sites recurrence/ progression 3 | FR3: Date recurrence/ progression 4 | FS3: Sites recurrence/ progression 4 | FT3: Date recurrence/ progression 5 | FU3: Sites recurrence/ progression 5 | FV3: Date recurrence/ progression 6 | FW3: Sites recurrence/ progression 6 | FX3: Date recurrence/ progression 7 | FY3: Sites recurrence/ progression 7 | FZ3: Date recurrence/ progression 8 | GA3: Sites recurrence/ progression 8 | GB3: Date recurrence/ progression 9 | GC3: Sites recurrence/ progression 9 | GD3: Date recurrence/ progression 10 | GE3: Sites recurrence/ progression 10 | GF3: Date recurrence/ progression 11 | GG3: Sites recurrence/ progression 11 | GH3: Date recurrence/ progression 12 | GI3: Sites recurrence/ progression 12 | GJ3: Date recurrence/ progression 13 | GK3: Sites recurrence/ progression 13 | GL3: Date recurrence/ progression 14 | GM3: Sites recurrence/ progression 14 | GN3: Date recurrence/ progression 15 | GO3: Sites recurrence/ progression 15 | GP3: Subsequent Tx1 | GQ3: Subsequent Tx1 Agent | GR3: Subsequent Tx1 Start Date | GS3: Subsequent Tx1 Finish Date | GT3: Tumour response to Subsequent Tx1 | GU3: Subsequent Tx2 | GV3: Subsequent Tx2 Agent | GW3: Subsequent Tx2 Start Date | GX3: Subsequent Tx2 Finish Date | GY3: Tumour response to Subsequent Tx2 | GZ3: Subsequent Tx3 | HA3: Subsequent Tx3 Agent | HB3: Subsequent Tx3 Start Date | HC3: Subsequent Tx3 Finish Date | HD3: Tumour response to Subsequent Tx3 | HE3: Subsequent Tx4 | HF3: Subsequent Tx4 Agent | HG3: Subsequent Tx4 Start Date | HH3: Subsequent Tx4 Finish Date | HI3: Tumour response to Subsequent Tx4 | HJ3: Subsequent Tx5 | HK3: Subsequent Tx5 Agent | HL3: Subsequent Tx5 Start Date | HM3: Subsequent Tx5 Finish Date | HN3: Tumour response to Subsequent Tx5 | HO3: Subsequent Tx6 | HP3: Subsequent Tx6 Agent | HQ3: Subsequent Tx6 Start Date | HR3: Subsequent Tx6 Finish Date | HS3: Tumour response to Subsequent Tx6 | HT3: Subsequent Tx7 | HU3: Subsequent Tx7 Agent | HV3: Subsequent Tx7 Start Date | HW3: Subsequent Tx7 Finish Date | HX3: Tumour response to Subsequent Tx7 | HY3: Subsequent Tx8 | HZ3: Subsequent Tx8 Agent | IA3: Subsequent Tx8 Start Date | IB3: Subsequent Tx8 Finish Date | IC3: Tumour response to Subsequent Tx8 | ID3: Subsequent Tx9 | IE3: Subsequent Tx9 Agent | IF3: Subsequent Tx9 Start Date | IG3: Subsequent Tx9 Finish Date | IH3: Tumour response to Subsequent Tx9 | II3: Subsequent Tx10 | IJ3: Subsequent Tx10 Agent | IK3: Subsequent Tx10 Start Date | IL3: Subsequent Tx10 Finish Date | IM3: Tumour response to Subsequent Tx10 | IN3: Subsequent Tx11 | IO3: Subsequent Tx11 Agent | IP3: Subsequent Tx11 Start Date | IQ3: Subsequent Tx11 Finish Date | IR3: Tumour response to Subsequent Tx11 | IS3: Subsequent Tx12 | IT3: Subsequent Tx12 Agent | IU3: Subsequent Tx12 Start Date | IV3: Subsequent Tx12 Finish Date | IW3: Tumour response to Subsequent Tx12 | IX3: Subsequent Tx13 | IY3: Subsequent Tx13 Agent | IZ3: Subsequent Tx13 Start Date | JA3: Subsequent Tx13 Finish Date | JB3: Tumour response to Subsequent Tx13 | JC3: Subsequent Tx14 | JD3: Subsequent Tx14 Agent | JE3: Subsequent Tx14 Start Date | JF3: Subsequent Tx14 Finish Date | JG3: Tumour response to Subsequent Tx14 | JH3: Subsequent Tx15 | JI3: Subsequent Tx15 Agent | JJ3: Subsequent Tx15 Start Date | JK3: Subsequent Tx15 Finish Date | JL3: Tumour response to Subsequent Tx15 | JM3: Current Status | JN3: Death date | JO3: Death tumour related | JP3: Cause of death | JQ3: Date last follow-up | JR3: Date Last Seen | JS3: Concurrent Medical Conditions | JT3: Comments from clinical team | JU3: TTE Neoadjuvant Tx1 Start Date | JV3: TTE Neoadjuvant Tx1 End Date | JW3: TTE Neoadjuvant Tx2 Start Date | JX3: TTE Neoadjuvant Tx2 End Date | JY3: TTE Neoadjuvant Tx3 Start Date | JZ3: TTE Neoadjuvant Tx3 End Date | KA3: TTE Neoadjuvant Tx4 Start Date | KB3: TTE Neoadjuvant Tx4 End Date | KC3: TTE Neoadjuvant Tx5 Start Date | KD3: TTE Neoadjuvant Tx5 End Date | KE3: TTE Neoadjuvant Tx6 Start Date | KF3: TTE Neoadjuvant Tx6 End Date | KG3: TTE Neoadjuvant Tx7 Start Date | KH3: TTE Neoadjuvant Tx7 End Date | KI3: TTE Neoadjuvant Tx8 Start Date | KJ3: TTE Neoadjuvant Tx8 End Date | KK3: TTE Neoadjuvant Tx9 Start Date | KL3: TTE Neoadjuvant Tx9 End Date | KM3: TTE Neoadjuvant Tx10 Start Date | KN3: TTE Neoadjuvant Tx10 End Date | KO3: TTE Specimen surgery date | KP3: TTE Primary Surgery date | KQ3: TTE Matched met 1 Surgery Date | KR3: TTE Matched met 2 Surgery Date | KS3: TTE Matched Normal tissue Surgery Date | KT3: TTE Adjuvant Tx1 Start Date | KU3: TTE Adjuvant Tx1 End Date | KV3: TTE Adjuvant Tx2 Start Date | KW3: TTE Adjuvant Tx2 End Date | KX3: TTE Adjuvant Tx3 Start Date | KY3: TTE Adjuvant Tx3 End Date | KZ3: TTE Adjuvant Tx4 Start Date | LA3: TTE Adjuvant Tx4 End Date | LB3: TTE Adjuvant Tx5 Start Date | LC3: TTE Adjuvant Tx5 End Date | LD3: TTE Adjuvant Tx6 Start Date | LE3: TTE Adjuvant Tx6 End Date | LF3: TTE Adjuvant Tx7 Start Date | LG3: TTE Adjuvant Tx7 End Date | LH3: TTE Adjuvant Tx8 Start Date | LI3: TTE Adjuvant Tx8 End Date | LJ3: TTE Adjuvant Tx9 Start Date | LK3: TTE Adjuvant Tx9 End Date | LL3: TTE Adjuvant Tx10 Start Date | LM3: TTE Adjuvant Tx10 End Date | LN3: TTE Adjuvant Tx11 Start Date | LO3: TTE Adjuvant Tx11 End Date | LP3: TTE Adjuvant Tx12 Start Date | LQ3: TTE Adjuvant Tx12 End Date | LR3: TTE Adjuvant Tx13 Start Date | LS3: TTE Adjuvant Tx13 End Date | LT3: TTE Adjuvant Tx14 Start Date | LU3: TTE Adjuvant Tx14 End Date | LV3: TTE Adjuvant Tx15 Start Date | LW3: TTE Adjuvant Tx15 End Date | LX3: TTE Date recurrence/ progression 1 | LY3: TTE Date recurrence/ progression 2 | LZ3: TTE Date recurrence/ progression 3 | MA3: TTE Date recurrence/ progression 4 | MB3: TTE Date recurrence/ progression 5 | MC3: TTE Date recurrence/ progression 6 | MD3: TTE Date recurrence/ progression 7 | ME3: TTE Date recurrence/ progression 8 | MF3: TTE Date recurrence/ progression 9 | MG3: TTE Date recurrence/ progression 10 | MH3: TTE Date recurrence/ progression 11 | MI3: TTE Date recurrence/ progression 12 | MJ3: TTE Date recurrence/ progression 13 | MK3: TTE Date recurrence/ progression 14 | ML3: TTE Date recurrence/ progression 15 | MM3: TTE Subsequent Tx1 Start Date | MN3: TTE Subsequent Tx1 Finish Date | MO3: TTE Subsequent Tx2 Start Date | MP3: TTE Subsequent Tx2 Finish Date | MQ3: TTE Subsequent Tx3 Start Date | MR3: TTE Subsequent Tx3 Finish Date | MS3: TTE Subsequent Tx4 Start Date | MT3: TTE Subsequent Tx4 Finish Date | MU3: TTE Subsequent Tx5 Start Date | MV3: TTE Subsequent Tx5 Finish Date | MW3: TTE Subsequent Tx6 Start Date | MX3: TTE Subsequent Tx6 Finish Date | MY3: TTE Subsequent Tx7 Start Date | MZ3: TTE Subsequent Tx7 Finish Date | NA3: TTE Subsequent Tx8 Start Date | NB3: TTE Subsequent Tx8 Finish Date | NC3: TTE Subsequent Tx9 Start Date | ND3: TTE Subsequent Tx9 Finish Date | NE3: TTE Subsequent Tx10 Start Date | NF3: TTE Subsequent Tx10 Finish Date | NG3: TTE Subsequent Tx11 Start Date | NH3: TTE Subsequent Tx11 Finish Date | NI3: TTE Subsequent Tx12 Start Date | NJ3: TTE Subsequent Tx12 Finish Date | NK3: TTE Subsequent Tx13 Start Date | NL3: TTE Subsequent Tx13 Finish Date | NM3: TTE Subsequent Tx14 Start Date | NN3: TTE Subsequent Tx14 Finish Date | NO3: TTE Subsequent Tx15 Start Date | NP3: TTE Subsequent Tx15 Finish Date | NQ3: TTE Recurrence (PFS) | NR3: TTE Death (OS and PFS) | NS3: TTE Date last follow-up (PFS) | NT3: TTE Date last seen (OS) | NU3: TTE Overall survival (OS) in months | NV3: TTE Progression free survival (PFS) in months | NW3: Event (recurrence/progression) | NX3: Event (cancer death) | NY3: Event (death; all causes) | NZ3: Event (recurrence or cancer death)
A4: 4849515096 | B4: No | C4: Treatment naïve | D4: No | E4: LH15-23319 | F4: C10 | G4: C7 | H4: 42159 | I4: Laparotomy with total abdominal hysterectomy, bilateral salpingo-oophorectomy, peritoneal washings and bilateral pelvic lymphadenectomy | J4: Uterine corpus | K4: N/A | L4: N/A | M4: N/A | N4: N/A | O4: N/A | P4: N/A | Q4: N/A | R4: N/A | S4: N/A | T4: N/A | U4: N/A | V4: N/A | W4: N/A | X4: N/A | Y4: N/A | Z4: N/A | AA4: N/A | AB4: F | AC4: 22788 | AD4: 42129 | AE4: =DATEDIF(AC4, AD4,"Y") -> 52 | AF4: Endometrioid adenocarcinoma | AG4: Specimen | AH4: Yes | AI4: 1A | AJ4: 0 | AK4: NR | AL4: 0 | AM4: T1AN0M0 | AN4: 2 | AO4: N/A
A5: 4760475672 | B5: No | C5: Treatment naïve | D5: No | E5: LH16-14222 | F5: A4 | G5: A11 | H5: 42464 | I5: Laparotomy with total abdominal hysterectomy, bilateral salpingo-oophorectomy, supracolic omentectomy, bilateral pelvic lymphadenectomy and para-aortic lymph node sampling | J5: Uterine corpus | K5: N/A | L5: N/A | M5: N/A | N5: N/A | O5: N/A | P5: N/A | Q5: N/A | R5: N/A | S5: N/A | T5: N/A | U5: N/A | V5: N/A | W5: N/A | X5: N/A | Y5: N/A | Z5: N/A | AA5: N/A | AB5: F | AC5: 23553 | AD5: 42409 | AE5: =DATEDIF(AC5, AD5,"Y") -> 51 | AF5: Endometrioid adenocarcinoma | AG5: Specimen | AH5: NR | AI5: 3B | AJ5: 0 | AK5: NR | AL5: 0 | AM5: T3BN0M0 | AN5: 1 | AO5: N/A | JT5: Synchronous IIA endometrioid adenocarcinoma in ovary (grade 1)
A6: 4363568348 | B6: No | C6: Treatment naïve | D6: No | E6: LH17-12064 | F6: A8 | G6: A9 | H6: 42815 | I6: Total laparoscopic hysterectomy, bilateral salpingo-oophorectomy, adhesiolysis, peritoneal washings and bilateral pelvic lymphadenectomy | J6: Uterine corpus | K6: N/A | L6: N/A | M6: N/A | N6: N/A | O6: N/A | P6: N/A | Q6: N/A | R6: N/A | S6: N/A | T6: N/A | U6: N/A | V6: N/A | W6: N/A | X6: N/A | Y6: N/A | Z6: N/A | AA6: N/A | AB6: F | AC6: 13593 | AD6: 42815 | AE6: =DATEDIF(AC6, AD6,"Y") -> 80 | AF6: Endometrioid adenocarcinoma | AG6: Specimen | AH6: Yes | AI6: 1B | AJ6: 0 | AK6: NR | AL6: 0 | AM6: T1BN0M0 | AN6: 1 | AO6: N/A
A7: 4862097049 | B7: No | C7: Treatment naïve | D7: No | E7: LH17-18561 | F7: A8 | G7: A4 | H7: 42858 | I7: Adhesiolysis, Total laparoscopic hysterectomy, bilateral salpingo-oophorectomy, pelvic lymphnode dissection, Para-aortal lymphnode dissection, paracaval lymphnode sampling | J7: Cervix, upper endocervical canal (tumour arising in lower uterine segment) | K7: N/A | L7: N/A | M7: N/A | N7: N/A | O7: N/A | P7: N/A | Q7: N/A | R7: N/A | S7: N/A | T7: N/A | U7: N/A | V7: N/A | W7: N/A | X7: N/A | Y7: N/A | Z7: N/A | AA7: N/A | AB7: F | AC7: 23118 | AD7: 42810 | AE7: =DATEDIF(AC7, AD7,"Y") -> 53 | AF7: Endometrioid adenocarcinoma | AG7: Specimen | AH7: Yes | AI7: 2 | AJ7: 0 | AK7: NR | AL7: 0 | AM7: T2N0M0 | AN7: 2 | AO7: N/A
A8: 4124075219 | B8: No | C8: Treatment naïve | D8: No | E8: LH17-31445 | F8: A5 | G8: A6 | H8: 42941 | I8: Total laparoscopic hysterectomy, bilateral salpingo-oophorectomy, adhesiolysis | J8: Uterine corpus | K8: N/A | L8: N/A | M8: N/A | N8: N/A | O8: N/A | P8: N/A | Q8: N/A | R8: N/A | S8: N/A | T8: N/A | U8: N/A | V8: N/A | W8: N/A | X8: N/A | Y8: N/A | Z8: N/A | AA8: N/A | AB8: F | AC8: 25388 | AD8: 42880 | AE8: =DATEDIF(AC8, AD8,"Y") -> 47 | AF8: Endometrioid adenocarcinoma | AG8: Specimen | AH8: Yes | AI8: 1A | AJ8: NR | AK8: NR | AL8: 0 | AM8: T1AN0M0 | AN8: 1 | AO8: N/A
A9: 4120037274 | B9: No | C9: Treatment naïve | D9: No | E9: LH18-18494 | F9: A27 | G9: A8 | H9: 43220 | I9: Total laparoscopic hysterectomy/Bilateral salpingo-oophorectomy | J9: Uterine corpus | K9: N/A | L9: N/A | M9: N/A | N9: N/A | O9: N/A | P9: N/A | Q9: N/A | R9: N/A | S9: N/A | T9: N/A | U9: N/A | V9: N/A | W9: N/A | X9: N/A | Y9: N/A | Z9: N/A | AA9: N/A | AB9: F | AC9: 25795 | AD9: 43133 | AE9: =DATEDIF(AC9, AD9,"Y") -> 47 | AF9: Endometrioid adenocarcinoma | AG9: Specimen | AH9: Yes | AI9: 1B | AJ9: NR | AK9: NR | AL9: 0 | AM9: T1BN0M0 | AN9: 1 | AO9: N/A | JU9: =IFERROR((YEARFRAC($AD9,$AT9)*12),"N/A") -> 1417.0667 | JV9: =IFERROR((YEARFRAC($AD9,$AU9)*12),"N/A") -> 1417.0667 | JW9: =IFERROR((YEARFRAC($AD9,$AY9)*12),"N/A") -> 1417.0667 | JX9: =IFERROR((YEARFRAC($AD9,$AZ9)*12),"N/A") -> 1417.0667 | JY9: =IFERROR((YEARFRAC($AD9,$BD9)*12),"N/A") -> 1417.0667 | JZ9: =IFERROR((YEARFRAC($AD9,$BE9)*12),"N/A") -> 1417.0667 | KA9: =IFERROR((YEARFRAC($AD9,$BI9)*12),"N/A") -> 1417.0667 | KB9: =IFERROR((YEARFRAC($AD9,$BJ9)*12),"N/A") -> 1417.0667 | KC9: =IFERROR((YEARFRAC($AD9,$BN9)*12),"N/A") -> 1417.0667 | KD9: =IFERROR((YEARFRAC($AD9,$BO9)*12),"N/A") -> 1417.0667 | KE9: =IFERROR((YEARFRAC($AD9,$BS9)*12),"N/A") -> 1417.0667 | KF9: =IFERROR((YEARFRAC($AD9,$BT9)*12),"N/A") -> 1417.0667 | KG9: =IFERROR((YEARFRAC($AD9,$BX9)*12),"N/A") -> 1417.0667 | KH9: =IFERROR((YEARFRAC($AD9,$BY9)*12),"N/A") -> 1417.0667 | KI9: =IFERROR((YEARFRAC($AD9,$CC9)*12),"N/A") -> 1417.0667 | KJ9: =IFERROR((YEARFRAC($AD9,$CD9)*12),"N/A") -> 1417.0667 | KK9: =IFERROR((YEARFRAC($AD9,$CH9)*12),"N/A") -> 1417.0667 | KL9: =IFERROR((YEARFRAC($AD9,$CI9)*12),"N/A") -> 1417.0667 | KM9: =IFERROR((YEARFRAC($AD9,$CM9)*12),"N/A") -> 1417.0667 | KN9: =IFERROR((YEARFRAC($AD9,$CN9)*12),"N/A") -> 1417.0667 | KO9: =IFERROR((YEARFRAC($AD9,$H9)*12),"N/A") -> 2.9333333 | KP9: =IFERROR((YEARFRAC($AD9,$K9)*12),"N/A") -> N/A | KQ9: =IFERROR((YEARFRAC($AD9,$P9)*12),"N/A") -> N/A | KR9: =IFERROR((YEARFRAC($AD9,$U9)*12),"N/A") -> N/A | KS9: =IFERROR((YEARFRAC($AD9,$Z9)*12),"N/A") -> N/A | KT9: =IFERROR((YEARFRAC($AD9,$CR9)*12),"N/A") -> 1417.0667 | KU9: =IFERROR((YEARFRAC($AD9,$CS9)*12),"N/A") -> 1417.0667 | KV9: =IFERROR((YEARFRAC($AD9,$CW9)*12),"N/A") -> 1417.0667 | KW9: =IFERROR((YEARFRAC($AD9,$CX9)*12),"N/A") -> 1417.0667 | KX9: =IFERROR((YEARFRAC($AD9,$DB9)*12),"N/A") -> 1417.0667 | KY9: =IFERROR((YEARFRAC($AD9,$DC9)*12),"N/A") -> 1417.0667 | KZ9: =IFERROR((YEARFRAC($AD9,$DG9)*12),"N/A") -> 1417.0667 | LA9: =IFERROR((YEARFRAC($AD9,$DH9)*12),"N/A") -> 1417.0667 | LB9: =IFERROR((YEARFRAC($AD9,$DL9)*12),"N/A") -> 1417.0667 | LC9: =IFERROR((YEARFRAC($AD9,$DM9)*12),"N/A") -> 1417.0667 | LD9: =IFERROR((YEARFRAC($AD9,$DQ9)*12),"N/A") -> 1417.0667 | LE9: =IFERROR((YEARFRAC($AD9,$DR9)*12),"N/A") -> 1417.0667 | LF9: =IFERROR((YEARFRAC($AD9,$DV9)*12),"N/A") -> 1417.0667 | LG9: =IFERROR((YEARFRAC($AD9,$DW9)*12),"N/A") -> 1417.0667 | LH9: =IFERROR((YEARFRAC($AD9,$EA9)*12),"N/A") -> 1417.0667 | LI9: =IFERROR((YEARFRAC($AD9,$EB9)*12),"N/A") -> 1417.0667 | LJ9: =IFERROR((YEARFRAC($AD9,$EF9)*12),"N/A") -> 1417.0667 | LK9: =IFERROR((YEARFRAC($AD9,$EG9)*12),"N/A") -> 1417.0667 | LL9: =IFERROR((YEARFRAC($AD9,$EK9)*12),"N/A") -> 1417.0667 | LM9: =IFERROR((YEARFRAC($AD9,$EL9)*12),"N/A") -> 1417.0667 | LN9: =IFERROR((YEARFRAC($AD9,$EP9)*12),"N/A") -> 1417.0667 | LO9: =IFERROR((YEARFRAC($AD9,$EQ9)*12),"N/A") -> 1417.0667 | LP9: =IFERROR((YEARFRAC($AD9,$EU9)*12),"N/A") -> 1417.0667 | LQ9: =IFERROR((YEARFRAC($AD9,$EV9)*12),"N/A") -> 1417.0667 | LR9: =IFERROR((YEARFRAC($AD9,$EZ9)*12),"N/A") -> 1417.0667 | LS9: =IFERROR((YEARFRAC($AD9,$FA9)*12),"N/A") -> 1417.0667 | LT9: =IFERROR((YEARFRAC($AD9,$EE9)*12),"N/A") -> 1417.0667 | LU9: =IFERROR((YEARFRAC($AD9,$EF9)*12),"N/A") -> 1417.0667 | LV9: =IFERROR((YEARFRAC($AD9,$FJ9)*12),"N/A") -> 1417.0667 | LW9: =IFERROR((YEARFRAC($AD9,$FK9)*12),"N/A") -> 1417.0667 | LX9: =IFERROR((YEARFRAC($AD9,$FL9)*12),"N/A") -> 1417.0667 | LY9: =IFERROR((YEARFRAC($AD9,$FN9)*12),"N/A") -> 1417.0667 | LZ9: =IFERROR((YEARFRAC($AD9,$FP9)*12),"N/A") -> 1417.0667 | MA9: =IFERROR((YEARFRAC($AD9,$FR9)*12),"N/A") -> 1417.0667 | MB9: =IFERROR((YEARFRAC($AD9,$FT9)*12),"N/A") -> 1417.0667 | MC9: =IFERROR((YEARFRAC($AD9,$FV9)*12),"N/A") -> 1417.0667 | MD9: =IFERROR((YEARFRAC($AD9,$FX9)*12),"N/A") -> 1417.0667 | ME9: =IFERROR((YEARFRAC($AD9,$FZ9)*12),"N/A") -> 1417.0667 | MF9: =IFERROR((YEARFRAC($AD9,$GB9)*12),"N/A") -> 1417.0667 | MG9: =IFERROR((YEARFRAC($AD9,$GD9)*12),"N/A") -> 1417.0667 | MH9: =IFERROR((YEARFRAC($AD9,$GF9)*12),"N/A") -> 1417.0667 | MI9: =IFERROR((YEARFRAC($AD9,$GH9)*12),"N/A") -> 1417.0667 | MJ9: =IFERROR((YEARFRAC($AD9,$GJ9)*12),"N/A") -> 1417.0667 | MK9: =IFERROR((YEARFRAC($AD9,$GL9)*12),"N/A") -> 1417.0667 | ML9: =IFERROR((YEARFRAC($AD9,$GN9)*12),"N/A") -> 1417.0667 | MM9: =IFERROR((YEARFRAC($AD9,$GR9)*12),"N/A") -> 1417.0667 | MN9: =IFERROR((YEARFRAC($AD9,$GS9)*12),"N/A") -> 1417.0667 | MO9: =IFERROR((YEARFRAC($AD9,$GW9)*12),"N/A") -> 1417.0667 | MP9: =IFERROR((YEARFRAC($AD9,$GX9)*12),"N/A") -> 1417.0667 | MQ9: =IFERROR((YEARFRAC($AD9,$HB9)*12),"N/A") -> 1417.0667 | MR9: =IFERROR((YEARFRAC($AD9,$HC9)*12),"N/A") -> 1417.0667 | MS9: =IFERROR((YEARFRAC($AD9,$HG9)*12),"N/A") -> 1417.0667 | MT9: =IFERROR((YEARFRAC($AD9,$HH9)*12),"N/A") -> 1417.0667 | MU9: =IFERROR((YEARFRAC($AD9,$HL9)*12),"N/A") -> 1417.0667 | MV9: =IFERROR((YEARFRAC($AD9,$HM9)*12),"N/A") -> 1417.0667 | MW9: =IFERROR((YEARFRAC($AD9,$HQ9)*12),"N/A") -> 1417.0667 | MX9: =IFERROR((YEARFRAC($AD9,$HR9)*12),"N/A") -> 1417.0667 | MY9: =IFERROR((YEARFRAC($AD9,$HV9)*12),"N/A") -> 1417.0667 | MZ9: =IFERROR((YEARFRAC($AD9,$HW9)*12),"N/A") -> 1417.0667 | NA9: =IFERROR((YEARFRAC($AD9,$IA9)*12),"N/A") -> 1417.0667 | NB9: =IFERROR((YEARFRAC($AD9,$IB9)*12),"N/A") -> 1417.0667 | NC9: =IFERROR((YEARFRAC($AD9,$IF9)*12),"N/A") -> 1417.0667 | ND9: =IFERROR((YEARFRAC($AD9,$IG9)*12),"N/A") -> 1417.0667 | NE9: =IFERROR((YEARFRAC($AD9,$IK9)*12),"N/A") -> 1417.0667 | NF9: =IFERROR((YEARFRAC($AD9,$IL9)*12),"N/A") -> 1417.0667 | NG9: =IFERROR((YEARFRAC($AD9,$IP9)*12),"N/A") -> 1417.0667 | NH9: =IFERROR((YEARFRAC($AD9,$IQ9)*12),"N/A") -> 1417.0667 | NI9: =IFERROR((YEARFRAC($AD9,$IU9)*12),"N/A") -> 1417.0667 | NJ9: =IFERROR((YEARFRAC($AD9,$IV9)*12),"N/A") -> 1417.0667 | NK9: =IFERROR((YEARFRAC($AD9,$IZ9)*12),"N/A") -> 1417.0667 | NL9: =IFERROR((YEARFRAC($AD9,$JA9)*12),"N/A") -> 1417.0667 | NM9: =IFERROR((YEARFRAC($AD9,$JE9)*12),"N/A") -> 1417.0667 | NN9: =IFERROR((YEARFRAC($AD9,$JF9)*12),"N/A") -> 1417.0667 | NO9: =IFERROR((YEARFRAC($AD9,$JJ9)*12),"N/A") -> 1417.0667 | NP9: =IFERROR((YEARFRAC($AD9,$JK9)*12),"N/A") -> 1417.0667 | NQ9: =$LX9 -> 1417.0667 | NR9: =IFERROR((YEARFRAC($AD9,$JN9)*12),"N/A") -> 1417.0667 | NS9: =IFERROR((YEARFRAC($AD9,$JQ9)*12),"N/A") -> 1417.0667 | NT9: =IFERROR((YEARFRAC($AD9,$JR9)*12),"N/A") -> 1417.0667 | NU9: =SUM($NR9,$NT9) -> 2834.1333 | NV9: {=INDEX($NQ9:$NS9,MATCH(TRUE,INDEX(ISNUMBER($NQ9:$NS9),0),0))} -> 1417.0667 | NW9: =IF($NQ9="N/A",0,1) -> 1 | NX9: =IF($JO9="Yes",1,0) -> 0 | NY9: =IF($NR9="N/A",0,1) -> 1 | NZ9: =IF(OR($NW9=1,$NX9=1),"1","0") -> 1
A10: 4582887899 | B10: No | C10: Treatment naïve | D10: No | E10: LH19-15431 | F10: A16 | G10: A18 | H10: 43560 | I10: Total Robotic Hysterectomy/Bilateral salpingo-oophorectomy/Pelvic Lymphadenectomy | J10: Uterine corpus | K10: N/A | L10: N/A | M10: N/A | N10: N/A | O10: N/A | P10: N/A | Q10: N/A | R10: N/A | S10: N/A | T10: N/A | U10: N/A | V10: N/A | W10: N/A | X10: N/A | Y10: N/A | Z10: N/A | AA10: N/A | AB10: F | AC10: 21867 | AD10: 43515 | AE10: =DATEDIF(AC10, AD10,"Y") -> 59 | AF10: Endometrioid carcinoma | AG10: Specimen | AH10: Yes | AI10: NR | AJ10: 1 | AK10: NR | AL10: 0 | AM10: N/A | AN10: 2 | AO10: N/A
A11: 4862084389 | B11: No | C11: Treatment naïve | D11: No | E11: LH19-26760 | F11: A10(L) | G11: A12(L) | H11: 43636 | I11: Total Laparoscopic Hysterectomy; Bilateral Salpingo-oophorectomy; Bilateral Pelvic Node Sampling; Peritoneal washings | J11: Uterine corpus | K11: N/A | L11: N/A | M11: N/A | N11: N/A | O11: N/A | P11: N/A | Q11: N/A | R11: N/A | S11: N/A | T11: N/A | U11: N/A | V11: N/A | W11: N/A | X11: N/A | Y11: N/A | Z11: N/A | AA11: N/A | AB11: F | AC11: 23329 | AD11: 43566 | AE11: =DATEDIF(AC11, AD11,"Y") -> 55 | AF11: Endometrioid adenocarcinoma | AG11: Specimen | AH11: Yes | AI11: 1B | AJ11: 0 | AK11: NR | AL11: 0 | AM11: T1BN0M0 | AN11: 1 | AO11: N/A
A12: 4505997235 | B12: No | C12: Treatment naïve | D12: No | E12: LH19-26931 | F12: A12 | G12: N/A | H12: 43637 | I12: Total laparoscopic hysterectomy/Bilateral salpingo-oophorectomy | J12: Uterine corpus | K12: N/A | L12: N/A | M12: N/A | N12: N/A | O12: N/A | P12: N/A | Q12: N/A | R12: N/A | S12: N/A | T12: N/A | U12: N/A | V12: N/A | W12: N/A | X12: N/A | Y12: N/A | Z12: N/A | AA12: N/A | AB12: F | AC12: 21498 | AD12: 43598 | AE12: =DATEDIF(AC12, AD12,"Y") -> 60 | AF12: Endometrioid adenocarcinoma | AG12: Specimen | AH12: Yes | AI12: 1A | AJ12: NR | AK12: NR | AL12: 0 | AM12: T1AN0M0 | AN12: 1 | AO12: N/A
A13: 4800798418 | B13: No | C13: Treatment naïve | D13: No | E13: LH19-34016 | F13: A15 | G13: A12 | H13: 43683 | I13: Total abdominal hysterectomy, Bilateral salpingo-ophorectomy, Omentectomy, Pelvic lymph node sampling, Paraaortic lymph node sampling | J13: Uterine corpus | K13: N/A | L13: N/A | M13: N/A | N13: N/A | O13: N/A | P13: N/A | Q13: N/A | R13: N/A | S13: N/A | T13: N/A | U13: N/A | V13: N/A | W13: N/A | X13: N/A | Y13: N/A | Z13: N/A | AA13: N/A | AB13: F | AC13: 22802 | AD13: 43696 | AE13: =DATEDIF(AC13, AD13,"Y") -> 57 | AF13: Endometrioid adenocarcinoma | AG13: Specimen | AH13: Yes | AI13: 3A | AJ13: 0 | AK13: NR | AL13: 0 | AM13: T3AN0M0 | AN13: 1 | AO13: N/A
A14: 4860443551 | B14: No | C14: Treatment naïve | D14: No | E14: LH19-34659 | F14: A8 | G14: A7 | H14: 43686 | I14: Total robotic hysterectomy, bilateral salpingo-oophorectomy and bilateral pelvic lymphadenectomy | J14: Uterine corpus | K14: N/A | L14: N/A | M14: N/A | N14: N/A | O14: N/A | P14: N/A | Q14: N/A | R14: N/A | S14: N/A | T14: N/A | U14: N/A | V14: N/A | W14: N/A | X14: N/A | Y14: N/A | Z14: N/A | AA14: N/A | AB14: F | AC14: 21371 | AD14: 43668 | AE14: =DATEDIF(AC14, AD14,"Y") -> 61 | AF14: Endometrioid adenocarcinoma | AG14: Specimen | AH14: No | AI14: 1B | AJ14: 0 | AK14: NR | AL14: 0 | AM14: T1BN0M0 | AN14: 3 | AO14: N/A
A15: 6163514831 | B15: No | C15: Treatment naïve | D15: No | E15: LH19-47908 | F15: A15 | G15: A10 | H15: 43773 | I15: Total laparoscopic hysterectomy, bilateral salpingo-oophorectomy and bilateral pelvic lymphadenectomy | J15: Uterine corpus | K15: N/A | L15: N/A | M15: N/A | N15: N/A | O15: N/A | P15: N/A | Q15: N/A | R15: N/A | S15: N/A | T15: N/A | U15: N/A | V15: N/A | W15: N/A | X15: N/A | Y15: N/A | Z15: N/A | AA15: N/A | AB15: F | AC15: 16253 | AD15: 43739 | AE15: =DATEDIF(AC15, AD15,"Y") -> 75 | AF15: Endometrioid adenocarcinoma | AG15: Specimen | AH15: Yes | AI15: 2 | AJ15: 0 | AK15: NR | AL15: 0 | AM15: T2N0M0 | AN15: 3 | AO15: N/A
A16: 4807687875 | B16: No | C16: Treatment naïve | D16: No | E16: LH19-50535 | F16: A14(L) | G16: N/A | H16: 43788 | I16: Total laparoscopic hysterectomy/Bilateral salpingo-oophorectomy | J16: Uterine corpus | K16: N/A | L16: N/A | M16: N/A | N16: N/A | O16: N/A | P16: N/A | Q16: N/A | R16: N/A | S16: N/A | T16: N/A | U16: N/A | V16: N/A | W16: N/A | X16: N/A | Y16: N/A | Z16: N/A | AA16: N/A | AB16: F | AC16: 23149 | AD16: 43739 | AE16: =DATEDIF(AC16, AD16,"Y") -> 56 | AF16: Endometrioid adenocarcinoma | AG16: Specimen | AH16: Yes | AI16: 1A | AJ16: NR | AK16: NR | AL16: 0 | AM16: T1AN0M0 | AN16: 1 | AO16: N/A
A17: 4109356563 | B17: No | C17: Treatment naïve | D17: No | E17: LH19-55935 | F17: A6 | G17: A5 | H17: 43819 | I17: Laparotomy/Total abdominal hysterectomy/Bilateral salpingo-oophorectomy/Omentectomy/Pelvic and para-aortic lymphadenectomy | J17: Uterine corpus | K17: N/A | L17: N/A | M17: N/A | N17: N/A | O17: N/A | P17: N/A | Q17: N/A | R17: N/A | S17: N/A | T17: N/A | U17: N/A | V17: N/A | W17: N/A | X17: N/A | Y17: N/A | Z17: N/A | AA17: N/A | AB17: F | AC17: 24603 | AD17: 43788 | AE17: =DATEDIF(AC17, AD17,"Y") -> 52 | AF17: Endometrioid adenocarcinoma | AG17: Specimen | AH17: Yes | AI17: NR | AJ17: 2 | AK17: NR | AL17: 0 | AM17: N/A | AN17: 3 | AO17: N/A
A18: 6289334077 | B18: No | C18: Treatment naïve | D18: No | E18: LH20-05949 | F18: A7 | G18: A17 | H18: 43867 | I18: Total laparoscopic hysterectomy/Bilateral salpingo-oophorectomy | J18: Uterine corpus | K18: N/A | L18: N/A | M18: N/A | N18: N/A | O18: N/A | P18: N/A | Q18: N/A | R18: N/A | S18: N/A | T18: N/A | U18: N/A | V18: N/A | W18: N/A | X18: N/A | Y18: N/A | Z18: N/A | AA18: N/A | AB18: F | AC18: 20012 | AD18: 43822 | AE18: =DATEDIF(AC18, AD18,"Y") -> 65 | AF18: Endometrioid adenocarcinoma | AG18: Specimen | AH18: Yes | AI18: 1A | AJ18: NR | AK18: NR | AL18: 0 | AM18: T1AN0M0 | AN18: 1 | AO18: N/A
A19: 4506314042 | B19: No | C19: Treatment naïve | D19: No | E19: LH20-05951 | F19: A9 | G19: A8 | H19: 43867 | I19: laparoscopically assisted total hysterectomy, bilateral salpingo-oophorectomy | J19: Uterine corpus | K19: N/A | L19: N/A | M19: N/A | N19: N/A | O19: N/A | P19: N/A | Q19: N/A | R19: N/A | S19: N/A | T19: N/A | U19: N/A | V19: N/A | W19: N/A | X19: N/A | Y19: N/A | Z19: N/A | AA19: N/A | AB19: F | AC19: 21295 | AD19: 43867 | AE19: =DATEDIF(AC19, AD19,"Y") -> 61 | AF19: Endometrioid adenocarcinoma | AG19: Specimen | AH19: Yes | AI19: 1B | AJ19: NR | AK19: NR | AL19: 0 | AM19: T1BN0M0 | AN19: 1 | AO19: N/A
A20: 4364284998 | B20: No | C20: Treatment naïve | D20: No | E20: LH20-10372 | F20: A6 | G20: A7 | H20: 43895 | I20: Total Laparoscopic Hysterectomy; Bilateral Salpingo-oophorectomy. | J20: Uterine corpus | K20: N/A | L20: N/A | M20: N/A | N20: N/A | O20: N/A | P20: N/A | Q20: N/A | R20: N/A | S20: N/A | T20: N/A | U20: N/A | V20: N/A | W20: N/A | X20: N/A | Y20: N/A | Z20: N/A | AA20: N/A | AB20: F | AC20: 13734 | AD20: 43823 | AE20: =DATEDIF(AC20, AD20,"Y") -> 82 | AF20: Endometrioid adenocarcinoma | AG20: Specimen | AH20: Yes | AI20: 2 | AJ20: NR | AK20: NR | AL20: 0 | AM20: T2N0M0 | AN20: 2 | AO20: N/A
A21: 4583302967 | B21: No | C21: Treatment naïve | D21: No | E21: LH20-10590 | F21: A17 | G21: A9 | H21: 43896 | I21: Total laparoscopic hysterectomy/Bilateral salpingo-oophorectomy | J21: Uterine corpus | K21: N/A | L21: N/A | M21: N/A | N21: N/A | O21: N/A | P21: N/A | Q21: N/A | R21: N/A | S21: N/A | T21: N/A | U21: N/A | V21: N/A | W21: N/A | X21: N/A | Y21: N/A | Z21: N/A | AA21: N/A | AB21: F | AC21: 20193 | AD21: 43864 | AE21: =DATEDIF(AC21, AD21,"Y") -> 64 | AF21: Endometrioid adenocarcinoma | AG21: Specimen | AH21: Yes | AI21: 1A | AJ21: NR | AK21: NR | AL21: 0 | AM21: T1AN0M0 | AN21: 2 | AO21: N/A
A22: 4086856999 | B22: No | C22: Treatment naïve | D22: No | E22: LH20-14746 | F22: A16 | G22: A12 | H22: 43950 | I22: Total Abdominal Hysterectomy; Bilateral Salpingo-oophorectomy; Bilateral Pelvic Node Sampling; Peritoneal washings. | J22: Uterine corpus | K22: N/A | L22: N/A | M22: N/A | N22: N/A | O22: N/A | P22: N/A | Q22: N/A | R22: N/A | S22: N/A | T22: N/A | U22: N/A | V22: N/A | W22: N/A | X22: N/A | Y22: N/A | Z22: N/A | AA22: N/A | AB22: F | AC22: 24070 | AD22: 43922 | AE22: =DATEDIF(AC22, AD22,"Y") -> 54 | AF22: Endometrioid adenocarcinoma | AG22: Specimen | AH22: NR | AI22: 2 | AJ22: 0 | AK22: NR | AL22: 0 | AM22: T2N0M0 | AN22: 2 | AO22: N/A
A23: 4087362620 | B23: No | C23: Treatment naïve | D23: No | E23: LH20-16019 | F23: A26 | G23: A15 | H23: 43978 | I23: Total laparoscopic hysterectomy/Bilateral salpingo-oophorectomy | J23: Uterine corpus | K23: N/A | L23: N/A | M23: N/A | N23: N/A | O23: N/A | P23: N/A | Q23: N/A | R23: N/A | S23: N/A | T23: N/A | U23: N/A | V23: N/A | W23: N/A | X23: N/A | Y23: N/A | Z23: N/A | AA23: N/A | AB23: F | AC23: 27734 | AD23: 43700 | AE23: =DATEDIF(AC23, AD23,"Y") -> 43 | AF23: Endometrioid adenocarcinoma | AG23: Specimen | AH23: Yes | AI23: 1A | AJ23: NR | AK23: NR | AL23: 0 | AM23: T1AN0M0 | AN23: 2 | AO23: N/A
A24: 4387969776 | B24: No | C24: Treatment naïve | D24: No | E24: LH20-20082 | F24: A10 | G24: A9 | H24: 44025 | I24: Laparoscopic converted to open Adhesiolysis/Total abdominal hysterectomy/Bilateral salpingo-oophorectomy/Pelvic lymphadenectomy/Omental biopsy | J24: Uterine corpus | K24: N/A | L24: N/A | M24: N/A | N24: N/A | O24: N/A | P24: N/A | Q24: N/A | R24: N/A | S24: N/A | T24: N/A | U24: N/A | V24: N/A | W24: N/A | X24: N/A | Y24: N/A | Z24: N/A | AA24: N/A | AB24: F | AC24: 16948 | AD24: 43990 | AE24: =DATEDIF(AC24, AD24,"Y") -> 74 | AF24: Endometrioid adenocarcinoma | AG24: Specimen | AH24: Yes | AI24: 1A | AJ24: 0 | AK24: NR | AL24: 0 | AM24: T1AN0M0 | AN24: 2 | AO24: N/A
A25: 4382038278 | B25: No | C25: Treatment naïve | D25: No | E25: LH20-24870 | F25: A12 | G25: A15 | H25: 44069 | I25: Total Abdominal Hysterectomy; Bilateral Salpingo-oophorectomy; and washings | J25: Uterine corpus | K25: N/A | L25: N/A | M25: N/A | N25: N/A | O25: N/A | P25: N/A | Q25: N/A | R25: N/A | S25: N/A | T25: N/A | U25: N/A | V25: N/A | W25: N/A | X25: N/A | Y25: N/A | Z25: N/A | AA25: N/A | AB25: F | AC25: 15672 | AD25: 44006 | AE25: =DATEDIF(AC25, AD25,"Y") -> 77 | AF25: Endometrioid adenocarcinoma | AG25: Specimen | AH25: No | AI25: 1B | AJ25: NR | AK25: NR | AL25: 0 | AM25: T1BN0M0 | AN25: 1 | AO25: N/A
A26: 4508985181 | B26: No | C26: Treatment naïve | D26: No | E26: LH20-27121 | F26: A13 | G26: A15 | H26: 44090 | I26: Total laparoscopic hysterectomy, bilateral salpingo-oophorectomy and bilateral pelvic lymphadenectomy | J26: Uterine corpus | K26: N/A | L26: N/A | M26: N/A | N26: N/A | O26: N/A | P26: N/A | Q26: N/A | R26: N/A | S26: N/A | T26: N/A | U26: N/A | V26: N/A | W26: N/A | X26: N/A | Y26: N/A | Z26: N/A | AA26: N/A | AB26: F | AC26: 17760 | AD26: 44041 | AE26: =DATEDIF(AC26, AD26,"Y") -> 71 | AF26: Endometrioid adenocarcinoma | AG26: Specimen | AH26: Yes | AI26: 1B | AJ26: 0 | AK26: NR | AL26: 0 | AM26: T1BN0M0 | AN26: 1 | AO26: N/A
A27: 4581844045 | B27: No | C27: Treatment naïve | D27: No | E27: LH20-29696 | F27: A21 | G27: A18 | H27: 44110 | I27: TAH, BSO, Omentectomy, Pelvic and para-aortal LND | J27: Uterine corpus | K27: N/A | L27: N/A | M27: N/A | N27: N/A | O27: N/A | P27: N/A | Q27: N/A | R27: N/A | S27: N/A | T27: N/A | U27: N/A | V27: N/A | W27: N/A | X27: N/A | Y27: N/A | Z27: N/A | AA27: N/A | AB27: F | AC27: 19269 | AD27: 44056 | AE27: =DATEDIF(AC27, AD27,"Y") -> 67 | AF27: Endometrioid adenocarcinoma | AG27: Specimen | AH27: Yes | AI27: NR | AJ27: 1 | AK27: NR | AL27: 0 | AM27: N/A | AN27: 2 | AO27: N/A
A28: 4125738122 | B28: No | C28: Treatment naïve | D28: No | E28: LH20-30294 | F28: A7 | G28: A8 | H28: 44116 | I28: Total laparoscopic hysterectomy, bilateral salpingo-oophorectomy and bilateral pelvic lymphadenectomy with adhesiolysis | J28: Uterine corpus | K28: N/A | L28: N/A | M28: N/A | N28: N/A | O28: N/A | P28: N/A | Q28: N/A | R28: N/A | S28: N/A | T28: N/A | U28: N/A | V28: N/A | W28: N/A | X28: N/A | Y28: N/A | Z28: N/A | AA28: N/A | AB28: F | AC28: 25385 | AD28: 44081 | AE28: =DATEDIF(AC28, AD28,"Y") -> 51 | AF28: Endometrioid adenocarcinoma | AG28: Specimen | AH28: Yes | AI28: 1A | AJ28: 0 | AK28: NR | AL28: 0 | AM28: T1AN0M0 | AN28: 2 | AO28: N/A
A29: 4083306041 | B29: No | C29: Treatment naïve | D29: No | E29: LH21-05633 | F29: A8 | G29: N/A | H29: 44243 | I29: Laparotomy, total abdominal hysterectomy, bilateral salpingo-oophorectomy, pelvic lymphadenectomy, para-aortic lymph node sampling, infracolic omentectomy | J29: Uterine corpus | K29: N/A | L29: N/A | M29: LH21-05633 | N29: A12 | O29: R Ovary | P29: 44243 | Q29: Treatment naïve | R29: N/A | S29: N/A | T29: N/A | U29: N/A | V29: N/A | W29: N/A | X29: N/A | Y29: N/A | Z29: N/A | AA29: N/A | AB29: F | AC29: 30498 | AD29: 44203 | AE29: =DATEDIF(AC29, AD29,"Y") -> 37 | AF29: Endometrioid carcinoma | AG29: Specimen | AH29: Yes | AI29: 3A | AJ29: 0 | AK29: NR | AL29: 0 | AM29: T3AN0M0 | AN29: 1 | AO29: N/A
A30: 4124649371 | B30: No | C30: Treatment naïve | D30: No | E30: LH21-05989 | F30: A8 | G30: A6 | H30: 44245 | I30: Total Abdominal Hysterectomy; Bilateral Salpingo-oophorectomy; Bilateral Pelvic and Para-aortic Node sampling; Infracolic Omental Biopsy; Peritoneal Washings; Insertion of On-Q pain catheters. | J30: Uterine corpus | K30: N/A | L30: N/A | M30: N/A | N30: N/A | O30: N/A | P30: N/A | Q30: N/A | R30: N/A | S30: N/A | T30: N/A | U30: N/A | V30: N/A | W30: N/A | X30: N/A | Y30: N/A | Z30: N/A | AA30: N/A | AB30: F | AC30: 27482 | AD30: 44188 | AE30: =DATEDIF(AC30, AD30,"Y") -> 45 | AF30: Endometrioid carcinoma | AG30: Specimen | AH30: Yes | AI30: 1A | AJ30: 0 | AK30: NR | AL30: 0 | AM30: T1AN0M0 | AN30: 3 | AO30: N/A
A31: 4382721598 | B31: No | C31: Treatment naïve | D31: No | E31: LH21-09144 | F31: A7 | G31: A10 | H31: 44270 | I31: Laparotomy with total abdominal hysterectomy, bilateral salpingo-oophorectomy, infracolic omentectomy, bilateral pelvic lymphadenectomy and para-aortic lymph node sampling | J31: Uterine corpus | K31: N/A | L31: N/A | M31: N/A | N31: N/A | O31: N/A | P31: N/A | Q31: N/A | R31: N/A | S31: N/A | T31: N/A | U31: N/A | V31: N/A | W31: N/A | X31: N/A | Y31: N/A | Z31: N/A | AA31: N/A | AB31: F | AC31: 17341 | AD31: 44244 | AE31: =DATEDIF(AC31, AD31,"Y") -> 73 | AF31: Endometrioid carcinoma | AG31: Specimen | AH31: No | AI31: 1B | AJ31: 0 | AK31: NR | AL31: 0 | AM31: T1BN0M0 | AN31: 2 | AO31: N/A
A32: 4861789648 | B32: No | C32: Treatment naïve | D32: No | E32: LH21-10715 | F32: A5 | G32: A6 | H32: 44280 | I32: Total laparoscopic hysterectomy, bilateral salpingo-oophorectomy | J32: Uterine corpus | K32: N/A | L32: N/A | M32: N/A | N32: N/A | O32: N/A | P32: N/A | Q32: N/A | R32: N/A | S32: N/A | T32: N/A | U32: N/A | V32: N/A | W32: N/A | X32: N/A | Y32: N/A | Z32: N/A | AA32: N/A | AB32: F | AC32: 22505 | AD32: 44123 | AE32: =DATEDIF(AC32, AD32,"Y") -> 59 | AF32: Endometrioid carcinoma | AG32: Specimen | AH32: Yes | AI32: 1A | AJ32: NR | AK32: NR | AL32: 0 | AM32: T1AN0M0 | AN32: 1 | AO32: N/A
A33: 4848989531 | B33: No | C33: Treatment naïve | D33: No | E33: LH21-16894 | F33: A19 | G33: A21 | H33: 44322 | I33: Total laparoscopic hysterectomy, bilateral salpingo-oophorectomy | J33: Uterine corpus | K33: N/A | L33: N/A | M33: N/A | N33: N/A | O33: N/A | P33: N/A | Q33: N/A | R33: N/A | S33: N/A | T33: N/A | U33: N/A | V33: N/A | W33: N/A | X33: N/A | Y33: N/A | Z33: N/A | AA33: N/A | AB33: F | AC33: 21894 | AD33: 44273 | AE33: =DATEDIF(AC33, AD33,"Y") -> 61 | AF33: Endometrioid carcinoma | AG33: Specimen | AH33: Yes | AI33: 1B | AJ33: NR | AK33: NR | AL33: 0 | AM33: T1BN0M0 | AN33: 1 | AO33: N/A
A34: 6145366486 | B34: No | C34: Treatment naïve | D34: No | E34: LH21-18821 | F34: A13 | G34: A10 | H34: 44336 | I34: Total laparoscopic hysterectomy, bilateral salpingo-oophorectomy, pelvic lymphadenectomy | J34: Uterine corpus | K34: N/A | L34: N/A | M34: N/A | N34: N/A | O34: N/A | P34: N/A | Q34: N/A | R34: N/A | S34: N/A | T34: N/A | U34: N/A | V34: N/A | W34: N/A | X34: N/A | Y34: N/A | Z34: N/A | AA34: N/A | AB34: F | AC34: 27990 | AD34: 44250 | AE34: =DATEDIF(AC34, AD34,"Y") -> 44 | AF34: Endometrioid carcinoma | AG34: Specimen | AH34: Yes | AI34: 3A | AJ34: 0 | AK34: NR | AL34: 0 | AM34: T3AN0M0 | AN34: 2 | AO34: N/A
A35: 4861720087 | B35: No | C35: Treatment naïve | D35: No | E35: LH21-25455 | F35: A15 | G35: A20 | H35: 44384 | I35: Staging TAH, BSO, Lymphadenectomy, infracolic omentectomy, excision hernia, washings | J35: Uterine corpus | K35: N/A | L35: N/A | M35: N/A | N35: N/A | O35: N/A | P35: N/A | Q35: N/A | R35: N/A | S35: N/A | T35: N/A | U35: N/A | V35: N/A | W35: N/A | X35: N/A | Y35: N/A | Z35: N/A | AA35: N/A | AB35: F | AC35: 21798 | AD35: 44320 | AE35: =DATEDIF(AC35, AD35,"Y") -> 61 | AF35: Endometrioid carcinoma | AG35: Specimen | AH35: Yes | AI35: 2 | AJ35: 0 | AK35: NR | AL35: 0 | AM35: T2N0M0 | AN35: 1 | AO35: N/A
A36: 6327986404 | B36: No | C36: Treatment naïve | D36: No | E36: LH21-32594 | F36: A3 | G36: N/A | H36: 44439 | I36: Interval debulking surgery, TAH, BSO, Omentectomy, Bladder peritoneum biopsy | J36: Endometrial polyp | K36: N/A | L36: N/A | M36: N/A | N36: N/A | O36: N/A | P36: N/A | Q36: N/A | R36: N/A | S36: N/A | T36: N/A | U36: N/A | V36: N/A | W36: N/A | X36: N/A | Y36: N/A | Z36: N/A | AA36: N/A | AB36: F | AC36: 17463 | AD36: 44348 | AE36: =DATEDIF(AC36, AD36,"Y") -> 73 | AF36: Endometrioid carcinoma | AG36: Specimen | AH36: Yes | AI36: 1A | AJ36: 0 | AK36: NR | AL36: 0 | AM36: T1AN0M0 | AN36: 1 | AO36: N/A | JT36: Synchronous stage IVB low grade serous ovarian cancer; patient treated with 3 cycles carboplatin plus paclitaxel prior to interval debulking surgery
A37: 4087924513 | B37: No | C37: Immunotherapy naïve | D37: No | E37: LH21-34655 | F37: A1 | G37: N/A | H37: 44454 | I37: Total Abdominal Hysterectomy; Bilateral Salpingo-oophorectomy; Supracolic Omentectomy; Appendicectomy; Peritoneal Biopsies; Removal of Portec drain Left side of abdomen. | J37: Uterine corpus | K37: N/A | L37: N/A | M37: LH21-34655 | N37: B15 | O37: Ovary | P37: 44454 | Q37: Immunotherapy naïve | R37: N/A | S37: N/A | T37: N/A | U37: N/A | V37: N/A | W37: N/A | X37: N/A | Y37: N/A | Z37: N/A | AA37: N/A | AB37: F | AC37: 24683 | AD37: 44215 | AE37: =DATEDIF(AC37, AD37,"Y") -> 53 | AF37: Endometrioid carcinoma with prominent mucinous metaplasia | AG37: Specimen | AH37: No | AI37: 3B | AJ37: NR | AK37: NR | AL37: 0 | AM37: T3BN0M0 | AN37: 2 | AO37: N/A
A38: 6163529707 | B38: No | C38: Treatment naïve | D38: No | E38: LH21-36998 | F38: A5 | G38: A12 | H38: 44470 | I38: Robotic hysterectomy, RSO and pelvic lymphadenectomy | J38: Uterine corpus | K38: N/A | L38: N/A | M38: N/A | N38: N/A | O38: N/A | P38: N/A | Q38: N/A | R38: N/A | S38: N/A | T38: N/A | U38: N/A | V38: N/A | W38: N/A | X38: N/A | Y38: N/A | Z38: N/A | AA38: N/A | AB38: F | AC38: 16431 | AD38: 44435 | AE38: =DATEDIF(AC38, AD38,"Y") -> 76 | AF38: Endometrioid carcinoma | AG38: Specimen | AH38: Yes | AI38: 1B | AJ38: 0 | AK38: NR | AL38: 0 | AM38: T1BN0M0 | AN38: 2 | AO38: N/A
A39: 4861644011 | B39: No | C39: Treatment naïve | D39: No | E39: LH21-42424 | F39: A17(L) | G39: A15 | H39: 44510 | I39: Lap Total Abdominal Hysterectomy; Bilateral Salpingo-oophorectomy | J39: Uterine corpus | K39: N/A | L39: N/A | M39: N/A | N39: N/A | O39: N/A | P39: N/A | Q39: N/A | R39: N/A | S39: N/A | T39: N/A | U39: N/A | V39: N/A | W39: N/A | X39: N/A | Y39: N/A | Z39: N/A | AA39: N/A | AB39: F | AC39: 21539 | AD39: 44461 | AE39: =DATEDIF(AC39, AD39,"Y") -> 62 | AF39: Endometrioid adenocarcinoma | AG39: Specimen | AH39: NR | AI39: 1B | AJ39: 0 | AK39: NR | AL39: 0 | AM39: T1BN0M0 | AN39: 1 | AO39: N/A
A40: 4584217416 | B40: No | C40: Treatment naïve | D40: No | E40: LH21-43784 | F40: A16 | G40: A14 | H40: 44487 | I40: Total laparoscopic hysterectomy, bilateral salpingo-oophorectomy, | J40: Uterine corpus | K40: N/A | L40: N/A | M40: N/A | N40: N/A | O40: N/A | P40: N/A | Q40: N/A | R40: N/A | S40: N/A | T40: N/A | U40: N/A | V40: N/A | W40: N/A | X40: N/A | Y40: N/A | Z40: N/A | AA40: N/A | AB40: F | AC40: 21012 | AD40: 44442 | AE40: =DATEDIF(AC40, AD40,"Y") -> 64 | AF40: Endometrioid adenocarcinoma | AG40: Specimen | AH40: Yes | AI40: 1A | AJ40: 0 | AK40: NR | AL40: 0 | AM40: T1AN0M0 | AN40: 2 | AO40: N/A
...

Sheet Proficient anonymized
A1: Donor ID | B1: Any Immunotherapy | C1: Specimen treatment subgrouping | D1: Specimen is a recurrence | E1: Selected specimen Anonymised ID | F1: Specimen Block number 1 | G1: Specimen Block number 2 | H1: Specimen surgery date | I1: Specimen surgery | J1: Specimen tumour site | K1: Primary Surgery date | L1: Primary tumour site | M1: Anonymized ID Matched met 1 | N1: Matched met 1 Block Number | O1: Matched met 1 Site | P1: Matched met 1 Surgery Date | Q1: Matched met 1 treatment subgrouping | R1: Anonymized ID Matched met 2 | S1: Matched met 2 Block Number | T1: Matched met 2 Site | U1: Matched met 2 Surgery Date | V1: Matched met 2 treatment subgrouping | W1: Anonymized ID Normal tissue | X1: Matched Normal tissue Block Number | Y1: Matched Normal tissue Site | Z1: Matched Normal tissue Surgery Date | AA1: Matched Normal treatment subgrouping | AB1: Gender | AC1: Date of DX | AD1: Age at Diagnosis | AE1: Specimen Histological Diagnosis | AF1: Staging/grading info provided for: | AG1: Resection margins clear | AH1: pT | AI1: pN | AJ1: pM | AK1: cM | AL1: TNM stage | AM1: Grade | AN1: Stage at DX (AJCC) | AO1: Comments from clinical team
A2: LDS0002771 | B2: No | C2: Treatment naïve | D2: No | E2: LH15-23319 | F2: C10 | G2: C7 | H2: =IFERROR("Q" &INT((MONTH('MMR proficient'!H4)+2)/3) & "-" & YEAR('MMR proficient'!H4),"N/A") -> Q2-2015 | I2: Laparotomy with total abdominal hysterectomy, bilateral salpingo-oophorectomy, peritoneal washings and bilateral pelvic lymphadenectomy | J2: Uterine corpus | K2: N/A | L2: N/A | M2: N/A | N2: N/A | O2: N/A | P2: =IFERROR("Q" &INT((MONTH('MMR proficient'!P4)+2)/3) & "-" & YEAR('MMR proficient'!P4),"N/A") -> N/A | Q2: N/A | R2: N/A | S2: N/A | T2: N/A | U2: N/A | V2: N/A | W2: N/A | X2: N/A | Y2: N/A | Z2: N/A | AA2: N/A | AB2: F | AC2: =IFERROR("Q" &INT((MONTH('MMR proficient'!AD4)+2)/3) & "-" & YEAR('MMR proficient'!AD4),"N/A") -> Q2-2015 | AD2: 52 | AE2: Endometrioid adenocarcinoma | AF2: Specimen | AG2: Yes | AH2: 1A | AI2: 0 | AJ2: NR | AK2: 0 | AL2: T1AN0M0 | AM2: 2 | AN2: N/A | AO2: N/A
A3: LDS0002772 | B3: No | C3: Treatment naïve | D3: No | E3: LH16-14222 | F3: A4 | G3: A11 | H3: =IFERROR("Q" &INT((MONTH('MMR proficient'!H5)+2)/3) & "-" & YEAR('MMR proficient'!H5),"N/A") -> Q2-2016 | I3: Laparotomy with total abdominal hysterectomy, bilateral salpingo-oophorectomy, supracolic omentectomy, bilateral pelvic lymphadenectomy and para-aortic lymph node sampling | J3: Uterine corpus | K3: N/A | L3: N/A | M3: N/A | N3: N/A | O3: N/A | P3: =IFERROR("Q" &INT((MONTH('MMR proficient'!P5)+2)/3) & "-" & YEAR('MMR proficient'!P5),"N/A") -> N/A | Q3: N/A | R3: N/A | S3: N/A | T3: N/A | U3: N/A | V3: N/A | W3: N/A | X3: N/A | Y3: N/A | Z3: N/A | AA3: N/A | AB3: F | AC3: =IFERROR("Q" &INT((MONTH('MMR proficient'!AD5)+2)/3) & "-" & YEAR('MMR proficient'!AD5),"N/A") -> Q1-2016 | AD3: 51 | AE3: Endometrioid adenocarcinoma | AF3: Specimen | AG3: NR | AH3: 3B | AI3: 0 | AJ3: NR | AK3: 0 | AL3: T3BN0M0 | AM3: 1 | AN3: N/A | AO3: Synchronous IIA endometrioid adenocarcinoma in ovary (grade 1)
A4: LDS0002773 | B4: No | C4: Treatment naïve | D4: No | E4: LH17-12064 | F4: A8 | G4: A9 | H4: =IFERROR("Q" &INT((MONTH('MMR proficient'!H6)+2)/3) & "-" & YEAR('MMR proficient'!H6),"N/A") -> Q1-2017 | I4: Total laparoscopic hysterectomy, bilateral salpingo-oophorectomy, adhesiolysis, peritoneal washings and bilateral pelvic lymphadenectomy | J4: Uterine corpus | K4: N/A | L4: N/A | M4: N/A | N4: N/A | O4: N/A | P4: =IFERROR("Q" &INT((MONTH('MMR proficient'!P6)+2)/3) & "-" & YEAR('MMR proficient'!P6),"N/A") -> N/A | Q4: N/A | R4: N/A | S4: N/A | T4: N/A | U4: N/A | V4: N/A | W4: N/A | X4: N/A | Y4: N/A | Z4: N/A | AA4: N/A | AB4: F | AC4: =IFERROR("Q" &INT((MONTH('MMR proficient'!AD6)+2)/3) & "-" & YEAR('MMR proficient'!AD6),"N/A") -> Q1-2017 | AD4: 80 | AE4: Endometrioid adenocarcinoma | AF4: Specimen | AG4: Yes | AH4: 1B | AI4: 0 | AJ4: NR | AK4: 0 | AL4: T1BN0M0 | AM4: 1 | AN4: N/A | AO4: N/A
A5: LDS0002774 | B5: No | C5: Treatment naïve | D5: No | E5: LH17-18561 | F5: A8 | G5: A4 | H5: =IFERROR("Q" &INT((MONTH('MMR proficient'!H7)+2)/3) & "-" & YEAR('MMR proficient'!H7),"N/A") -> Q2-2017 | I5: Adhesiolysis, Total laparoscopic hysterectomy, bilateral salpingo-oophorectomy, pelvic lymphnode dissection, Para-aortal lymphnode dissection, paracaval lymphnode sampling | J5: Cervix, upper endocervical canal (tumour arising in lower uterine segment) | K5: N/A | L5: N/A | M5: N/A | N5: N/A | O5: N/A | P5: =IFERROR("Q" &INT((MONTH('MMR proficient'!P7)+2)/3) & "-" & YEAR('MMR proficient'!P7),"N/A") -> N/A | Q5: N/A | R5: N/A | S5: N/A | T5: N/A | U5: N/A | V5: N/A | W5: N/A | X5: N/A | Y5: N/A | Z5: N/A | AA5: N/A | AB5: F | AC5: =IFERROR("Q" &INT((MONTH('MMR proficient'!AD7)+2)/3) & "-" & YEAR('MMR proficient'!AD7),"N/A") -> Q1-2017 | AD5: 53 | AE5: Endometrioid adenocarcinoma | AF5: Specimen | AG5: Yes | AH5: 2 | AI5: 0 | AJ5: NR | AK5: 0 | AL5: T2N0M0 | AM5: 2 | AN5: N/A | AO5: N/A
A6: LDS0002775 | B6: No | C6: Treatment naïve | D6: No | E6: LH17-31445 | F6: A5 | G6: A6 | H6: =IFERROR("Q" &INT((MONTH('MMR proficient'!H8)+2)/3) & "-" & YEAR('MMR proficient'!H8),"N/A") -> Q3-2017 | I6: Total laparoscopic hysterectomy, bilateral salpingo-oophorectomy, adhesiolysis | J6: Uterine corpus | K6: N/A | L6: N/A | M6: N/A | N6: N/A | O6: N/A | P6: =IFERROR("Q" &INT((MONTH('MMR proficient'!P8)+2)/3) & "-" & YEAR('MMR proficient'!P8),"N/A") -> N/A | Q6: N/A | R6: N/A | S6: N/A | T6: N/A | U6: N/A | V6: N/A | W6: N/A | X6: N/A | Y6: N/A | Z6: N/A | AA6: N/A | AB6: F | AC6: =IFERROR("Q" &INT((MONTH('MMR proficient'!AD8)+2)/3) & "-" & YEAR('MMR proficient'!AD8),"N/A") -> Q2-2017 | AD6: 47 | AE6: Endometrioid adenocarcinoma | AF6: Specimen | AG6: Yes | AH6: 1A | AI6: NR | AJ6: NR | AK6: 0 | AL6: T1AN0M0 | AM6: 1 | AN6: N/A | AO6: N/A
A7: LDS0002776 | B7: No | C7: Treatment naïve | D7: No | E7: LH18-18494 | F7: A27 | G7: A8 | H7: =IFERROR("Q" &INT((MONTH('MMR proficient'!H9)+2)/3) & "-" & YEAR('MMR proficient'!H9),"N/A") -> Q2-2018 | I7: Total laparoscopic hysterectomy/Bilateral salpingo-oophorectomy | J7: Uterine corpus | K7: N/A | L7: N/A | M7: N/A | N7: N/A | O7: N/A | P7: =IFERROR("Q" &INT((MONTH('MMR proficient'!P9)+2)/3) & "-" & YEAR('MMR proficient'!P9),"N/A") -> N/A | Q7: N/A | R7: N/A | S7: N/A | T7: N/A | U7: N/A | V7: N/A | W7: N/A | X7: N/A | Y7: N/A | Z7: N/A | AA7: N/A | AB7: F | AC7: =IFERROR("Q" &INT((MONTH('MMR proficient'!AD9)+2)/3) & "-" & YEAR('MMR proficient'!AD9),"N/A") -> Q1-2018 | AD7: 47 | AE7: Endometrioid adenocarcinoma | AF7: Specimen | AG7: Yes | AH7: 1B | AI7: NR | AJ7: NR | AK7: 0 | AL7: T1BN0M0 | AM7: 1 | AN7: N/A | AO7: N/A
A8: LDS0002777 | B8: No | C8: Treatment naïve | D8: No | E8: LH19-15431 | F8: A16 | G8: A18 | H8: =IFERROR("Q" &INT((MONTH('MMR proficient'!H10)+2)/3) & "-" & YEAR('MMR proficient'!H10),"N/A") -> Q2-2019 | I8: Total Robotic Hysterectomy/Bilateral salpingo-oophorectomy/Pelvic Lymphadenectomy | J8: Uterine corpus | K8: N/A | L8: N/A | M8: N/A | N8: N/A | O8: N/A | P8: =IFERROR("Q" &INT((MONTH('MMR proficient'!P10)+2)/3) & "-" & YEAR('MMR proficient'!P10),"N/A") -> N/A | Q8: N/A | R8: N/A | S8: N/A | T8: N/A | U8: N/A | V8: N/A | W8: N/A | X8: N/A | Y8: N/A | Z8: N/A | AA8: N/A | AB8: F | AC8: =IFERROR("Q" &INT((MONTH('MMR proficient'!AD10)+2)/3) & "-" & YEAR('MMR proficient'!AD10),"N/A") -> Q1-2019 | AD8: 59 | AE8: Endometrioid carcinoma | AF8: Specimen | AG8: Yes | AH8: NR | AI8: 1 | AJ8: NR | AK8: 0 | AL8: N/A | AM8: 2 | AN8: N/A | AO8: N/A
A9: LDS0002778 | B9: No | C9: Treatment naïve | D9: No | E9: LH19-26760 | F9: A10(L) | G9: A12(L) | H9: =IFERROR("Q" &INT((MONTH('MMR proficient'!H11)+2)/3) & "-" & YEAR('MMR proficient'!H11),"N/A") -> Q2-2019 | I9: Total Laparoscopic Hysterectomy; Bilateral Salpingo-oophorectomy; Bilateral Pelvic Node Sampling; Peritoneal washings | J9: Uterine corpus | K9: N/A | L9: N/A | M9: N/A | N9: N/A | O9: N/A | P9: =IFERROR("Q" &INT((MONTH('MMR proficient'!P11)+2)/3) & "-" & YEAR('MMR proficient'!P11),"N/A") -> N/A | Q9: N/A | R9: N/A | S9: N/A | T9: N/A | U9: N/A | V9: N/A | W9: N/A | X9: N/A | Y9: N/A | Z9: N/A | AA9: N/A | AB9: F | AC9: =IFERROR("Q" &INT((MONTH('MMR proficient'!AD11)+2)/3) & "-" & YEAR('MMR proficient'!AD11),"N/A") -> Q2-2019 | AD9: 55 | AE9: Endometrioid adenocarcinoma | AF9: Specimen | AG9: Yes | AH9: 1B | AI9: 0 | AJ9: NR | AK9: 0 | AL9: T1BN0M0 | AM9: 1 | AN9: N/A | AO9: N/A
A10: LDS0002779 | B10: No | C10: Treatment naïve | D10: No | E10: LH19-26931 | F10: A12 | G10: N/A | H10: =IFERROR("Q" &INT((MONTH('MMR proficient'!H12)+2)/3) & "-" & YEAR('MMR proficient'!H12),"N/A") -> Q2-2019 | I10: Total laparoscopic hysterectomy/Bilateral salpingo-oophorectomy | J10: Uterine corpus | K10: N/A | L10: N/A | M10: N/A | N10: N/A | O10: N/A | P10: =IFERROR("Q" &INT((MONTH('MMR proficient'!P12)+2)/3) & "-" & YEAR('MMR proficient'!P12),"N/A") -> N/A | Q10: N/A | R10: N/A | S10: N/A | T10: N/A | U10: N/A | V10: N/A | W10: N/A | X10: N/A | Y10: N/A | Z10: N/A | AA10: N/A | AB10: F | AC10: =IFERROR("Q" &INT((MONTH('MMR proficient'!AD12)+2)/3) & "-" & YEAR('MMR proficient'!AD12),"N/A") -> Q2-2019 | AD10: 60 | AE10: Endometrioid adenocarcinoma | AF10: Specimen | AG10: Yes | AH10: 1A | AI10: NR | AJ10: NR | AK10: 0 | AL10: T1AN0M0 | AM10: 1 | AN10: N/A | AO10: N/A
A11: LDS0002780 | B11: No | C11: Treatment naïve | D11: No | E11: LH19-34016 | F11: A15 | G11: A12 | H11: =IFERROR("Q" &INT((MONTH('MMR proficient'!H13)+2)/3) & "-" & YEAR('MMR proficient'!H13),"N/A") -> Q3-2019 | I11: Total abdominal hysterectomy, Bilateral salpingo-ophorectomy, Omentectomy, Pelvic lymph node sampling, Paraaortic lymph node sampling | J11: Uterine corpus | K11: N/A | L11: N/A | M11: N/A | N11: N/A | O11: N/A | P11: =IFERROR("Q" &INT((MONTH('MMR proficient'!P13)+2)/3) & "-" & YEAR('MMR proficient'!P13),"N/A") -> N/A | Q11: N/A | R11: N/A | S11: N/A | T11: N/A | U11: N/A | V11: N/A | W11: N/A | X11: N/A | Y11: N/A | Z11: N/A | AA11: N/A | AB11: F | AC11: =IFERROR("Q" &INT((MONTH('MMR proficient'!AD13)+2)/3) & "-" & YEAR('MMR proficient'!AD13),"N/A") -> Q3-2019 | AD11: 57 | AE11: Endometrioid adenocarcinoma | AF11: Specimen | AG11: Yes | AH11: 3A | AI11: 0 | AJ11: NR | AK11: 0 | AL11: T3AN0M0 | AM11: 1 | AN11: N/A | AO11: N/A
A12: LDS0002781 | B12: No | C12: Treatment naïve | D12: No | E12: LH19-34659 | F12: A8 | G12: A7 | H12: =IFERROR("Q" &INT((MONTH('MMR proficient'!H14)+2)/3) & "-" & YEAR('MMR proficient'!H14),"N/A") -> Q3-2019 | I12: Total robotic hysterectomy, bilateral salpingo-oophorectomy and bilateral pelvic lymphadenectomy | J12: Uterine corpus | K12: N/A | L12: N/A | M12: N/A | N12: N/A | O12: N/A | P12: =IFERROR("Q" &INT((MONTH('MMR proficient'!P14)+2)/3) & "-" & YEAR('MMR proficient'!P14),"N/A") -> N/A | Q12: N/A | R12: N/A | S12: N/A | T12: N/A | U12: N/A | V12: N/A | W12: N/A | X12: N/A | Y12: N/A | Z12: N/A | AA12: N/A | AB12: F | AC12: =IFERROR("Q" &INT((MONTH('MMR proficient'!AD14)+2)/3) & "-" & YEAR('MMR proficient'!AD14),"N/A") -> Q3-2019 | AD12: 61 | AE12: Endometrioid adenocarcinoma | AF12: Specimen | AG12: No | AH12: 1B | AI12: 0 | AJ12: NR | AK12: 0 | AL12: T1BN0M0 | AM12: 3 | AN12: N/A | AO12: N/A
A13: LDS0002782 | B13: No | C13: Treatment naïve | D13: No | E13: LH19-47908 | F13: A15 | G13: A10 | H13: =IFERROR("Q" &INT((MONTH('MMR proficient'!H15)+2)/3) & "-" & YEAR('MMR proficient'!H15),"N/A") -> Q4-2019 | I13: Total laparoscopic hysterectomy, bilateral salpingo-oophorectomy and bilateral pelvic lymphadenectomy | J13: Uterine corpus | K13: N/A | L13: N/A | M13: N/A | N13: N/A | O13: N/A | P13: =IFERROR("Q" &INT((MONTH('MMR proficient'!P15)+2)/3) & "-" & YEAR('MMR proficient'!P15),"N/A") -> N/A | Q13: N/A | R13: N/A | S13: N/A | T13: N/A | U13: N/A | V13: N/A | W13: N/A | X13: N/A | Y13: N/A | Z13: N/A | AA13: N/A | AB13: F | AC13: =IFERROR("Q" &INT((MONTH('MMR proficient'!AD15)+2)/3) & "-" & YEAR('MMR proficient'!AD15),"N/A") -> Q4-2019 | AD13: 75 | AE13: Endometrioid adenocarcinoma | AF13: Specimen | AG13: Yes | AH13: 2 | AI13: 0 | AJ13: NR | AK13: 0 | AL13: T2N0M0 | AM13: 3 | AN13: N/A | AO13: N/A
A14: LDS0002783 | B14: No | C14: Treatment naïve | D14: No | E14: LH19-50535 | F14: A14(L) | G14: N/A | H14: =IFERROR("Q" &INT((MONTH('MMR proficient'!H16)+2)/3) & "-" & YEAR('MMR proficient'!H16),"N/A") -> Q4-2019 | I14: Total laparoscopic hysterectomy/Bilateral salpingo-oophorectomy | J14: Uterine corpus | K14: N/A | L14: N/A | M14: N/A | N14: N/A | O14: N/A | P14: =IFERROR("Q" &INT((MONTH('MMR proficient'!P16)+2)/3) & "-" & YEAR('MMR proficient'!P16),"N/A") -> N/A | Q14: N/A | R14: N/A | S14: N/A | T14: N/A | U14: N/A | V14: N/A | W14: N/A | X14: N/A | Y14: N/A | Z14: N/A | AA14: N/A | AB14: F | AC14: =IFERROR("Q" &INT((MONTH('MMR proficient'!AD16)+2)/3) & "-" & YEAR('MMR proficient'!AD16),"N/A") -> Q4-2019 | AD14: 56 | AE14: Endometrioid adenocarcinoma | AF14: Specimen | AG14: Yes | AH14: 1A | AI14: NR | AJ14: NR | AK14: 0 | AL14: T1AN0M0 | AM14: 1 | AN14: N/A | AO14: N/A
A15: LDS0002784 | B15: No | C15: Treatment naïve | D15: No | E15: LH19-55935 | F15: A6 | G15: A5 | H15: =IFERROR("Q" &INT((MONTH('MMR proficient'!H17)+2)/3) & "-" & YEAR('MMR proficient'!H17),"N/A") -> Q4-2019 | I15: Laparotomy/Total abdominal hysterectomy/Bilateral salpingo-oophorectomy/Omentectomy/Pelvic and para-aortic lymphadenectomy | J15: Uterine corpus | K15: N/A | L15: N/A | M15: N/A | N15: N/A | O15: N/A | P15: =IFERROR("Q" &INT((MONTH('MMR proficient'!P17)+2)/3) & "-" & YEAR('MMR proficient'!P17),"N/A") -> N/A | Q15: N/A | R15: N/A | S15: N/A | T15: N/A | U15: N/A | V15: N/A | W15: N/A | X15: N/A | Y15: N/A | Z15: N/A | AA15: N/A | AB15: F | AC15: =IFERROR("Q" &INT((MONTH('MMR proficient'!AD17)+2)/3) & "-" & YEAR('MMR proficient'!AD17),"N/A") -> Q4-2019 | AD15: 52 | AE15: Endometrioid adenocarcinoma | AF15: Specimen | AG15: Yes | AH15: NR | AI15: 2 | AJ15: NR | AK15: 0 | AL15: N/A | AM15: 3 | AN15: N/A | AO15: N/A
A16: LDS0002785 | B16: No | C16: Treatment naïve | D16: No | E16: LH20-05949 | F16: A7 | G16: A17 | H16: =IFERROR("Q" &INT((MONTH('MMR proficient'!H18)+2)/3) & "-" & YEAR('MMR proficient'!H18),"N/A") -> Q1-2020 | I16: Total laparoscopic hysterectomy/Bilateral salpingo-oophorectomy | J16: Uterine corpus | K16: N/A | L16: N/A | M16: N/A | N16: N/A | O16: N/A | P16: =IFERROR("Q" &INT((MONTH('MMR proficient'!P18)+2)/3) & "-" & YEAR('MMR proficient'!P18),"N/A") -> N/A | Q16: N/A | R16: N/A | S16: N/A | T16: N/A | U16: N/A | V16: N/A | W16: N/A | X16: N/A | Y16: N/A | Z16: N/A | AA16: N/A | AB16: F | AC16: =IFERROR("Q" &INT((MONTH('MMR proficient'!AD18)+2)/3) & "-" & YEAR('MMR proficient'!AD18),"N/A") -> Q4-2019 | AD16: 65 | AE16: Endometrioid adenocarcinoma | AF16: Specimen | AG16: Yes | AH16: 1A | AI16: NR | AJ16: NR | AK16: 0 | AL16: T1AN0M0 | AM16: 1 | AN16: N/A | AO16: N/A
A17: LDS0002786 | B17: No | C17: Treatment naïve | D17: No | E17: LH20-05951 | F17: A9 | G17: A8 | H17: =IFERROR("Q" &INT((MONTH('MMR proficient'!H19)+2)/3) & "-" & YEAR('MMR proficient'!H19),"N/A") -> Q1-2020 | I17: laparoscopically assisted total hysterectomy, bilateral salpingo-oophorectomy | J17: Uterine corpus | K17: N/A | L17: N/A | M17: N/A | N17: N/A | O17: N/A | P17: =IFERROR("Q" &INT((MONTH('MMR proficient'!P19)+2)/3) & "-" & YEAR('MMR proficient'!P19),"N/A") -> N/A | Q17: N/A | R17: N/A | S17: N/A | T17: N/A | U17: N/A | V17: N/A | W17: N/A | X17: N/A | Y17: N/A | Z17: N/A | AA17: N/A | AB17: F | AC17: =IFERROR("Q" &INT((MONTH('MMR proficient'!AD19)+2)/3) & "-" & YEAR('MMR proficient'!AD19),"N/A") -> Q1-2020 | AD17: 61 | AE17: Endometrioid adenocarcinoma | AF17: Specimen | AG17: Yes | AH17: 1B | AI17: NR | AJ17: NR | AK17: 0 | AL17: T1BN0M0 | AM17: 1 | AN17: N/A | AO17: N/A
